ts_recv,ts_event,rtype,publisher_id,instrument_id,action,side,depth,price,size,flags,ts_in_delta,sequence,bid_px_00,ask_px_00,bid_sz_00,ask_sz_00,bid_ct_00,ask_ct_00,bid_px_01,ask_px_01,bid_sz_01,ask_sz_01,bid_ct_01,ask_ct_01,bid_px_02,ask_px_02,bid_sz_02,ask_sz_02,bid_ct_02,ask_ct_02,bid_px_03,ask_px_03,bid_sz_03,ask_sz_03,bid_ct_03,ask_ct_03,bid_px_04,ask_px_04,bid_sz_04,ask_sz_04,bid_ct_04,ask_ct_04,bid_px_05,ask_px_05,bid_sz_05,ask_sz_05,bid_ct_05,ask_ct_05,bid_px_06,ask_px_06,bid_sz_06,ask_sz_06,bid_ct_06,ask_ct_06,bid_px_07,ask_px_07,bid_sz_07,ask_sz_07,bid_ct_07,ask_ct_07,bid_px_08,ask_px_08,bid_sz_08,ask_sz_08,bid_ct_08,ask_ct_08,bid_px_09,ask_px_09,bid_sz_09,ask_sz_09,bid_ct_09,ask_ct_09,symbol
2024-10-21T12:11:25.073096247Z,2024-10-21T12:11:25.072929618Z,10,2,38,A,A,1,234.12,400,130,166629,12288986,233.9,234.0,11,154,2,7,233.78,234.12,400,400,1,1,233.76,234.13,30,427,1,2,233.7,234.17,1200,1,1,1,233.66,234.41,1,600,1,2,233.58,234.43,505,105,2,2,233.53,234.5,10,63,1,4,233.5,234.75,100,1,1,1,233.45,234.79,15,2000,1,1,233.4,234.89,110,2,2,2,JPM
2024-10-21T12:11:25.073458008Z,2024-10-21T12:11:25.073291984Z,10,2,38,C,B,2,233.76,30,130,166024,12288987,233.9,234.0,11,154,2,7,233.78,234.12,400,400,1,1,233.7,234.13,1200,427,1,2,233.66,234.17,1,1,1,1,233.58,234.41,505,600,2,2,233.53,234.43,10,105,1,2,233.5,234.5,100,63,1,4,233.45,234.75,15,1,1,1,233.4,234.79,110,2000,2,1,233.39,234.89,10,2,1,2,JPM
2024-10-21T12:11:25.073555014Z,2024-10-21T12:11:25.073388717Z,10,2,38,A,B,1,233.81,26,130,166297,12288988,233.9,234.0,11,154,2,7,233.81,234.12,26,400,1,1,233.78,234.13,400,427,1,2,233.7,234.17,1200,1,1,1,233.66,234.41,1,600,1,2,233.58,234.43,505,105,2,2,233.53,234.5,10,63,1,4,233.5,234.75,100,1,1,1,233.45,234.79,15,2000,1,1,233.4,234.89,110,2,2,2,JPM
2024-10-21T12:11:25.074138845Z,2024-10-21T12:11:25.073972612Z,10,2,38,C,A,2,234.13,27,130,166233,12288989,233.9,234.0,11,154,2,7,233.81,234.12,26,400,1,1,233.78,234.13,400,400,1,1,233.7,234.17,1200,1,1,1,233.66,234.41,1,600,1,2,233.58,234.43,505,105,2,2,233.53,234.5,10,63,1,4,233.5,234.75,100,1,1,1,233.45,234.79,15,2000,1,1,233.4,234.89,110,2,2,2,JPM
2024-10-21T12:11:25.074266365Z,2024-10-21T12:11:25.074100004Z,10,2,38,A,A,4,234.18,30,130,166361,12288990,233.9,234.0,11,154,2,7,233.81,234.12,26,400,1,1,233.78,234.13,400,400,1,1,233.7,234.17,1200,1,1,1,233.66,234.18,1,30,1,1,233.58,234.41,505,600,2,2,233.53,234.43,10,105,1,2,233.5,234.5,100,63,1,4,233.45,234.75,15,1,1,1,233.4,234.79,110,2000,2,1,JPM
2024-10-21T12:11:25.129461870Z,2024-10-21T12:11:25.129294511Z,10,2,38,A,B,1,233.86,200,130,167359,12289009,233.9,234.0,11,154,2,7,233.86,234.12,200,400,1,1,233.81,234.13,26,400,1,1,233.7,234.17,1200,1,1,1,233.66,234.18,1,30,1,1,233.58,234.41,505,600,2,2,233.53,234.43,10,105,1,2,233.5,234.5,100,63,1,4,233.45,234.75,15,1,1,1,233.4,234.79,110,2000,2,1,JPM
2024-10-21T12:11:27.120171307Z,2024-10-21T12:11:27.120005157Z,10,2,38,C,B,1,233.86,200,130,166150,12290119,233.9,234.0,11,154,2,7,233.81,234.12,26,400,1,1,233.7,234.13,1200,400,1,1,233.66,234.17,1,1,1,1,233.58,234.18,505,30,2,1,233.53,234.41,10,600,1,2,233.5,234.43,100,105,1,2,233.45,234.5,15,63,1,4,233.4,234.75,110,1,2,1,233.39,234.79,10,2000,1,1,JPM
2024-10-21T12:11:27.120184761Z,2024-10-21T12:11:27.120018111Z,10,2,38,A,B,2,233.78,400,130,166650,12290120,233.9,234.0,11,154,2,7,233.81,234.12,26,400,1,1,233.78,234.13,400,400,1,1,233.7,234.17,1200,1,1,1,233.66,234.18,1,30,1,1,233.58,234.41,505,600,2,2,233.53,234.43,10,105,1,2,233.5,234.5,100,63,1,4,233.45,234.75,15,1,1,1,233.4,234.79,110,2000,2,1,JPM
2024-10-21T12:11:27.120673190Z,2024-10-21T12:11:27.120506757Z,10,2,38,C,B,1,233.81,26,130,166433,12290123,233.9,234.0,11,154,2,7,233.78,234.12,400,400,1,1,233.7,234.13,1200,400,1,1,233.66,234.17,1,1,1,1,233.58,234.18,505,30,2,1,233.53,234.41,10,600,1,2,233.5,234.43,100,105,1,2,233.45,234.5,15,63,1,4,233.4,234.75,110,1,2,1,233.39,234.79,10,2000,1,1,JPM
2024-10-21T12:11:27.120714598Z,2024-10-21T12:11:27.120548454Z,10,2,38,A,B,2,233.76,29,130,166144,12290124,233.9,234.0,11,154,2,7,233.78,234.12,400,400,1,1,233.76,234.13,29,400,1,1,233.7,234.17,1200,1,1,1,233.66,234.18,1,30,1,1,233.58,234.41,505,600,2,2,233.53,234.43,10,105,1,2,233.5,234.5,100,63,1,4,233.45,234.75,15,1,1,1,233.4,234.79,110,2000,2,1,JPM
2024-10-21T12:11:27.120816314Z,2024-10-21T12:11:27.120650159Z,10,2,38,A,A,2,234.13,27,130,166155,12290125,233.9,234.0,11,154,2,7,233.78,234.12,400,400,1,1,233.76,234.13,29,427,1,2,233.7,234.17,1200,1,1,1,233.66,234.18,1,30,1,1,233.58,234.41,505,600,2,2,233.53,234.43,10,105,1,2,233.5,234.5,100,63,1,4,233.45,234.75,15,1,1,1,233.4,234.79,110,2000,2,1,JPM
2024-10-21T12:11:27.120886583Z,2024-10-21T12:11:27.120720548Z,10,2,38,C,A,4,234.18,30,130,166035,12290126,233.9,234.0,11,154,2,7,233.78,234.12,400,400,1,1,233.76,234.13,29,427,1,2,233.7,234.17,1200,1,1,1,233.66,234.41,1,600,1,2,233.58,234.43,505,105,2,2,233.53,234.5,10,63,1,4,233.5,234.75,100,1,1,1,233.45,234.79,15,2000,1,1,233.4,234.89,110,2,2,2,JPM
2024-10-21T12:11:27.177695699Z,2024-10-21T12:11:27.177529449Z,10,2,38,A,A,1,234.06,200,130,166250,12290153,233.9,234.0,11,154,2,7,233.78,234.06,400,200,1,1,233.76,234.13,29,427,1,2,233.7,234.17,1200,1,1,1,233.66,234.41,1,600,1,2,233.58,234.43,505,105,2,2,233.53,234.5,10,63,1,4,233.5,234.75,100,1,1,1,233.45,234.79,15,2000,1,1,233.4,234.89,110,2,2,2,JPM
2024-10-21T12:11:30.179271563Z,2024-10-21T12:11:30.179103980Z,10,2,38,A,B,1,233.82,200,130,167583,12292157,233.9,234.0,11,154,2,7,233.82,234.06,200,200,1,1,233.76,234.13,29,427,1,2,233.7,234.17,1200,1,1,1,233.66,234.41,1,600,1,2,233.58,234.43,505,105,2,2,233.53,234.5,10,63,1,4,233.5,234.75,100,1,1,1,233.45,234.79,15,2000,1,1,233.4,234.89,110,2,2,2,JPM
2024-10-21T12:11:34.156557363Z,2024-10-21T12:11:34.156391256Z,10,2,38,C,B,1,233.82,200,130,166107,12294618,233.9,234.0,11,154,2,7,233.76,234.06,29,200,1,1,233.7,234.13,1200,427,1,2,233.66,234.17,1,1,1,1,233.58,234.41,505,600,2,2,233.53,234.43,10,105,1,2,233.5,234.5,100,63,1,4,233.45,234.75,15,1,1,1,233.4,234.79,110,2000,2,1,233.39,234.89,10,2,1,2,JPM
2024-10-21T12:11:34.156569858Z,2024-10-21T12:11:34.156403417Z,10,2,38,A,B,1,233.78,400,130,166441,12294619,233.9,234.0,11,154,2,7,233.78,234.06,400,200,1,1,233.76,234.13,29,427,1,2,233.7,234.17,1200,1,1,1,233.66,234.41,1,600,1,2,233.58,234.43,505,105,2,2,233.53,234.5,10,63,1,4,233.5,234.75,100,1,1,1,233.45,234.79,15,2000,1,1,233.4,234.89,110,2,2,2,JPM
2024-10-21T12:11:36.738842101Z,2024-10-21T12:11:36.738675617Z,10,2,38,C,B,0,233.9,1,130,166484,12295779,233.9,234.0,10,154,1,7,233.78,234.06,400,200,1,1,233.76,234.13,29,427,1,2,233.7,234.17,1200,1,1,1,233.66,234.41,1,600,1,2,233.58,234.43,505,105,2,2,233.53,234.5,10,63,1,4,233.5,234.75,100,1,1,1,233.45,234.79,15,2000,1,1,233.4,234.89,110,2,2,2,JPM
2024-10-21T12:11:37.211098382Z,2024-10-21T12:11:37.210931791Z,10,2,38,A,B,1,233.82,200,130,166591,12295954,233.9,234.0,10,154,1,7,233.82,234.06,200,200,1,1,233.76,234.13,29,427,1,2,233.7,234.17,1200,1,1,1,233.66,234.41,1,600,1,2,233.58,234.43,505,105,2,2,233.53,234.5,10,63,1,4,233.5,234.75,100,1,1,1,233.45,234.79,15,2000,1,1,233.4,234.89,110,2,2,2,JPM
2024-10-21T12:11:40.138648473Z,2024-10-21T12:11:40.138482175Z,10,2,38,C,B,1,233.82,200,130,166298,12298108,233.9,234.0,10,154,1,7,233.76,234.06,29,200,1,1,233.7,234.13,1200,427,1,2,233.66,234.17,1,1,1,1,233.58,234.41,505,600,2,2,233.53,234.43,10,105,1,2,233.5,234.5,100,63,1,4,233.45,234.75,15,1,1,1,233.4,234.79,110,2000,2,1,233.39,234.89,10,2,1,2,JPM
2024-10-21T12:11:40.138664034Z,2024-10-21T12:11:40.138496802Z,10,2,38,A,B,1,233.78,400,130,167232,12298109,233.9,234.0,10,154,1,7,233.78,234.06,400,200,1,1,233.76,234.13,29,427,1,2,233.7,234.17,1200,1,1,1,233.66,234.41,1,600,1,2,233.58,234.43,505,105,2,2,233.53,234.5,10,63,1,4,233.5,234.75,100,1,1,1,233.45,234.79,15,2000,1,1,233.4,234.89,110,2,2,2,JPM
2024-10-21T12:11:43.193642005Z,2024-10-21T12:11:43.193475620Z,10,2,38,A,B,1,233.82,200,130,166385,12299803,233.9,234.0,10,154,1,7,233.82,234.06,200,200,1,1,233.76,234.13,29,427,1,2,233.7,234.17,1200,1,1,1,233.66,234.41,1,600,1,2,233.58,234.43,505,105,2,2,233.53,234.5,10,63,1,4,233.5,234.75,100,1,1,1,233.45,234.79,15,2000,1,1,233.4,234.89,110,2,2,2,JPM
2024-10-21T12:11:45.774890873Z,2024-10-21T12:11:45.774723015Z,10,2,38,T,N,0,233.98,50,130,167858,12301317,233.9,234.0,10,154,1,7,233.82,234.06,200,200,1,1,233.76,234.13,29,427,1,2,233.7,234.17,1200,1,1,1,233.66,234.41,1,600,1,2,233.58,234.43,505,105,2,2,233.53,234.5,10,63,1,4,233.5,234.75,100,1,1,1,233.45,234.79,15,2000,1,1,233.4,234.89,110,2,2,2,JPM
2024-10-21T12:11:45.844109427Z,2024-10-21T12:11:45.843943302Z,10,2,38,C,B,1,233.82,200,130,166125,12301621,233.9,234.0,10,154,1,7,233.76,234.06,29,200,1,1,233.7,234.13,1200,427,1,2,233.66,234.17,1,1,1,1,233.58,234.41,505,600,2,2,233.53,234.43,10,105,1,2,233.5,234.5,100,63,1,4,233.45,234.75,15,1,1,1,233.4,234.79,110,2000,2,1,233.39,234.89,10,2,1,2,JPM
2024-10-21T12:11:45.844122189Z,2024-10-21T12:11:45.843955896Z,10,2,38,A,B,1,233.78,400,130,166293,12301622,233.9,234.0,10,154,1,7,233.78,234.06,400,200,1,1,233.76,234.13,29,427,1,2,233.7,234.17,1200,1,1,1,233.66,234.41,1,600,1,2,233.58,234.43,505,105,2,2,233.53,234.5,10,63,1,4,233.5,234.75,100,1,1,1,233.45,234.79,15,2000,1,1,233.4,234.89,110,2,2,2,JPM
2024-10-21T12:11:48.580889153Z,2024-10-21T12:11:48.580722768Z,10,2,38,A,B,1,233.79,400,130,166385,12303381,233.9,234.0,10,154,1,7,233.79,234.06,400,200,1,1,233.76,234.13,29,427,1,2,233.7,234.17,1200,1,1,1,233.66,234.41,1,600,1,2,233.58,234.43,505,105,2,2,233.53,234.5,10,63,1,4,233.5,234.75,100,1,1,1,233.45,234.79,15,2000,1,1,233.4,234.89,110,2,2,2,JPM
2024-10-21T12:11:48.598638403Z,2024-10-21T12:11:48.598471411Z,10,2,38,C,B,2,233.76,29,130,166992,12303469,233.9,234.0,10,154,1,7,233.79,234.06,400,200,1,1,233.7,234.13,1200,427,1,2,233.66,234.17,1,1,1,1,233.58,234.41,505,600,2,2,233.53,234.43,10,105,1,2,233.5,234.5,100,63,1,4,233.45,234.75,15,1,1,1,233.4,234.79,110,2000,2,1,233.39,234.89,10,2,1,2,JPM
2024-10-21T12:11:48.598681245Z,2024-10-21T12:11:48.598514970Z,10,2,38,A,B,2,233.77,28,130,166275,12303470,233.9,234.0,10,154,1,7,233.79,234.06,400,200,1,1,233.77,234.13,28,427,1,2,233.7,234.17,1200,1,1,1,233.66,234.41,1,600,1,2,233.58,234.43,505,105,2,2,233.53,234.5,10,63,1,4,233.5,234.75,100,1,1,1,233.45,234.79,15,2000,1,1,233.4,234.89,110,2,2,2,JPM
2024-10-21T12:11:48.899213107Z,2024-10-21T12:11:48.899046660Z,10,2,38,A,B,1,233.83,200,130,166447,12303858,233.9,234.0,10,154,1,7,233.83,234.06,200,200,1,1,233.77,234.13,28,427,1,2,233.7,234.17,1200,1,1,1,233.66,234.41,1,600,1,2,233.58,234.43,505,105,2,2,233.53,234.5,10,63,1,4,233.5,234.75,100,1,1,1,233.45,234.79,15,2000,1,1,233.4,234.89,110,2,2,2,JPM
2024-10-21T12:11:50.835087071Z,2024-10-21T12:11:50.834920978Z,10,2,38,C,B,1,233.83,200,130,166093,12305321,233.9,234.0,10,154,1,7,233.77,234.06,28,200,1,1,233.7,234.13,1200,427,1,2,233.66,234.17,1,1,1,1,233.58,234.41,505,600,2,2,233.53,234.43,10,105,1,2,233.5,234.5,100,63,1,4,233.45,234.75,15,1,1,1,233.4,234.79,110,2000,2,1,233.39,234.89,10,2,1,2,JPM
2024-10-21T12:11:50.924256645Z,2024-10-21T12:11:50.924089402Z,10,2,38,A,B,1,233.83,200,130,167243,12305429,233.9,234.0,10,154,1,7,233.83,234.06,200,200,1,1,233.77,234.13,28,427,1,2,233.7,234.17,1200,1,1,1,233.66,234.41,1,600,1,2,233.58,234.43,505,105,2,2,233.53,234.5,10,63,1,4,233.5,234.75,100,1,1,1,233.45,234.79,15,2000,1,1,233.4,234.89,110,2,2,2,JPM
2024-10-21T12:11:53.326738713Z,2024-10-21T12:11:53.326572732Z,10,2,38,C,B,1,233.83,200,130,165981,12306983,233.9,234.0,10,154,1,7,233.77,234.06,28,200,1,1,233.7,234.13,1200,427,1,2,233.66,234.17,1,1,1,1,233.58,234.41,505,600,2,2,233.53,234.43,10,105,1,2,233.5,234.5,100,63,1,4,233.45,234.75,15,1,1,1,233.4,234.79,110,2000,2,1,233.39,234.89,10,2,1,2,JPM
2024-10-21T12:11:53.326752130Z,2024-10-21T12:11:53.326585955Z,10,2,38,A,B,1,233.79,400,130,166175,12306984,233.9,234.0,10,154,1,7,233.79,234.06,400,200,1,1,233.77,234.13,28,427,1,2,233.7,234.17,1200,1,1,1,233.66,234.41,1,600,1,2,233.58,234.43,505,105,2,2,233.53,234.5,10,63,1,4,233.5,234.75,100,1,1,1,233.45,234.79,15,2000,1,1,233.4,234.89,110,2,2,2,JPM
2024-10-21T12:11:56.382644560Z,2024-10-21T12:11:56.382477901Z,10,2,38,A,B,1,233.83,200,130,166659,12309100,233.9,234.0,10,154,1,7,233.83,234.06,200,200,1,1,233.77,234.13,28,427,1,2,233.7,234.17,1200,1,1,1,233.66,234.41,1,600,1,2,233.58,234.43,505,105,2,2,233.53,234.5,10,63,1,4,233.5,234.75,100,1,1,1,233.45,234.79,15,2000,1,1,233.4,234.89,110,2,2,2,JPM
2024-10-21T12:12:02.086696137Z,2024-10-21T12:12:02.086529609Z,10,2,38,A,A,0,233.97,20,130,166528,12315842,233.9,233.97,10,20,1,1,233.83,234.0,200,154,1,7,233.77,234.06,28,200,1,1,233.7,234.13,1200,427,1,2,233.66,234.17,1,1,1,1,233.58,234.41,505,600,2,2,233.53,234.43,10,105,1,2,233.5,234.5,100,63,1,4,233.45,234.75,15,1,1,1,233.4,234.79,110,2000,2,1,JPM
2024-10-21T12:12:02.213968660Z,2024-10-21T12:12:02.213802116Z,10,2,38,C,B,1,233.83,200,130,166544,12315992,233.9,233.97,10,20,1,1,233.77,234.0,28,154,1,7,233.7,234.06,1200,200,1,1,233.66,234.13,1,427,1,2,233.58,234.17,505,1,2,1,233.53,234.41,10,600,1,2,233.5,234.43,100,105,1,2,233.45,234.5,15,63,1,4,233.4,234.75,110,1,2,1,233.39,234.79,10,2000,1,1,JPM
2024-10-21T12:12:02.316815369Z,2024-10-21T12:12:02.316648939Z,10,2,38,A,B,1,233.82,200,130,166430,12316513,233.9,233.97,10,20,1,1,233.82,234.0,200,154,1,7,233.77,234.06,28,200,1,1,233.7,234.13,1200,427,1,2,233.66,234.17,1,1,1,1,233.58,234.41,505,600,2,2,233.53,234.43,10,105,1,2,233.5,234.5,100,63,1,4,233.45,234.75,15,1,1,1,233.4,234.79,110,2000,2,1,JPM
2024-10-21T12:12:08.967352049Z,2024-10-21T12:12:08.967185824Z,10,2,38,C,A,0,233.97,20,130,166225,12322349,233.9,234.0,10,154,1,7,233.82,234.06,200,200,1,1,233.77,234.13,28,427,1,2,233.7,234.17,1200,1,1,1,233.66,234.41,1,600,1,2,233.58,234.43,505,105,2,2,233.53,234.5,10,63,1,4,233.5,234.75,100,1,1,1,233.45,234.79,15,2000,1,1,233.4,234.89,110,2,2,2,JPM
2024-10-21T12:12:08.996872145Z,2024-10-21T12:12:08.996704242Z,10,2,38,T,N,0,233.96,4,130,167903,12322367,233.9,234.0,10,154,1,7,233.82,234.06,200,200,1,1,233.77,234.13,28,427,1,2,233.7,234.17,1200,1,1,1,233.66,234.41,1,600,1,2,233.58,234.43,505,105,2,2,233.53,234.5,10,63,1,4,233.5,234.75,100,1,1,1,233.45,234.79,15,2000,1,1,233.4,234.89,110,2,2,2,JPM
2024-10-21T12:12:08.996899848Z,2024-10-21T12:12:08.996733815Z,10,2,38,C,B,1,233.82,200,130,166033,12322368,233.9,234.0,10,154,1,7,233.77,234.06,28,200,1,1,233.7,234.13,1200,427,1,2,233.66,234.17,1,1,1,1,233.58,234.41,505,600,2,2,233.53,234.43,10,105,1,2,233.5,234.5,100,63,1,4,233.45,234.75,15,1,1,1,233.4,234.79,110,2000,2,1,233.39,234.89,10,2,1,2,JPM
2024-10-21T12:12:09.099905611Z,2024-10-21T12:12:09.099739392Z,10,2,38,A,B,1,233.82,200,130,166219,12322505,233.9,234.0,10,154,1,7,233.82,234.06,200,200,1,1,233.77,234.13,28,427,1,2,233.7,234.17,1200,1,1,1,233.66,234.41,1,600,1,2,233.58,234.43,505,105,2,2,233.53,234.5,10,63,1,4,233.5,234.75,100,1,1,1,233.45,234.79,15,2000,1,1,233.4,234.89,110,2,2,2,JPM
2024-10-21T12:12:10.232857553Z,2024-10-21T12:12:10.232691130Z,10,2,38,A,B,1,233.83,200,130,166423,12324515,233.9,234.0,10,154,1,7,233.83,234.06,200,200,1,1,233.77,234.13,28,427,1,2,233.7,234.17,1200,1,1,1,233.66,234.41,1,600,1,2,233.58,234.43,505,105,2,2,233.53,234.5,10,63,1,4,233.5,234.75,100,1,1,1,233.45,234.79,15,2000,1,1,233.4,234.89,110,2,2,2,JPM
2024-10-21T12:12:22.882293776Z,2024-10-21T12:12:22.882127538Z,10,2,38,C,B,1,233.83,200,130,166238,12335502,233.9,234.0,10,154,1,7,233.77,234.06,28,200,1,1,233.7,234.13,1200,427,1,2,233.66,234.17,1,1,1,1,233.58,234.41,505,600,2,2,233.53,234.43,10,105,1,2,233.5,234.5,100,63,1,4,233.45,234.75,15,1,1,1,233.4,234.79,110,2000,2,1,233.39,234.89,10,2,1,2,JPM
2024-10-21T12:12:22.882306926Z,2024-10-21T12:12:22.882140909Z,10,2,38,A,B,1,233.78,400,130,166017,12335503,233.9,234.0,10,154,1,7,233.78,234.06,400,200,1,1,233.77,234.13,28,427,1,2,233.7,234.17,1200,1,1,1,233.66,234.41,1,600,1,2,233.58,234.43,505,105,2,2,233.53,234.5,10,63,1,4,233.5,234.75,100,1,1,1,233.45,234.79,15,2000,1,1,233.4,234.89,110,2,2,2,JPM
2024-10-21T12:12:25.937011711Z,2024-10-21T12:12:25.936845190Z,10,2,38,A,B,1,233.82,200,130,166521,12338576,233.9,234.0,10,154,1,7,233.82,234.06,200,200,1,1,233.77,234.13,28,427,1,2,233.7,234.17,1200,1,1,1,233.66,234.41,1,600,1,2,233.58,234.43,505,105,2,2,233.53,234.5,10,63,1,4,233.5,234.75,100,1,1,1,233.45,234.79,15,2000,1,1,233.4,234.89,110,2,2,2,JPM
2024-10-21T12:12:28.133938919Z,2024-10-21T12:12:28.133772380Z,10,2,38,A,B,1,233.83,200,130,166539,12339995,233.9,234.0,10,154,1,7,233.83,234.06,200,200,1,1,233.77,234.13,28,427,1,2,233.7,234.17,1200,1,1,1,233.66,234.41,1,600,1,2,233.58,234.43,505,105,2,2,233.53,234.5,10,63,1,4,233.5,234.75,100,1,1,1,233.45,234.79,15,2000,1,1,233.4,234.89,110,2,2,2,JPM
2024-10-21T12:12:28.677615324Z,2024-10-21T12:12:28.677449361Z,10,2,38,C,B,1,233.83,200,130,165963,12340411,233.9,234.0,10,154,1,7,233.77,234.06,28,200,1,1,233.7,234.13,1200,427,1,2,233.66,234.17,1,1,1,1,233.58,234.41,505,600,2,2,233.53,234.43,10,105,1,2,233.5,234.5,100,63,1,4,233.45,234.75,15,1,1,1,233.4,234.79,110,2000,2,1,233.39,234.89,10,2,1,2,JPM
2024-10-21T12:12:28.677627803Z,2024-10-21T12:12:28.677461375Z,10,2,38,A,B,1,233.78,400,130,166428,12340412,233.9,234.0,10,154,1,7,233.78,234.06,400,200,1,1,233.77,234.13,28,427,1,2,233.7,234.17,1200,1,1,1,233.66,234.41,1,600,1,2,233.58,234.43,505,105,2,2,233.53,234.5,10,63,1,4,233.5,234.75,100,1,1,1,233.45,234.79,15,2000,1,1,233.4,234.89,110,2,2,2,JPM
2024-10-21T12:12:31.318989443Z,2024-10-21T12:12:31.318823338Z,10,2,38,C,A,1,234.06,200,130,166105,12341951,233.9,234.0,10,154,1,7,233.78,234.13,400,427,1,2,233.77,234.17,28,1,1,1,233.7,234.41,1200,600,1,2,233.66,234.43,1,105,1,2,233.58,234.5,505,63,2,4,233.53,234.75,10,1,1,1,233.5,234.79,100,2000,1,1,233.45,234.89,15,2,1,2,233.4,235.0,110,213,2,6,JPM
2024-10-21T12:12:31.398006757Z,2024-10-21T12:12:31.397839079Z,10,2,38,T,N,0,233.98,50,130,167678,12342316,233.9,234.0,10,154,1,7,233.78,234.13,400,427,1,2,233.77,234.17,28,1,1,1,233.7,234.41,1200,600,1,2,233.66,234.43,1,105,1,2,233.58,234.5,505,63,2,4,233.53,234.75,10,1,1,1,233.5,234.79,100,2000,1,1,233.45,234.89,15,2,1,2,233.4,235.0,110,213,2,6,JPM
2024-10-21T12:12:31.425970357Z,2024-10-21T12:12:31.425804077Z,10,2,38,A,A,1,234.07,200,130,166280,12342547,233.9,234.0,10,154,1,7,233.78,234.07,400,200,1,1,233.77,234.13,28,427,1,2,233.7,234.17,1200,1,1,1,233.66,234.41,1,600,1,2,233.58,234.43,505,105,2,2,233.53,234.5,10,63,1,4,233.5,234.75,100,1,1,1,233.45,234.79,15,2000,1,1,233.4,234.89,110,2,2,2,JPM
2024-10-21T12:12:31.454024371Z,2024-10-21T12:12:31.453857757Z,10,2,38,A,B,1,233.79,400,130,166614,12342589,233.9,234.0,10,154,1,7,233.79,234.07,400,200,1,1,233.77,234.13,28,427,1,2,233.7,234.17,1200,1,1,1,233.66,234.41,1,600,1,2,233.58,234.43,505,105,2,2,233.53,234.5,10,63,1,4,233.5,234.75,100,1,1,1,233.45,234.79,15,2000,1,1,233.4,234.89,110,2,2,2,JPM
2024-10-21T12:12:31.679118349Z,2024-10-21T12:12:31.678952187Z,10,2,38,C,B,2,233.77,28,130,166162,12343225,233.9,234.0,10,154,1,7,233.79,234.07,400,200,1,1,233.7,234.13,1200,427,1,2,233.66,234.17,1,1,1,1,233.58,234.41,505,600,2,2,233.53,234.43,10,105,1,2,233.5,234.5,100,63,1,4,233.45,234.75,15,1,1,1,233.4,234.79,110,2000,2,1,233.39,234.89,10,2,1,2,JPM
2024-10-21T12:12:31.679174617Z,2024-10-21T12:12:31.679008317Z,10,2,38,A,B,1,233.82,30,130,166300,12343226,233.9,234.0,10,154,1,7,233.82,234.07,30,200,1,1,233.79,234.13,400,427,1,2,233.7,234.17,1200,1,1,1,233.66,234.41,1,600,1,2,233.58,234.43,505,105,2,2,233.53,234.5,10,63,1,4,233.5,234.75,100,1,1,1,233.45,234.79,15,2000,1,1,233.4,234.89,110,2,2,2,JPM
2024-10-21T12:12:31.733543975Z,2024-10-21T12:12:31.733377635Z,10,2,38,A,B,1,233.87,200,130,166340,12343455,233.9,234.0,10,154,1,7,233.87,234.07,200,200,1,1,233.82,234.13,30,427,1,2,233.7,234.17,1200,1,1,1,233.66,234.41,1,600,1,2,233.58,234.43,505,105,2,2,233.53,234.5,10,63,1,4,233.5,234.75,100,1,1,1,233.45,234.79,15,2000,1,1,233.4,234.89,110,2,2,2,JPM
2024-10-21T12:12:41.238878627Z,2024-10-21T12:12:41.238712131Z,10,2,38,A,A,1,234.06,200,130,166496,12350539,233.9,234.0,10,154,1,7,233.87,234.06,200,200,1,1,233.82,234.13,30,427,1,2,233.7,234.17,1200,1,1,1,233.66,234.41,1,600,1,2,233.58,234.43,505,105,2,2,233.53,234.5,10,63,1,4,233.5,234.75,100,1,1,1,233.45,234.79,15,2000,1,1,233.4,234.89,110,2,2,2,JPM
2024-10-21T12:12:43.651514581Z,2024-10-21T12:12:43.651347870Z,10,2,38,C,B,1,233.87,200,130,166711,12352115,233.9,234.0,10,154,1,7,233.82,234.06,30,200,1,1,233.7,234.13,1200,427,1,2,233.66,234.17,1,1,1,1,233.58,234.41,505,600,2,2,233.53,234.43,10,105,1,2,233.5,234.5,100,63,1,4,233.45,234.75,15,1,1,1,233.4,234.79,110,2000,2,1,233.39,234.89,10,2,1,2,JPM
2024-10-21T12:12:43.731298274Z,2024-10-21T12:12:43.731132036Z,10,2,38,A,B,2,233.78,400,130,166238,12352210,233.9,234.0,10,154,1,7,233.82,234.06,30,200,1,1,233.78,234.13,400,427,1,2,233.7,234.17,1200,1,1,1,233.66,234.41,1,600,1,2,233.58,234.43,505,105,2,2,233.53,234.5,10,63,1,4,233.5,234.75,100,1,1,1,233.45,234.79,15,2000,1,1,233.4,234.89,110,2,2,2,JPM
2024-10-21T12:12:43.731821725Z,2024-10-21T12:12:43.731655758Z,10,2,38,C,B,1,233.82,30,130,165967,12352211,233.9,234.0,10,154,1,7,233.78,234.06,400,200,1,1,233.7,234.13,1200,427,1,2,233.66,234.17,1,1,1,1,233.58,234.41,505,600,2,2,233.53,234.43,10,105,1,2,233.5,234.5,100,63,1,4,233.45,234.75,15,1,1,1,233.4,234.79,110,2000,2,1,233.39,234.89,10,2,1,2,JPM
2024-10-21T12:12:43.731951886Z,2024-10-21T12:12:43.731785539Z,10,2,38,A,B,2,233.76,29,130,166347,12352212,233.9,234.0,10,154,1,7,233.78,234.06,400,200,1,1,233.76,234.13,29,427,1,2,233.7,234.17,1200,1,1,1,233.66,234.41,1,600,1,2,233.58,234.43,505,105,2,2,233.53,234.5,10,63,1,4,233.5,234.75,100,1,1,1,233.45,234.79,15,2000,1,1,233.4,234.89,110,2,2,2,JPM
2024-10-21T12:12:46.780539855Z,2024-10-21T12:12:46.780372537Z,10,2,38,A,B,1,233.82,200,128,167318,12353700,233.9,234.0,10,154,1,7,233.82,234.06,200,200,1,1,233.76,234.13,29,427,1,2,233.7,234.17,1200,1,1,1,233.66,234.41,1,600,1,2,233.58,234.43,505,105,2,2,233.53,234.5,10,63,1,4,233.5,234.75,100,1,1,1,233.45,234.79,15,2000,1,1,233.4,234.89,110,2,2,2,JPM
2024-10-21T12:12:47.484642192Z,2024-10-21T12:12:47.484476304Z,10,2,38,C,B,1,233.82,200,130,165888,12353973,233.9,234.0,10,154,1,7,233.76,234.06,29,200,1,1,233.7,234.13,1200,427,1,2,233.66,234.17,1,1,1,1,233.58,234.41,505,600,2,2,233.53,234.43,10,105,1,2,233.5,234.5,100,63,1,4,233.45,234.75,15,1,1,1,233.4,234.79,110,2000,2,1,233.39,234.89,10,2,1,2,JPM
2024-10-21T12:12:47.484860069Z,2024-10-21T12:12:47.484693420Z,10,2,38,A,A,0,233.99,100,130,166649,12353975,233.9,233.99,10,100,1,1,233.76,234.0,29,154,1,7,233.7,234.06,1200,200,1,1,233.66,234.13,1,427,1,2,233.58,234.17,505,1,2,1,233.53,234.41,10,600,1,2,233.5,234.43,100,105,1,2,233.45,234.5,15,63,1,4,233.4,234.75,110,1,2,1,233.39,234.79,10,2000,1,1,JPM
2024-10-21T12:12:47.485189477Z,2024-10-21T12:12:47.485023375Z,10,2,38,C,A,0,233.99,100,130,166102,12353978,233.9,234.0,10,154,1,7,233.76,234.06,29,200,1,1,233.7,234.13,1200,427,1,2,233.66,234.17,1,1,1,1,233.58,234.41,505,600,2,2,233.53,234.43,10,105,1,2,233.5,234.5,100,63,1,4,233.45,234.75,15,1,1,1,233.4,234.79,110,2000,2,1,233.39,234.89,10,2,1,2,JPM
2024-10-21T12:12:47.604634522Z,2024-10-21T12:12:47.604468075Z,10,2,38,A,B,1,233.78,400,130,166447,12354240,233.9,234.0,10,154,1,7,233.78,234.06,400,200,1,1,233.76,234.13,29,427,1,2,233.7,234.17,1200,1,1,1,233.66,234.41,1,600,1,2,233.58,234.43,505,105,2,2,233.53,234.5,10,63,1,4,233.5,234.75,100,1,1,1,233.45,234.79,15,2000,1,1,233.4,234.89,110,2,2,2,JPM
2024-10-21T12:12:47.736357741Z,2024-10-21T12:12:47.736191420Z,10,2,38,A,A,1,234.06,200,130,166321,12354295,233.9,234.0,10,154,1,7,233.78,234.06,400,400,1,2,233.76,234.13,29,427,1,2,233.7,234.17,1200,1,1,1,233.66,234.41,1,600,1,2,233.58,234.43,505,105,2,2,233.53,234.5,10,63,1,4,233.5,234.75,100,1,1,1,233.45,234.79,15,2000,1,1,233.4,234.89,110,2,2,2,JPM
2024-10-21T12:12:48.104314520Z,2024-10-21T12:12:48.104146428Z,10,2,38,T,A,0,233.9,10,130,168092,12354546,233.9,234.0,10,154,1,7,233.78,234.06,400,400,1,2,233.76,234.13,29,427,1,2,233.7,234.17,1200,1,1,1,233.66,234.41,1,600,1,2,233.58,234.43,505,105,2,2,233.53,234.5,10,63,1,4,233.5,234.75,100,1,1,1,233.45,234.79,15,2000,1,1,233.4,234.89,110,2,2,2,JPM
2024-10-21T12:12:48.104314520Z,2024-10-21T12:12:48.104146428Z,10,2,38,C,B,0,233.9,10,130,168092,12354546,233.78,234.0,400,154,1,7,233.76,234.06,29,400,1,2,233.7,234.13,1200,427,1,2,233.66,234.17,1,1,1,1,233.58,234.41,505,600,2,2,233.53,234.43,10,105,1,2,233.5,234.5,100,63,1,4,233.45,234.75,15,1,1,1,233.4,234.79,110,2000,2,1,233.39,234.89,10,2,1,2,JPM
2024-10-21T12:12:48.104334124Z,2024-10-21T12:12:48.104167967Z,10,2,38,A,A,0,233.98,100,130,166157,12354547,233.78,233.98,400,100,1,1,233.76,234.0,29,154,1,7,233.7,234.06,1200,400,1,2,233.66,234.13,1,427,1,2,233.58,234.17,505,1,2,1,233.53,234.41,10,600,1,2,233.5,234.43,100,105,1,2,233.45,234.5,15,63,1,4,233.4,234.75,110,1,2,1,233.39,234.79,10,2000,1,1,JPM
2024-10-21T12:12:48.104345015Z,2024-10-21T12:12:48.104178898Z,10,2,38,C,B,0,233.78,400,130,166117,12354548,233.76,233.98,29,100,1,1,233.7,234.0,1200,154,1,7,233.66,234.06,1,400,1,2,233.58,234.13,505,427,2,2,233.53,234.17,10,1,1,1,233.5,234.41,100,600,1,2,233.45,234.43,15,105,1,2,233.4,234.5,110,63,2,4,233.39,234.75,10,1,1,1,233.31,234.79,110,2000,2,1,JPM
2024-10-21T12:12:48.104347234Z,2024-10-21T12:12:48.104181225Z,10,2,38,A,A,0,233.98,100,130,166009,12354549,233.76,233.98,29,200,1,2,233.7,234.0,1200,154,1,7,233.66,234.06,1,400,1,2,233.58,234.13,505,427,2,2,233.53,234.17,10,1,1,1,233.5,234.41,100,600,1,2,233.45,234.43,15,105,1,2,233.4,234.5,110,63,2,4,233.39,234.75,10,1,1,1,233.31,234.79,110,2000,2,1,JPM
2024-10-21T12:12:48.104351926Z,2024-10-21T12:12:48.104185923Z,10,2,38,C,A,0,233.98,100,130,166003,12354550,233.76,233.98,29,100,1,1,233.7,234.0,1200,154,1,7,233.66,234.06,1,400,1,2,233.58,234.13,505,427,2,2,233.53,234.17,10,1,1,1,233.5,234.41,100,600,1,2,233.45,234.43,15,105,1,2,233.4,234.5,110,63,2,4,233.39,234.75,10,1,1,1,233.31,234.79,110,2000,2,1,JPM
2024-10-21T12:12:48.104356853Z,2024-10-21T12:12:48.104190565Z,10,2,38,A,A,0,233.95,14,130,166288,12354552,233.76,233.95,29,14,1,1,233.7,233.98,1200,100,1,1,233.66,234.0,1,154,1,7,233.58,234.06,505,400,2,2,233.53,234.13,10,427,1,2,233.5,234.17,100,1,1,1,233.45,234.41,15,600,1,2,233.4,234.43,110,105,2,2,233.39,234.5,10,63,1,4,233.31,234.75,110,1,2,1,JPM
2024-10-21T12:12:48.104362882Z,2024-10-21T12:12:48.104196514Z,10,2,38,A,A,0,233.95,16,130,166368,12354553,233.76,233.95,29,30,1,2,233.7,233.98,1200,100,1,1,233.66,234.0,1,154,1,7,233.58,234.06,505,400,2,2,233.53,234.13,10,427,1,2,233.5,234.17,100,1,1,1,233.45,234.41,15,600,1,2,233.4,234.43,110,105,2,2,233.39,234.5,10,63,1,4,233.31,234.75,110,1,2,1,JPM
2024-10-21T12:12:48.104375784Z,2024-10-21T12:12:48.104209602Z,10,2,38,A,A,1,233.98,16,130,166182,12354554,233.76,233.95,29,30,1,2,233.7,233.98,1200,116,1,2,233.66,234.0,1,154,1,7,233.58,234.06,505,400,2,2,233.53,234.13,10,427,1,2,233.5,234.17,100,1,1,1,233.45,234.41,15,600,1,2,233.4,234.43,110,105,2,2,233.39,234.5,10,63,1,4,233.31,234.75,110,1,2,1,JPM
2024-10-21T12:12:48.104385015Z,2024-10-21T12:12:48.104217612Z,10,2,38,C,A,1,233.98,100,130,167403,12354555,233.76,233.95,29,30,1,2,233.7,233.98,1200,16,1,1,233.66,234.0,1,154,1,7,233.58,234.06,505,400,2,2,233.53,234.13,10,427,1,2,233.5,234.17,100,1,1,1,233.45,234.41,15,600,1,2,233.4,234.43,110,105,2,2,233.39,234.5,10,63,1,4,233.31,234.75,110,1,2,1,JPM
2024-10-21T12:12:48.176341448Z,2024-10-21T12:12:48.176175311Z,10,2,38,A,B,1,233.71,27,130,166137,12354620,233.76,233.95,29,30,1,2,233.71,233.98,27,16,1,1,233.7,234.0,1200,154,1,7,233.66,234.06,1,400,1,2,233.58,234.13,505,427,2,2,233.53,234.17,10,1,1,1,233.5,234.41,100,600,1,2,233.45,234.43,15,105,1,2,233.4,234.5,110,63,2,4,233.39,234.75,10,1,1,1,JPM
2024-10-21T12:12:48.176370376Z,2024-10-21T12:12:48.176204532Z,10,2,38,C,B,0,233.76,29,130,165844,12354621,233.71,233.95,27,30,1,2,233.7,233.98,1200,16,1,1,233.66,234.0,1,154,1,7,233.58,234.06,505,400,2,2,233.53,234.13,10,427,1,2,233.5,234.17,100,1,1,1,233.45,234.41,15,600,1,2,233.4,234.43,110,105,2,2,233.39,234.5,10,63,1,4,233.31,234.75,110,1,2,1,JPM
2024-10-21T12:12:48.177018480Z,2024-10-21T12:12:48.176852661Z,10,2,38,C,B,0,233.71,27,130,165819,12354624,233.7,233.95,1200,30,1,2,233.66,233.98,1,16,1,1,233.58,234.0,505,154,2,7,233.53,234.06,10,400,1,2,233.5,234.13,100,427,1,2,233.45,234.17,15,1,1,1,233.4,234.41,110,600,2,2,233.39,234.43,10,105,1,2,233.31,234.5,110,63,2,4,233.3,234.75,100,1,1,1,JPM
2024-10-21T12:12:48.180095554Z,2024-10-21T12:12:48.179929431Z,10,2,38,A,A,4,234.08,29,130,166123,12354625,233.7,233.95,1200,30,1,2,233.66,233.98,1,16,1,1,233.58,234.0,505,154,2,7,233.53,234.06,10,400,1,2,233.5,234.08,100,29,1,1,233.45,234.13,15,427,1,2,233.4,234.17,110,1,2,1,233.39,234.41,10,600,1,2,233.31,234.43,110,105,2,2,233.3,234.5,100,63,1,4,JPM
2024-10-21T12:12:48.180133214Z,2024-10-21T12:12:48.179967058Z,10,2,38,C,A,5,234.13,27,130,166156,12354626,233.7,233.95,1200,30,1,2,233.66,233.98,1,16,1,1,233.58,234.0,505,154,2,7,233.53,234.06,10,400,1,2,233.5,234.08,100,29,1,1,233.45,234.13,15,400,1,1,233.4,234.17,110,1,2,1,233.39,234.41,10,600,1,2,233.31,234.43,110,105,2,2,233.3,234.5,100,63,1,4,JPM
2024-10-21T12:12:48.204420400Z,2024-10-21T12:12:48.204254179Z,10,2,38,C,A,0,233.95,14,130,166221,12354640,233.7,233.95,1200,16,1,1,233.66,233.98,1,16,1,1,233.58,234.0,505,154,2,7,233.53,234.06,10,400,1,2,233.5,234.08,100,29,1,1,233.45,234.13,15,400,1,1,233.4,234.17,110,1,2,1,233.39,234.41,10,600,1,2,233.31,234.43,110,105,2,2,233.3,234.5,100,63,1,4,JPM
2024-10-21T12:12:48.204447035Z,2024-10-21T12:12:48.204281167Z,10,2,38,C,A,1,233.98,16,130,165868,12354641,233.7,233.95,1200,16,1,1,233.66,234.0,1,154,1,7,233.58,234.06,505,400,2,2,233.53,234.08,10,29,1,1,233.5,234.13,100,400,1,1,233.45,234.17,15,1,1,1,233.4,234.41,110,600,2,2,233.39,234.43,10,105,1,2,233.31,234.5,110,63,2,4,233.3,234.75,100,1,1,1,JPM
2024-10-21T12:12:48.214127843Z,2024-10-21T12:12:48.213961498Z,10,2,38,A,B,1,233.67,400,130,166345,12354647,233.7,233.95,1200,16,1,1,233.67,234.0,400,154,1,7,233.66,234.06,1,400,1,2,233.58,234.08,505,29,2,1,233.53,234.13,10,400,1,1,233.5,234.17,100,1,1,1,233.45,234.41,15,600,1,2,233.4,234.43,110,105,2,2,233.39,234.5,10,63,1,4,233.31,234.75,110,1,2,1,JPM
2024-10-21T12:12:48.233136592Z,2024-10-21T12:12:48.232970230Z,10,2,38,C,A,2,234.06,200,130,166362,12354661,233.7,233.95,1200,16,1,1,233.67,234.0,400,154,1,7,233.66,234.06,1,200,1,1,233.58,234.08,505,29,2,1,233.53,234.13,10,400,1,1,233.5,234.17,100,1,1,1,233.45,234.41,15,600,1,2,233.4,234.43,110,105,2,2,233.39,234.5,10,63,1,4,233.31,234.75,110,1,2,1,JPM
2024-10-21T12:12:48.233149556Z,2024-10-21T12:12:48.232983049Z,10,2,38,A,A,2,234.01,200,130,166507,12354662,233.7,233.95,1200,16,1,1,233.67,234.0,400,154,1,7,233.66,234.01,1,200,1,1,233.58,234.08,505,29,2,1,233.53,234.13,10,400,1,1,233.5,234.17,100,1,1,1,233.45,234.41,15,600,1,2,233.4,234.43,110,105,2,2,233.39,234.5,10,63,1,4,233.31,234.75,110,1,2,1,JPM
2024-10-21T12:12:48.247502164Z,2024-10-21T12:12:48.247336117Z,10,2,38,C,B,1,233.67,400,130,166047,12354665,233.7,233.95,1200,16,1,1,233.66,234.0,1,154,1,7,233.58,234.01,505,200,2,1,233.53,234.08,10,29,1,1,233.5,234.13,100,400,1,1,233.45,234.17,15,1,1,1,233.4,234.41,110,600,2,2,233.39,234.43,10,105,1,2,233.31,234.5,110,63,2,4,233.3,234.75,100,1,1,1,JPM
2024-10-21T12:12:48.247514656Z,2024-10-21T12:12:48.247348435Z,10,2,38,A,B,2,233.62,400,130,166221,12354666,233.7,233.95,1200,16,1,1,233.66,234.0,1,154,1,7,233.62,234.01,400,200,1,1,233.58,234.08,505,29,2,1,233.53,234.13,10,400,1,1,233.5,234.17,100,1,1,1,233.45,234.41,15,600,1,2,233.4,234.43,110,105,2,2,233.39,234.5,10,63,1,4,233.31,234.75,110,1,2,1,JPM
2024-10-21T12:12:48.307017573Z,2024-10-21T12:12:48.306851049Z,10,2,38,A,B,0,233.72,400,130,166524,12354670,233.72,233.95,400,16,1,1,233.7,234.0,1200,154,1,7,233.66,234.01,1,200,1,1,233.58,234.08,505,29,2,1,233.53,234.13,10,400,1,1,233.5,234.17,100,1,1,1,233.45,234.41,15,600,1,2,233.4,234.43,110,105,2,2,233.39,234.5,10,63,1,4,233.31,234.75,110,1,2,1,JPM
2024-10-21T12:12:48.348045881Z,2024-10-21T12:12:48.347879918Z,10,2,38,C,A,2,234.01,200,130,165963,12354690,233.72,233.95,400,16,1,1,233.7,234.0,1200,154,1,7,233.66,234.08,1,29,1,1,233.58,234.13,505,400,2,1,233.53,234.17,10,1,1,1,233.5,234.41,100,600,1,2,233.45,234.43,15,105,1,2,233.4,234.5,110,63,2,4,233.39,234.75,10,1,1,1,233.31,234.79,110,2000,2,1,JPM
2024-10-21T12:12:48.348059124Z,2024-10-21T12:12:48.347893041Z,10,2,38,A,A,2,234.06,400,130,166083,12354691,233.72,233.95,400,16,1,1,233.7,234.0,1200,154,1,7,233.66,234.06,1,400,1,1,233.58,234.08,505,29,2,1,233.53,234.13,10,400,1,1,233.5,234.17,100,1,1,1,233.45,234.41,15,600,1,2,233.4,234.43,110,105,2,2,233.39,234.5,10,63,1,4,233.31,234.75,110,1,2,1,JPM
2024-10-21T12:12:48.363929061Z,2024-10-21T12:12:48.363762750Z,10,2,38,C,A,0,233.95,16,130,166311,12354719,233.72,234.0,400,154,1,7,233.7,234.06,1200,400,1,1,233.66,234.08,1,29,1,1,233.58,234.13,505,400,2,1,233.53,234.17,10,1,1,1,233.5,234.41,100,600,1,2,233.45,234.43,15,105,1,2,233.4,234.5,110,63,2,4,233.39,234.75,10,1,1,1,233.31,234.79,110,2000,2,1,JPM
2024-10-21T12:12:49.107440196Z,2024-10-21T12:12:49.107274312Z,10,2,38,C,B,0,233.72,400,130,165884,12355060,233.7,234.0,1200,154,1,7,233.66,234.06,1,400,1,1,233.58,234.08,505,29,2,1,233.53,234.13,10,400,1,1,233.5,234.17,100,1,1,1,233.45,234.41,15,600,1,2,233.4,234.43,110,105,2,2,233.39,234.5,10,63,1,4,233.31,234.75,110,1,2,1,233.3,234.79,100,2000,1,1,JPM
2024-10-21T12:12:49.117722704Z,2024-10-21T12:12:49.117556478Z,10,2,38,A,B,0,233.72,200,130,166226,12355064,233.72,234.0,200,154,1,7,233.7,234.06,1200,400,1,1,233.66,234.08,1,29,1,1,233.58,234.13,505,400,2,1,233.53,234.17,10,1,1,1,233.5,234.41,100,600,1,2,233.45,234.43,15,105,1,2,233.4,234.5,110,63,2,4,233.39,234.75,10,1,1,1,233.31,234.79,110,2000,2,1,JPM
2024-10-21T12:12:49.170261083Z,2024-10-21T12:12:49.170094147Z,10,2,38,A,B,3,233.65,28,130,166936,12355076,233.72,234.0,200,154,1,7,233.7,234.06,1200,400,1,1,233.66,234.08,1,29,1,1,233.65,234.13,28,400,1,1,233.58,234.17,505,1,2,1,233.53,234.41,10,600,1,2,233.5,234.43,100,105,1,2,233.45,234.5,15,63,1,4,233.4,234.75,110,1,2,1,233.39,234.79,10,2000,1,1,JPM
2024-10-21T12:12:49.179734911Z,2024-10-21T12:12:49.179568062Z,10,2,38,A,B,0,233.72,200,130,166849,12355080,233.72,234.0,400,154,2,7,233.7,234.06,1200,400,1,1,233.66,234.08,1,29,1,1,233.65,234.13,28,400,1,1,233.58,234.17,505,1,2,1,233.53,234.41,10,600,1,2,233.5,234.43,100,105,1,2,233.45,234.5,15,63,1,4,233.4,234.75,110,1,2,1,233.39,234.79,10,2000,1,1,JPM
2024-10-21T12:12:50.108822491Z,2024-10-21T12:12:50.108656247Z,10,2,38,C,B,0,233.72,200,130,166244,12355613,233.72,234.0,200,154,1,7,233.7,234.06,1200,400,1,1,233.66,234.08,1,29,1,1,233.65,234.13,28,400,1,1,233.58,234.17,505,1,2,1,233.53,234.41,10,600,1,2,233.5,234.43,100,105,1,2,233.45,234.5,15,63,1,4,233.4,234.75,110,1,2,1,233.39,234.79,10,2000,1,1,JPM
2024-10-21T12:12:50.108831892Z,2024-10-21T12:12:50.108666090Z,10,2,38,C,B,0,233.72,200,130,165802,12355614,233.7,234.0,1200,154,1,7,233.66,234.06,1,400,1,1,233.65,234.08,28,29,1,1,233.58,234.13,505,400,2,1,233.53,234.17,10,1,1,1,233.5,234.41,100,600,1,2,233.45,234.43,15,105,1,2,233.4,234.5,110,63,2,4,233.39,234.75,10,1,1,1,233.31,234.79,110,2000,2,1,JPM
2024-10-21T12:12:50.212341929Z,2024-10-21T12:12:50.212175433Z,10,2,38,A,B,0,233.72,400,130,166496,12355646,233.72,234.0,400,154,1,7,233.7,234.06,1200,400,1,1,233.66,234.08,1,29,1,1,233.65,234.13,28,400,1,1,233.58,234.17,505,1,2,1,233.53,234.41,10,600,1,2,233.5,234.43,100,105,1,2,233.45,234.5,15,63,1,4,233.4,234.75,110,1,2,1,233.39,234.79,10,2000,1,1,JPM
2024-10-21T12:12:50.565470381Z,2024-10-21T12:12:50.565304171Z,10,2,38,C,B,3,233.65,28,130,166210,12355988,233.72,234.0,400,154,1,7,233.7,234.06,1200,400,1,1,233.66,234.08,1,29,1,1,233.58,234.13,505,400,2,1,233.53,234.17,10,1,1,1,233.5,234.41,100,600,1,2,233.45,234.43,15,105,1,2,233.4,234.5,110,63,2,4,233.39,234.75,10,1,1,1,233.31,234.79,110,2000,2,1,JPM
2024-10-21T12:12:50.565594035Z,2024-10-21T12:12:50.565427767Z,10,2,38,A,B,1,233.71,26,130,166268,12355989,233.72,234.0,400,154,1,7,233.71,234.06,26,400,1,1,233.7,234.08,1200,29,1,1,233.66,234.13,1,400,1,1,233.58,234.17,505,1,2,1,233.53,234.41,10,600,1,2,233.5,234.43,100,105,1,2,233.45,234.5,15,63,1,4,233.4,234.75,110,1,2,1,233.39,234.79,10,2000,1,1,JPM
2024-10-21T12:12:50.565667034Z,2024-10-21T12:12:50.565500981Z,10,2,38,C,A,2,234.08,29,130,166053,12355990,233.72,234.0,400,154,1,7,233.71,234.06,26,400,1,1,233.7,234.13,1200,400,1,1,233.66,234.17,1,1,1,1,233.58,234.41,505,600,2,2,233.53,234.43,10,105,1,2,233.5,234.5,100,63,1,4,233.45,234.75,15,1,1,1,233.4,234.79,110,2000,2,1,233.39,234.89,10,2,1,2,JPM
2024-10-21T12:12:50.565721409Z,2024-10-21T12:12:50.565554902Z,10,2,38,A,A,2,234.13,30,130,166507,12355991,233.72,234.0,400,154,1,7,233.71,234.06,26,400,1,1,233.7,234.13,1200,430,1,2,233.66,234.17,1,1,1,1,233.58,234.41,505,600,2,2,233.53,234.43,10,105,1,2,233.5,234.5,100,63,1,4,233.45,234.75,15,1,1,1,233.4,234.79,110,2000,2,1,233.39,234.89,10,2,1,2,JPM
2024-10-21T12:12:50.574010932Z,2024-10-21T12:12:50.573844808Z,10,2,38,C,B,0,233.72,200,130,166124,12355992,233.72,234.0,200,154,1,7,233.71,234.06,26,400,1,1,233.7,234.13,1200,430,1,2,233.66,234.17,1,1,1,1,233.58,234.41,505,600,2,2,233.53,234.43,10,105,1,2,233.5,234.5,100,63,1,4,233.45,234.75,15,1,1,1,233.4,234.79,110,2000,2,1,233.39,234.89,10,2,1,2,JPM
2024-10-21T12:12:50.619715566Z,2024-10-21T12:12:50.619549454Z,10,2,38,C,B,0,233.72,200,130,166112,12355999,233.71,234.0,26,154,1,7,233.7,234.06,1200,400,1,1,233.66,234.13,1,430,1,2,233.58,234.17,505,1,2,1,233.53,234.41,10,600,1,2,233.5,234.43,100,105,1,2,233.45,234.5,15,63,1,4,233.4,234.75,110,1,2,1,233.39,234.79,10,2000,1,1,233.31,234.89,110,2,2,2,JPM
2024-10-21T12:12:50.619728644Z,2024-10-21T12:12:50.619562205Z,10,2,38,A,A,1,234.05,200,130,166439,12356000,233.71,234.0,26,154,1,7,233.7,234.05,1200,200,1,1,233.66,234.13,1,430,1,2,233.58,234.17,505,1,2,1,233.53,234.41,10,600,1,2,233.5,234.43,100,105,1,2,233.45,234.5,15,63,1,4,233.4,234.75,110,1,2,1,233.39,234.79,10,2000,1,1,233.31,234.89,110,2,2,2,JPM
2024-10-21T12:12:50.622790340Z,2024-10-21T12:12:50.622623771Z,10,2,38,A,A,1,234.01,200,130,166569,12356003,233.71,234.0,26,154,1,7,233.7,234.01,1200,200,1,1,233.66,234.13,1,430,1,2,233.58,234.17,505,1,2,1,233.53,234.41,10,600,1,2,233.5,234.43,100,105,1,2,233.45,234.5,15,63,1,4,233.4,234.75,110,1,2,1,233.39,234.79,10,2000,1,1,233.31,234.89,110,2,2,2,JPM
2024-10-21T12:12:50.641720668Z,2024-10-21T12:12:50.641554545Z,10,2,38,A,B,0,233.77,200,130,166123,12356008,233.77,234.0,200,154,1,7,233.71,234.01,26,200,1,1,233.7,234.13,1200,430,1,2,233.66,234.17,1,1,1,1,233.58,234.41,505,600,2,2,233.53,234.43,10,105,1,2,233.5,234.5,100,63,1,4,233.45,234.75,15,1,1,1,233.4,234.79,110,2000,2,1,233.39,234.89,10,2,1,2,JPM
2024-10-21T12:12:50.682530531Z,2024-10-21T12:12:50.682363924Z,10,2,38,C,A,1,234.01,200,130,166607,12356017,233.77,234.0,200,154,1,7,233.71,234.13,26,430,1,2,233.7,234.17,1200,1,1,1,233.66,234.41,1,600,1,2,233.58,234.43,505,105,2,2,233.53,234.5,10,63,1,4,233.5,234.75,100,1,1,1,233.45,234.79,15,2000,1,1,233.4,234.89,110,2,2,2,233.39,235.0,10,213,1,6,JPM
2024-10-21T12:12:50.682542775Z,2024-10-21T12:12:50.682376586Z,10,2,38,A,A,1,234.06,400,130,166189,12356018,233.77,234.0,200,154,1,7,233.71,234.06,26,400,1,1,233.7,234.13,1200,430,1,2,233.66,234.17,1,1,1,1,233.58,234.41,505,600,2,2,233.53,234.43,10,105,1,2,233.5,234.5,100,63,1,4,233.45,234.75,15,1,1,1,233.4,234.79,110,2000,2,1,233.39,234.89,10,2,1,2,JPM
2024-10-21T12:12:50.736679110Z,2024-10-21T12:12:50.736513051Z,10,2,38,C,B,0,233.77,200,130,166059,12356039,233.71,234.0,26,154,1,7,233.7,234.06,1200,400,1,1,233.66,234.13,1,430,1,2,233.58,234.17,505,1,2,1,233.53,234.41,10,600,1,2,233.5,234.43,100,105,1,2,233.45,234.5,15,63,1,4,233.4,234.75,110,1,2,1,233.39,234.79,10,2000,1,1,233.31,234.89,110,2,2,2,JPM
2024-10-21T12:12:50.837873116Z,2024-10-21T12:12:50.837707032Z,10,2,38,A,B,0,233.77,200,130,166084,12356086,233.77,234.0,200,154,1,7,233.71,234.06,26,400,1,1,233.7,234.13,1200,430,1,2,233.66,234.17,1,1,1,1,233.58,234.41,505,600,2,2,233.53,234.43,10,105,1,2,233.5,234.5,100,63,1,4,233.45,234.75,15,1,1,1,233.4,234.79,110,2000,2,1,233.39,234.89,10,2,1,2,JPM
2024-10-21T12:12:50.886653895Z,2024-10-21T12:12:50.886487788Z,10,2,38,C,B,0,233.77,200,130,166107,12356099,233.71,234.0,26,154,1,7,233.7,234.06,1200,400,1,1,233.66,234.13,1,430,1,2,233.58,234.17,505,1,2,1,233.53,234.41,10,600,1,2,233.5,234.43,100,105,1,2,233.45,234.5,15,63,1,4,233.4,234.75,110,1,2,1,233.39,234.79,10,2000,1,1,233.31,234.89,110,2,2,2,JPM
2024-10-21T12:12:50.986944410Z,2024-10-21T12:12:50.986777714Z,10,2,38,A,B,0,233.77,200,130,166696,12356148,233.77,234.0,200,154,1,7,233.71,234.06,26,400,1,1,233.7,234.13,1200,430,1,2,233.66,234.17,1,1,1,1,233.58,234.41,505,600,2,2,233.53,234.43,10,105,1,2,233.5,234.5,100,63,1,4,233.45,234.75,15,1,1,1,233.4,234.79,110,2000,2,1,233.39,234.89,10,2,1,2,JPM
2024-10-21T12:12:51.039503151Z,2024-10-21T12:12:51.039337327Z,10,2,38,C,B,0,233.77,200,130,165824,12356173,233.71,234.0,26,154,1,7,233.7,234.06,1200,400,1,1,233.66,234.13,1,430,1,2,233.58,234.17,505,1,2,1,233.53,234.41,10,600,1,2,233.5,234.43,100,105,1,2,233.45,234.5,15,63,1,4,233.4,234.75,110,1,2,1,233.39,234.79,10,2000,1,1,233.31,234.89,110,2,2,2,JPM
2024-10-21T12:12:51.148063732Z,2024-10-21T12:12:51.147897247Z,10,2,38,A,B,0,233.77,200,130,166485,12356223,233.77,234.0,200,154,1,7,233.71,234.06,26,400,1,1,233.7,234.13,1200,430,1,2,233.66,234.17,1,1,1,1,233.58,234.41,505,600,2,2,233.53,234.43,10,105,1,2,233.5,234.5,100,63,1,4,233.45,234.75,15,1,1,1,233.4,234.79,110,2000,2,1,233.39,234.89,10,2,1,2,JPM
2024-10-21T12:12:51.221545416Z,2024-10-21T12:12:51.221379329Z,10,2,38,C,B,0,233.77,200,130,166087,12356261,233.71,234.0,26,154,1,7,233.7,234.06,1200,400,1,1,233.66,234.13,1,430,1,2,233.58,234.17,505,1,2,1,233.53,234.41,10,600,1,2,233.5,234.43,100,105,1,2,233.45,234.5,15,63,1,4,233.4,234.75,110,1,2,1,233.39,234.79,10,2000,1,1,233.31,234.89,110,2,2,2,JPM
2024-10-21T12:12:51.330104268Z,2024-10-21T12:12:51.329937404Z,10,2,38,A,B,0,233.77,200,130,166864,12356295,233.77,234.0,200,154,1,7,233.71,234.06,26,400,1,1,233.7,234.13,1200,430,1,2,233.66,234.17,1,1,1,1,233.58,234.41,505,600,2,2,233.53,234.43,10,105,1,2,233.5,234.5,100,63,1,4,233.45,234.75,15,1,1,1,233.4,234.79,110,2000,2,1,233.39,234.89,10,2,1,2,JPM
2024-10-21T12:12:51.374577807Z,2024-10-21T12:12:51.374411634Z,10,2,38,C,B,0,233.77,200,130,166173,12356317,233.71,234.0,26,154,1,7,233.7,234.06,1200,400,1,1,233.66,234.13,1,430,1,2,233.58,234.17,505,1,2,1,233.53,234.41,10,600,1,2,233.5,234.43,100,105,1,2,233.45,234.5,15,63,1,4,233.4,234.75,110,1,2,1,233.39,234.79,10,2000,1,1,233.31,234.89,110,2,2,2,JPM
2024-10-21T12:12:51.475205660Z,2024-10-21T12:12:51.475039269Z,10,2,38,A,B,0,233.77,200,130,166391,12356344,233.77,234.0,200,154,1,7,233.71,234.06,26,400,1,1,233.7,234.13,1200,430,1,2,233.66,234.17,1,1,1,1,233.58,234.41,505,600,2,2,233.53,234.43,10,105,1,2,233.5,234.5,100,63,1,4,233.45,234.75,15,1,1,1,233.4,234.79,110,2000,2,1,233.39,234.89,10,2,1,2,JPM
2024-10-21T12:12:51.507242100Z,2024-10-21T12:12:51.507076220Z,10,2,38,C,B,0,233.77,200,130,165880,12356356,233.71,234.0,26,154,1,7,233.7,234.06,1200,400,1,1,233.66,234.13,1,430,1,2,233.58,234.17,505,1,2,1,233.53,234.41,10,600,1,2,233.5,234.43,100,105,1,2,233.45,234.5,15,63,1,4,233.4,234.75,110,1,2,1,233.39,234.79,10,2000,1,1,233.31,234.89,110,2,2,2,JPM
2024-10-21T12:12:51.709392937Z,2024-10-21T12:12:51.709226597Z,10,2,38,A,B,0,233.77,200,130,166340,12356415,233.77,234.0,200,154,1,7,233.71,234.06,26,400,1,1,233.7,234.13,1200,430,1,2,233.66,234.17,1,1,1,1,233.58,234.41,505,600,2,2,233.53,234.43,10,105,1,2,233.5,234.5,100,63,1,4,233.45,234.75,15,1,1,1,233.4,234.79,110,2000,2,1,233.39,234.89,10,2,1,2,JPM
2024-10-21T12:12:52.481412276Z,2024-10-21T12:12:52.481246232Z,10,2,38,C,B,0,233.77,200,130,166044,12356788,233.71,234.0,26,154,1,7,233.7,234.06,1200,400,1,1,233.66,234.13,1,430,1,2,233.58,234.17,505,1,2,1,233.53,234.41,10,600,1,2,233.5,234.43,100,105,1,2,233.45,234.5,15,63,1,4,233.4,234.75,110,1,2,1,233.39,234.79,10,2000,1,1,233.31,234.89,110,2,2,2,JPM
2024-10-21T12:12:52.583011665Z,2024-10-21T12:12:52.582845276Z,10,2,38,A,B,0,233.77,200,130,166389,12356899,233.77,234.0,200,154,1,7,233.71,234.06,26,400,1,1,233.7,234.13,1200,430,1,2,233.66,234.17,1,1,1,1,233.58,234.41,505,600,2,2,233.53,234.43,10,105,1,2,233.5,234.5,100,63,1,4,233.45,234.75,15,1,1,1,233.4,234.79,110,2000,2,1,233.39,234.89,10,2,1,2,JPM
2024-10-21T12:12:53.923027418Z,2024-10-21T12:12:53.922861024Z,10,2,38,C,B,1,233.71,26,130,166394,12357591,233.77,234.0,200,154,1,7,233.7,234.06,1200,400,1,1,233.66,234.13,1,430,1,2,233.58,234.17,505,1,2,1,233.53,234.41,10,600,1,2,233.5,234.43,100,105,1,2,233.45,234.5,15,63,1,4,233.4,234.75,110,1,2,1,233.39,234.79,10,2000,1,1,233.31,234.89,110,2,2,2,JPM
2024-10-21T12:12:53.923129817Z,2024-10-21T12:12:53.922963386Z,10,2,38,A,B,1,233.76,27,130,166431,12357592,233.77,234.0,200,154,1,7,233.76,234.06,27,400,1,1,233.7,234.13,1200,430,1,2,233.66,234.17,1,1,1,1,233.58,234.41,505,600,2,2,233.53,234.43,10,105,1,2,233.5,234.5,100,63,1,4,233.45,234.75,15,1,1,1,233.4,234.79,110,2000,2,1,233.39,234.89,10,2,1,2,JPM
2024-10-21T12:12:59.629031962Z,2024-10-21T12:12:59.628865467Z,10,2,38,A,B,0,233.78,200,130,166495,12361324,233.78,234.0,200,154,1,7,233.76,234.06,27,400,1,1,233.7,234.13,1200,430,1,2,233.66,234.17,1,1,1,1,233.58,234.41,505,600,2,2,233.53,234.43,10,105,1,2,233.5,234.5,100,63,1,4,233.45,234.75,15,1,1,1,233.4,234.79,110,2000,2,1,233.39,234.89,10,2,1,2,JPM
2024-10-21T12:12:59.643903867Z,2024-10-21T12:12:59.643737494Z,10,2,38,A,B,1,233.77,26,130,166373,12361417,233.78,234.0,200,154,1,7,233.77,234.06,26,400,1,1,233.76,234.13,27,430,1,2,233.7,234.17,1200,1,1,1,233.66,234.41,1,600,1,2,233.58,234.43,505,105,2,2,233.53,234.5,10,63,1,4,233.5,234.75,100,1,1,1,233.45,234.79,15,2000,1,1,233.4,234.89,110,2,2,2,JPM
2024-10-21T12:12:59.691792264Z,2024-10-21T12:12:59.691625988Z,10,2,38,C,B,2,233.76,27,130,166276,12361539,233.78,234.0,200,154,1,7,233.77,234.06,26,400,1,1,233.7,234.13,1200,430,1,2,233.66,234.17,1,1,1,1,233.58,234.41,505,600,2,2,233.53,234.43,10,105,1,2,233.5,234.5,100,63,1,4,233.45,234.75,15,1,1,1,233.4,234.79,110,2000,2,1,233.39,234.89,10,2,1,2,JPM
2024-10-21T12:12:59.691815700Z,2024-10-21T12:12:59.691649558Z,10,2,38,C,B,1,233.77,26,130,166142,12361540,233.78,234.0,200,154,1,7,233.7,234.06,1200,400,1,1,233.66,234.13,1,430,1,2,233.58,234.17,505,1,2,1,233.53,234.41,10,600,1,2,233.5,234.43,100,105,1,2,233.45,234.5,15,63,1,4,233.4,234.75,110,1,2,1,233.39,234.79,10,2000,1,1,233.31,234.89,110,2,2,2,JPM
2024-10-21T12:12:59.691888302Z,2024-10-21T12:12:59.691721965Z,10,2,38,A,B,1,233.77,26,130,166337,12361541,233.78,234.0,200,154,1,7,233.77,234.06,26,400,1,1,233.7,234.13,1200,430,1,2,233.66,234.17,1,1,1,1,233.58,234.41,505,600,2,2,233.53,234.43,10,105,1,2,233.5,234.5,100,63,1,4,233.45,234.75,15,1,1,1,233.4,234.79,110,2000,2,1,233.39,234.89,10,2,1,2,JPM
2024-10-21T12:13:11.883895663Z,2024-10-21T12:13:11.883729412Z,10,2,38,C,A,1,234.06,400,130,166251,12371151,233.78,234.0,200,154,1,7,233.77,234.13,26,430,1,2,233.7,234.17,1200,1,1,1,233.66,234.41,1,600,1,2,233.58,234.43,505,105,2,2,233.53,234.5,10,63,1,4,233.5,234.75,100,1,1,1,233.45,234.79,15,2000,1,1,233.4,234.89,110,2,2,2,233.39,235.0,10,213,1,6,JPM
2024-10-21T12:13:11.920775720Z,2024-10-21T12:13:11.920609443Z,10,2,38,A,A,1,234.06,200,130,166277,12371429,233.78,234.0,200,154,1,7,233.77,234.06,26,200,1,1,233.7,234.13,1200,430,1,2,233.66,234.17,1,1,1,1,233.58,234.41,505,600,2,2,233.53,234.43,10,105,1,2,233.5,234.5,100,63,1,4,233.45,234.75,15,1,1,1,233.4,234.79,110,2000,2,1,233.39,234.89,10,2,1,2,JPM
2024-10-21T12:13:11.948803197Z,2024-10-21T12:13:11.948637105Z,10,2,38,A,A,1,234.06,200,130,166092,12371519,233.78,234.0,200,154,1,7,233.77,234.06,26,400,1,2,233.7,234.13,1200,430,1,2,233.66,234.17,1,1,1,1,233.58,234.41,505,600,2,2,233.53,234.43,10,105,1,2,233.5,234.5,100,63,1,4,233.45,234.75,15,1,1,1,233.4,234.79,110,2000,2,1,233.39,234.89,10,2,1,2,JPM
2024-10-21T12:13:21.543158873Z,2024-10-21T12:13:21.542992246Z,10,2,38,C,A,1,234.06,200,130,166627,12379437,233.78,234.0,200,154,1,7,233.77,234.06,26,200,1,1,233.7,234.13,1200,430,1,2,233.66,234.17,1,1,1,1,233.58,234.41,505,600,2,2,233.53,234.43,10,105,1,2,233.5,234.5,100,63,1,4,233.45,234.75,15,1,1,1,233.4,234.79,110,2000,2,1,233.39,234.89,10,2,1,2,JPM
2024-10-21T12:13:21.543168132Z,2024-10-21T12:13:21.543002194Z,10,2,38,C,A,1,234.06,200,130,165938,12379438,233.78,234.0,200,154,1,7,233.77,234.13,26,430,1,2,233.7,234.17,1200,1,1,1,233.66,234.41,1,600,1,2,233.58,234.43,505,105,2,2,233.53,234.5,10,63,1,4,233.5,234.75,100,1,1,1,233.45,234.79,15,2000,1,1,233.4,234.89,110,2,2,2,233.39,235.0,10,213,1,6,JPM
2024-10-21T12:13:21.543179396Z,2024-10-21T12:13:21.543013145Z,10,2,38,A,A,1,234.08,400,130,166251,12379439,233.78,234.0,200,154,1,7,233.77,234.08,26,400,1,1,233.7,234.13,1200,430,1,2,233.66,234.17,1,1,1,1,233.58,234.41,505,600,2,2,233.53,234.43,10,105,1,2,233.5,234.5,100,63,1,4,233.45,234.75,15,1,1,1,233.4,234.79,110,2000,2,1,233.39,234.89,10,2,1,2,JPM
2024-10-21T12:13:21.617302321Z,2024-10-21T12:13:21.617135979Z,10,2,38,C,B,1,233.77,26,130,166342,12379657,233.78,234.0,200,154,1,7,233.7,234.08,1200,400,1,1,233.66,234.13,1,430,1,2,233.58,234.17,505,1,2,1,233.53,234.41,10,600,1,2,233.5,234.43,100,105,1,2,233.45,234.5,15,63,1,4,233.4,234.75,110,1,2,1,233.39,234.79,10,2000,1,1,233.31,234.89,110,2,2,2,JPM
2024-10-21T12:13:21.617386770Z,2024-10-21T12:13:21.617220419Z,10,2,38,A,B,1,233.72,26,130,166351,12379659,233.78,234.0,200,154,1,7,233.72,234.08,26,400,1,1,233.7,234.13,1200,430,1,2,233.66,234.17,1,1,1,1,233.58,234.41,505,600,2,2,233.53,234.43,10,105,1,2,233.5,234.5,100,63,1,4,233.45,234.75,15,1,1,1,233.4,234.79,110,2000,2,1,233.39,234.89,10,2,1,2,JPM
2024-10-21T12:13:22.557998386Z,2024-10-21T12:13:22.557831797Z,10,2,38,A,A,1,234.07,400,130,166589,12380655,233.78,234.0,200,154,1,7,233.72,234.07,26,400,1,1,233.7,234.13,1200,430,1,2,233.66,234.17,1,1,1,1,233.58,234.41,505,600,2,2,233.53,234.43,10,105,1,2,233.5,234.5,100,63,1,4,233.45,234.75,15,1,1,1,233.4,234.79,110,2000,2,1,233.39,234.89,10,2,1,2,JPM
2024-10-21T12:13:25.372097284Z,2024-10-21T12:13:25.371930587Z,10,2,38,A,B,0,233.79,200,130,166697,12382998,233.79,234.0,200,154,1,7,233.72,234.07,26,400,1,1,233.7,234.13,1200,430,1,2,233.66,234.17,1,1,1,1,233.58,234.41,505,600,2,2,233.53,234.43,10,105,1,2,233.5,234.5,100,63,1,4,233.45,234.75,15,1,1,1,233.4,234.79,110,2000,2,1,233.39,234.89,10,2,1,2,JPM
2024-10-21T12:13:25.495708682Z,2024-10-21T12:13:25.495542627Z,10,2,38,C,B,1,233.72,26,130,166055,12383140,233.79,234.0,200,154,1,7,233.7,234.07,1200,400,1,1,233.66,234.13,1,430,1,2,233.58,234.17,505,1,2,1,233.53,234.41,10,600,1,2,233.5,234.43,100,105,1,2,233.45,234.5,15,63,1,4,233.4,234.75,110,1,2,1,233.39,234.79,10,2000,1,1,233.31,234.89,110,2,2,2,JPM
2024-10-21T12:13:25.495754875Z,2024-10-21T12:13:25.495588580Z,10,2,38,A,B,1,233.73,27,130,166295,12383141,233.79,234.0,200,154,1,7,233.73,234.07,27,400,1,1,233.7,234.13,1200,430,1,2,233.66,234.17,1,1,1,1,233.58,234.41,505,600,2,2,233.53,234.43,10,105,1,2,233.5,234.5,100,63,1,4,233.45,234.75,15,1,1,1,233.4,234.79,110,2000,2,1,233.39,234.89,10,2,1,2,JPM
2024-10-21T12:13:29.150506254Z,2024-10-21T12:13:29.150340169Z,10,2,38,A,A,3,234.15,30,130,166085,12386039,233.79,234.0,200,154,1,7,233.73,234.07,27,400,1,1,233.7,234.13,1200,430,1,2,233.66,234.15,1,30,1,1,233.58,234.17,505,1,2,1,233.53,234.41,10,600,1,2,233.5,234.43,100,105,1,2,233.45,234.5,15,63,1,4,233.4,234.75,110,1,2,1,233.39,234.79,10,2000,1,1,JPM
2024-10-21T12:13:29.268802068Z,2024-10-21T12:13:29.268636112Z,10,2,38,C,A,2,234.13,30,130,165956,12386279,233.79,234.0,200,154,1,7,233.73,234.07,27,400,1,1,233.7,234.13,1200,400,1,1,233.66,234.15,1,30,1,1,233.58,234.17,505,1,2,1,233.53,234.41,10,600,1,2,233.5,234.43,100,105,1,2,233.45,234.5,15,63,1,4,233.4,234.75,110,1,2,1,233.39,234.79,10,2000,1,1,JPM
2024-10-21T12:13:32.213848825Z,2024-10-21T12:13:32.213682828Z,10,2,38,C,A,1,234.07,400,130,165997,12388761,233.79,234.0,200,154,1,7,233.73,234.13,27,400,1,1,233.7,234.15,1200,30,1,1,233.66,234.17,1,1,1,1,233.58,234.41,505,600,2,2,233.53,234.43,10,105,1,2,233.5,234.5,100,63,1,4,233.45,234.75,15,1,1,1,233.4,234.79,110,2000,2,1,233.39,234.89,10,2,1,2,JPM
2024-10-21T12:13:32.213862106Z,2024-10-21T12:13:32.213695191Z,10,2,38,A,A,1,234.09,400,130,166915,12388762,233.79,234.0,200,154,1,7,233.73,234.09,27,400,1,1,233.7,234.13,1200,400,1,1,233.66,234.15,1,30,1,1,233.58,234.17,505,1,2,1,233.53,234.41,10,600,1,2,233.5,234.43,100,105,1,2,233.45,234.5,15,63,1,4,233.4,234.75,110,1,2,1,233.39,234.79,10,2000,1,1,JPM
2024-10-21T12:13:32.278971542Z,2024-10-21T12:13:32.278804796Z,10,2,38,A,B,0,233.8,200,130,166746,12388939,233.8,234.0,200,154,1,7,233.73,234.09,27,400,1,1,233.7,234.13,1200,400,1,1,233.66,234.15,1,30,1,1,233.58,234.17,505,1,2,1,233.53,234.41,10,600,1,2,233.5,234.43,100,105,1,2,233.45,234.5,15,63,1,4,233.4,234.75,110,1,2,1,233.39,234.79,10,2000,1,1,JPM
2024-10-21T12:13:32.362493854Z,2024-10-21T12:13:32.362327800Z,10,2,38,C,A,3,234.15,30,130,166054,12389254,233.8,234.0,200,154,1,7,233.73,234.09,27,400,1,1,233.7,234.13,1200,400,1,1,233.66,234.17,1,1,1,1,233.58,234.41,505,600,2,2,233.53,234.43,10,105,1,2,233.5,234.5,100,63,1,4,233.45,234.75,15,1,1,1,233.4,234.79,110,2000,2,1,233.39,234.89,10,2,1,2,JPM
2024-10-21T12:13:32.402038108Z,2024-10-21T12:13:32.401872088Z,10,2,38,C,B,1,233.73,27,130,166020,12389357,233.8,234.0,200,154,1,7,233.7,234.09,1200,400,1,1,233.66,234.13,1,400,1,1,233.58,234.17,505,1,2,1,233.53,234.41,10,600,1,2,233.5,234.43,100,105,1,2,233.45,234.5,15,63,1,4,233.4,234.75,110,1,2,1,233.39,234.79,10,2000,1,1,233.31,234.89,110,2,2,2,JPM
2024-10-21T12:13:32.412797711Z,2024-10-21T12:13:32.412631196Z,10,2,38,A,A,2,234.11,27,130,166515,12389377,233.8,234.0,200,154,1,7,233.7,234.09,1200,400,1,1,233.66,234.11,1,27,1,1,233.58,234.13,505,400,2,1,233.53,234.17,10,1,1,1,233.5,234.41,100,600,1,2,233.45,234.43,15,105,1,2,233.4,234.5,110,63,2,4,233.39,234.75,10,1,1,1,233.31,234.79,110,2000,2,1,JPM
2024-10-21T12:13:34.144890619Z,2024-10-21T12:13:34.144724456Z,10,2,38,A,B,0,233.89,100,130,166163,12390756,233.89,234.0,100,154,1,7,233.8,234.09,200,400,1,1,233.7,234.11,1200,27,1,1,233.66,234.13,1,400,1,1,233.58,234.17,505,1,2,1,233.53,234.41,10,600,1,2,233.5,234.43,100,105,1,2,233.45,234.5,15,63,1,4,233.4,234.75,110,1,2,1,233.39,234.79,10,2000,1,1,JPM
2024-10-21T12:13:34.145338999Z,2024-10-21T12:13:34.145172866Z,10,2,38,C,B,0,233.89,100,130,166133,12390759,233.8,234.0,200,154,1,7,233.7,234.09,1200,400,1,1,233.66,234.11,1,27,1,1,233.58,234.13,505,400,2,1,233.53,234.17,10,1,1,1,233.5,234.41,100,600,1,2,233.45,234.43,15,105,1,2,233.4,234.5,110,63,2,4,233.39,234.75,10,1,1,1,233.31,234.79,110,2000,2,1,JPM
2024-10-21T12:13:34.215444342Z,2024-10-21T12:13:34.215278319Z,10,2,38,C,A,2,234.11,27,130,166023,12390798,233.8,234.0,200,154,1,7,233.7,234.09,1200,400,1,1,233.66,234.13,1,400,1,1,233.58,234.17,505,1,2,1,233.53,234.41,10,600,1,2,233.5,234.43,100,105,1,2,233.45,234.5,15,63,1,4,233.4,234.75,110,1,2,1,233.39,234.79,10,2000,1,1,233.31,234.89,110,2,2,2,JPM
2024-10-21T12:13:34.277590859Z,2024-10-21T12:13:34.277424242Z,10,2,38,A,A,1,234.06,200,130,166617,12390835,233.8,234.0,200,154,1,7,233.7,234.06,1200,200,1,1,233.66,234.13,1,400,1,1,233.58,234.17,505,1,2,1,233.53,234.41,10,600,1,2,233.5,234.43,100,105,1,2,233.45,234.5,15,63,1,4,233.4,234.75,110,1,2,1,233.39,234.79,10,2000,1,1,233.31,234.89,110,2,2,2,JPM
2024-10-21T12:13:35.061243869Z,2024-10-21T12:13:35.061077358Z,10,2,38,A,B,0,233.81,200,130,166511,12391575,233.81,234.0,200,154,1,7,233.7,234.06,1200,200,1,1,233.66,234.13,1,400,1,1,233.58,234.17,505,1,2,1,233.53,234.41,10,600,1,2,233.5,234.43,100,105,1,2,233.45,234.5,15,63,1,4,233.4,234.75,110,1,2,1,233.39,234.79,10,2000,1,1,233.31,234.89,110,2,2,2,JPM
2024-10-21T12:13:35.075339842Z,2024-10-21T12:13:35.075174042Z,10,2,38,C,B,0,233.81,200,130,165800,12391728,233.7,234.0,1200,154,1,7,233.66,234.06,1,200,1,1,233.58,234.13,505,400,2,1,233.53,234.17,10,1,1,1,233.5,234.41,100,600,1,2,233.45,234.43,15,105,1,2,233.4,234.5,110,63,2,4,233.39,234.75,10,1,1,1,233.31,234.79,110,2000,2,1,233.3,234.89,100,2,1,2,JPM
2024-10-21T12:13:35.075350085Z,2024-10-21T12:13:35.075183720Z,10,2,38,A,B,0,233.74,200,130,166365,12391729,233.74,234.0,200,154,1,7,233.7,234.06,1200,200,1,1,233.66,234.13,1,400,1,1,233.58,234.17,505,1,2,1,233.53,234.41,10,600,1,2,233.5,234.43,100,105,1,2,233.45,234.5,15,63,1,4,233.4,234.75,110,1,2,1,233.39,234.79,10,2000,1,1,233.31,234.89,110,2,2,2,JPM
2024-10-21T12:13:35.077639622Z,2024-10-21T12:13:35.077473825Z,10,2,38,C,A,1,234.06,200,130,165797,12391777,233.74,234.0,200,154,1,7,233.7,234.13,1200,400,1,1,233.66,234.17,1,1,1,1,233.58,234.41,505,600,2,2,233.53,234.43,10,105,1,2,233.5,234.5,100,63,1,4,233.45,234.75,15,1,1,1,233.4,234.79,110,2000,2,1,233.39,234.89,10,2,1,2,233.31,235.0,110,213,2,6,JPM
2024-10-21T12:13:35.077651330Z,2024-10-21T12:13:35.077485044Z,10,2,38,A,A,1,234.08,200,130,166286,12391778,233.74,234.0,200,154,1,7,233.7,234.08,1200,200,1,1,233.66,234.13,1,400,1,1,233.58,234.17,505,1,2,1,233.53,234.41,10,600,1,2,233.5,234.43,100,105,1,2,233.45,234.5,15,63,1,4,233.4,234.75,110,1,2,1,233.39,234.79,10,2000,1,1,233.31,234.89,110,2,2,2,JPM
2024-10-21T12:13:35.086732850Z,2024-10-21T12:13:35.086566953Z,10,2,38,C,B,0,233.74,200,130,165897,12391883,233.7,234.0,1200,154,1,7,233.66,234.08,1,200,1,1,233.58,234.13,505,400,2,1,233.53,234.17,10,1,1,1,233.5,234.41,100,600,1,2,233.45,234.43,15,105,1,2,233.4,234.5,110,63,2,4,233.39,234.75,10,1,1,1,233.31,234.79,110,2000,2,1,233.3,234.89,100,2,1,2,JPM
2024-10-21T12:13:35.086745457Z,2024-10-21T12:13:35.086579076Z,10,2,38,A,B,0,233.72,400,130,166381,12391884,233.72,234.0,400,154,1,7,233.7,234.08,1200,200,1,1,233.66,234.13,1,400,1,1,233.58,234.17,505,1,2,1,233.53,234.41,10,600,1,2,233.5,234.43,100,105,1,2,233.45,234.5,15,63,1,4,233.4,234.75,110,1,2,1,233.39,234.79,10,2000,1,1,233.31,234.89,110,2,2,2,JPM
2024-10-21T12:13:35.108265805Z,2024-10-21T12:13:35.108095991Z,10,2,38,T,N,0,233.94,50,0,169814,12392002,233.72,234.0,400,154,1,7,233.7,234.08,1200,200,1,1,233.66,234.13,1,400,1,1,233.58,234.17,505,1,2,1,233.53,234.41,10,600,1,2,233.5,234.43,100,105,1,2,233.45,234.5,15,63,1,4,233.4,234.75,110,1,2,1,233.39,234.79,10,2000,1,1,233.31,234.89,110,2,2,2,JPM
2024-10-21T12:13:35.108265805Z,2024-10-21T12:13:35.108095991Z,10,2,38,T,N,0,233.93,50,0,169814,12392003,233.72,234.0,400,154,1,7,233.7,234.08,1200,200,1,1,233.66,234.13,1,400,1,1,233.58,234.17,505,1,2,1,233.53,234.41,10,600,1,2,233.5,234.43,100,105,1,2,233.45,234.5,15,63,1,4,233.4,234.75,110,1,2,1,233.39,234.79,10,2000,1,1,233.31,234.89,110,2,2,2,JPM
2024-10-21T12:13:35.108265805Z,2024-10-21T12:13:35.108095991Z,10,2,38,T,N,0,233.9,250,130,169814,12392004,233.72,234.0,400,154,1,7,233.7,234.08,1200,200,1,1,233.66,234.13,1,400,1,1,233.58,234.17,505,1,2,1,233.53,234.41,10,600,1,2,233.5,234.43,100,105,1,2,233.45,234.5,15,63,1,4,233.4,234.75,110,1,2,1,233.39,234.79,10,2000,1,1,233.31,234.89,110,2,2,2,JPM
2024-10-21T12:13:35.146538430Z,2024-10-21T12:13:35.146372690Z,10,2,38,C,B,0,233.72,400,130,165740,12392297,233.7,234.0,1200,154,1,7,233.66,234.08,1,200,1,1,233.58,234.13,505,400,2,1,233.53,234.17,10,1,1,1,233.5,234.41,100,600,1,2,233.45,234.43,15,105,1,2,233.4,234.5,110,63,2,4,233.39,234.75,10,1,1,1,233.31,234.79,110,2000,2,1,233.3,234.89,100,2,1,2,JPM
2024-10-21T12:13:35.146551508Z,2024-10-21T12:13:35.146384339Z,10,2,38,A,B,0,233.7,200,128,167169,12392298,233.7,234.0,1400,154,2,7,233.66,234.08,1,200,1,1,233.58,234.13,505,400,2,1,233.53,234.17,10,1,1,1,233.5,234.41,100,600,1,2,233.45,234.43,15,105,1,2,233.4,234.5,110,63,2,4,233.39,234.75,10,1,1,1,233.31,234.79,110,2000,2,1,233.3,234.89,100,2,1,2,JPM
2024-10-21T12:13:35.168035257Z,2024-10-21T12:13:35.167869345Z,10,2,38,C,B,0,233.7,200,130,165912,12392426,233.7,234.0,1200,154,1,7,233.66,234.08,1,200,1,1,233.58,234.13,505,400,2,1,233.53,234.17,10,1,1,1,233.5,234.41,100,600,1,2,233.45,234.43,15,105,1,2,233.4,234.5,110,63,2,4,233.39,234.75,10,1,1,1,233.31,234.79,110,2000,2,1,233.3,234.89,100,2,1,2,JPM
2024-10-21T12:13:35.175958206Z,2024-10-21T12:13:35.175791647Z,10,2,38,A,B,2,233.64,200,130,166559,12392448,233.7,234.0,1200,154,1,7,233.66,234.08,1,200,1,1,233.64,234.13,200,400,1,1,233.58,234.17,505,1,2,1,233.53,234.41,10,600,1,2,233.5,234.43,100,105,1,2,233.45,234.5,15,63,1,4,233.4,234.75,110,1,2,1,233.39,234.79,10,2000,1,1,233.31,234.89,110,2,2,2,JPM
2024-10-21T12:13:35.334095780Z,2024-10-21T12:13:35.333929432Z,10,2,38,A,B,2,233.65,200,130,166348,12392747,233.7,234.0,1200,154,1,7,233.66,234.08,1,200,1,1,233.65,234.13,200,400,1,1,233.58,234.17,505,1,2,1,233.53,234.41,10,600,1,2,233.5,234.43,100,105,1,2,233.45,234.5,15,63,1,4,233.4,234.75,110,1,2,1,233.39,234.79,10,2000,1,1,233.31,234.89,110,2,2,2,JPM
2024-10-21T12:13:35.352463215Z,2024-10-21T12:13:35.352296693Z,10,2,38,A,B,0,233.7,200,130,166522,12392766,233.7,234.0,1400,154,2,7,233.66,234.08,1,200,1,1,233.58,234.13,505,400,2,1,233.53,234.17,10,1,1,1,233.5,234.41,100,600,1,2,233.45,234.43,15,105,1,2,233.4,234.5,110,63,2,4,233.39,234.75,10,1,1,1,233.31,234.79,110,2000,2,1,233.3,234.89,100,2,1,2,JPM
2024-10-21T12:13:35.424517936Z,2024-10-21T12:13:35.424351548Z,10,2,38,A,B,0,233.72,200,130,166388,12392793,233.72,234.0,200,154,1,7,233.7,234.08,1200,200,1,1,233.66,234.13,1,400,1,1,233.58,234.17,505,1,2,1,233.53,234.41,10,600,1,2,233.5,234.43,100,105,1,2,233.45,234.5,15,63,1,4,233.4,234.75,110,1,2,1,233.39,234.79,10,2000,1,1,233.31,234.89,110,2,2,2,JPM
2024-10-21T12:13:38.132138622Z,2024-10-21T12:13:38.131971887Z,10,2,38,A,B,0,233.77,200,130,166735,12394618,233.77,234.0,200,154,1,7,233.7,234.08,1200,200,1,1,233.66,234.13,1,400,1,1,233.58,234.17,505,1,2,1,233.53,234.41,10,600,1,2,233.5,234.43,100,105,1,2,233.45,234.5,15,63,1,4,233.4,234.75,110,1,2,1,233.39,234.79,10,2000,1,1,233.31,234.89,110,2,2,2,JPM
2024-10-21T12:13:42.509253965Z,2024-10-21T12:13:42.509087486Z,10,2,38,A,B,1,233.76,29,130,166479,12397192,233.77,234.0,200,154,1,7,233.76,234.08,29,200,1,1,233.7,234.13,1200,400,1,1,233.66,234.17,1,1,1,1,233.58,234.41,505,600,2,2,233.53,234.43,10,105,1,2,233.5,234.5,100,63,1,4,233.45,234.75,15,1,1,1,233.4,234.79,110,2000,2,1,233.39,234.89,10,2,1,2,JPM
2024-10-21T12:13:42.509287026Z,2024-10-21T12:13:42.509120725Z,10,2,38,A,A,2,234.13,29,130,166301,12397193,233.77,234.0,200,154,1,7,233.76,234.08,29,200,1,1,233.7,234.13,1200,429,1,2,233.66,234.17,1,1,1,1,233.58,234.41,505,600,2,2,233.53,234.43,10,105,1,2,233.5,234.5,100,63,1,4,233.45,234.75,15,1,1,1,233.4,234.79,110,2000,2,1,233.39,234.89,10,2,1,2,JPM
2024-10-21T12:13:45.327521347Z,2024-10-21T12:13:45.327353906Z,10,2,38,A,A,1,234.07,200,130,167441,12399281,233.77,234.0,200,154,1,7,233.76,234.07,29,200,1,1,233.7,234.13,1200,429,1,2,233.66,234.17,1,1,1,1,233.58,234.41,505,600,2,2,233.53,234.43,10,105,1,2,233.5,234.5,100,63,1,4,233.45,234.75,15,1,1,1,233.4,234.79,110,2000,2,1,233.39,234.89,10,2,1,2,JPM
2024-10-21T12:13:45.348446565Z,2024-10-21T12:13:45.348280342Z,10,2,38,C,A,2,234.13,29,130,166223,12399379,233.77,234.0,200,154,1,7,233.76,234.07,29,200,1,1,233.7,234.13,1200,400,1,1,233.66,234.17,1,1,1,1,233.58,234.41,505,600,2,2,233.53,234.43,10,105,1,2,233.5,234.5,100,63,1,4,233.45,234.75,15,1,1,1,233.4,234.79,110,2000,2,1,233.39,234.89,10,2,1,2,JPM
2024-10-21T12:13:45.348489295Z,2024-10-21T12:13:45.348322946Z,10,2,38,A,A,2,234.12,26,130,166349,12399380,233.77,234.0,200,154,1,7,233.76,234.07,29,200,1,1,233.7,234.12,1200,26,1,1,233.66,234.13,1,400,1,1,233.58,234.17,505,1,2,1,233.53,234.41,10,600,1,2,233.5,234.43,100,105,1,2,233.45,234.5,15,63,1,4,233.4,234.75,110,1,2,1,233.39,234.79,10,2000,1,1,JPM
2024-10-21T12:13:45.469223815Z,2024-10-21T12:13:45.469056600Z,10,2,38,T,N,0,233.98,18,130,167215,12399561,233.77,234.0,200,154,1,7,233.76,234.07,29,200,1,1,233.7,234.12,1200,26,1,1,233.66,234.13,1,400,1,1,233.58,234.17,505,1,2,1,233.53,234.41,10,600,1,2,233.5,234.43,100,105,1,2,233.45,234.5,15,63,1,4,233.4,234.75,110,1,2,1,233.39,234.79,10,2000,1,1,JPM
2024-10-21T12:13:45.811636426Z,2024-10-21T12:13:45.811467280Z,10,2,38,T,N,0,233.98,77,0,169146,12400065,233.77,234.0,200,154,1,7,233.76,234.07,29,200,1,1,233.7,234.12,1200,26,1,1,233.66,234.13,1,400,1,1,233.58,234.17,505,1,2,1,233.53,234.41,10,600,1,2,233.5,234.43,100,105,1,2,233.45,234.5,15,63,1,4,233.4,234.75,110,1,2,1,233.39,234.79,10,2000,1,1,JPM
2024-10-21T12:13:45.811636426Z,2024-10-21T12:13:45.811467280Z,10,2,38,T,B,0,234.0,20,0,169146,12400066,233.77,234.0,200,154,1,7,233.76,234.07,29,200,1,1,233.7,234.12,1200,26,1,1,233.66,234.13,1,400,1,1,233.58,234.17,505,1,2,1,233.53,234.41,10,600,1,2,233.5,234.43,100,105,1,2,233.45,234.5,15,63,1,4,233.4,234.75,110,1,2,1,233.39,234.79,10,2000,1,1,JPM
2024-10-21T12:13:45.811636426Z,2024-10-21T12:13:45.811467280Z,10,2,38,T,B,0,234.0,3,130,169146,12400067,233.77,234.0,200,134,1,6,233.76,234.07,29,200,1,1,233.7,234.12,1200,26,1,1,233.66,234.13,1,400,1,1,233.58,234.17,505,1,2,1,233.53,234.41,10,600,1,2,233.5,234.43,100,105,1,2,233.45,234.5,15,63,1,4,233.4,234.75,110,1,2,1,233.39,234.79,10,2000,1,1,JPM
2024-10-21T12:13:45.811636426Z,2024-10-21T12:13:45.811467280Z,10,2,38,C,A,0,234.0,3,130,169146,12400067,233.77,234.0,200,131,1,6,233.76,234.07,29,200,1,1,233.7,234.12,1200,26,1,1,233.66,234.13,1,400,1,1,233.58,234.17,505,1,2,1,233.53,234.41,10,600,1,2,233.5,234.43,100,105,1,2,233.45,234.5,15,63,1,4,233.4,234.75,110,1,2,1,233.39,234.79,10,2000,1,1,JPM
2024-10-21T12:13:45.811643125Z,2024-10-21T12:13:45.811476289Z,10,2,38,C,A,1,234.07,200,130,166836,12400068,233.77,234.0,200,131,1,6,233.76,234.12,29,26,1,1,233.7,234.13,1200,400,1,1,233.66,234.17,1,1,1,1,233.58,234.41,505,600,2,2,233.53,234.43,10,105,1,2,233.5,234.5,100,63,1,4,233.45,234.75,15,1,1,1,233.4,234.79,110,2000,2,1,233.39,234.89,10,2,1,2,JPM
2024-10-21T12:13:45.811657243Z,2024-10-21T12:13:45.811491355Z,10,2,38,A,B,0,233.9,100,130,165888,12400070,233.9,234.0,100,131,1,6,233.77,234.12,200,26,1,1,233.76,234.13,29,400,1,1,233.7,234.17,1200,1,1,1,233.66,234.41,1,600,1,2,233.58,234.43,505,105,2,2,233.53,234.5,10,63,1,4,233.5,234.75,100,1,1,1,233.45,234.79,15,2000,1,1,233.4,234.89,110,2,2,2,JPM
2024-10-21T12:13:45.811666921Z,2024-10-21T12:13:45.811500957Z,10,2,38,A,B,0,233.92,100,130,165964,12400071,233.92,234.0,100,131,1,6,233.9,234.12,100,26,1,1,233.77,234.13,200,400,1,1,233.76,234.17,29,1,1,1,233.7,234.41,1200,600,1,2,233.66,234.43,1,105,1,2,233.58,234.5,505,63,2,4,233.53,234.75,10,1,1,1,233.5,234.79,100,2000,1,1,233.45,234.89,15,2,1,2,JPM
2024-10-21T12:13:45.811683758Z,2024-10-21T12:13:45.811510984Z,10,2,38,T,B,0,234.0,27,0,172774,12400072,233.92,234.0,100,131,1,6,233.9,234.12,100,26,1,1,233.77,234.13,200,400,1,1,233.76,234.17,29,1,1,1,233.7,234.41,1200,600,1,2,233.66,234.43,1,105,1,2,233.58,234.5,505,63,2,4,233.53,234.75,10,1,1,1,233.5,234.79,100,2000,1,1,233.45,234.89,15,2,1,2,JPM
2024-10-21T12:13:45.811683758Z,2024-10-21T12:13:45.811510984Z,10,2,38,T,B,0,234.0,50,0,172774,12400073,233.92,234.0,100,104,1,5,233.9,234.12,100,26,1,1,233.77,234.13,200,400,1,1,233.76,234.17,29,1,1,1,233.7,234.41,1200,600,1,2,233.66,234.43,1,105,1,2,233.58,234.5,505,63,2,4,233.53,234.75,10,1,1,1,233.5,234.79,100,2000,1,1,233.45,234.89,15,2,1,2,JPM
2024-10-21T12:13:45.811683758Z,2024-10-21T12:13:45.811510984Z,10,2,38,T,B,0,234.0,2,0,172774,12400074,233.92,234.0,100,54,1,4,233.9,234.12,100,26,1,1,233.77,234.13,200,400,1,1,233.76,234.17,29,1,1,1,233.7,234.41,1200,600,1,2,233.66,234.43,1,105,1,2,233.58,234.5,505,63,2,4,233.53,234.75,10,1,1,1,233.5,234.79,100,2000,1,1,233.45,234.89,15,2,1,2,JPM
2024-10-21T12:13:45.811683758Z,2024-10-21T12:13:45.811510984Z,10,2,38,T,B,0,234.0,1,0,172774,12400075,233.92,234.0,100,52,1,3,233.9,234.12,100,26,1,1,233.77,234.13,200,400,1,1,233.76,234.17,29,1,1,1,233.7,234.41,1200,600,1,2,233.66,234.43,1,105,1,2,233.58,234.5,505,63,2,4,233.53,234.75,10,1,1,1,233.5,234.79,100,2000,1,1,233.45,234.89,15,2,1,2,JPM
2024-10-21T12:13:45.811683758Z,2024-10-21T12:13:45.811510984Z,10,2,38,T,B,0,234.0,50,0,172774,12400076,233.92,234.0,100,51,1,2,233.9,234.12,100,26,1,1,233.77,234.13,200,400,1,1,233.76,234.17,29,1,1,1,233.7,234.41,1200,600,1,2,233.66,234.43,1,105,1,2,233.58,234.5,505,63,2,4,233.53,234.75,10,1,1,1,233.5,234.79,100,2000,1,1,233.45,234.89,15,2,1,2,JPM
2024-10-21T12:13:45.811683758Z,2024-10-21T12:13:45.811510984Z,10,2,38,T,B,0,234.0,1,130,172774,12400077,233.92,234.0,100,1,1,1,233.9,234.12,100,26,1,1,233.77,234.13,200,400,1,1,233.76,234.17,29,1,1,1,233.7,234.41,1200,600,1,2,233.66,234.43,1,105,1,2,233.58,234.5,505,63,2,4,233.53,234.75,10,1,1,1,233.5,234.79,100,2000,1,1,233.45,234.89,15,2,1,2,JPM
2024-10-21T12:13:45.811683758Z,2024-10-21T12:13:45.811510984Z,10,2,38,C,A,0,234.0,1,130,172774,12400077,233.92,234.12,100,26,1,1,233.9,234.13,100,400,1,1,233.77,234.17,200,1,1,1,233.76,234.41,29,600,1,2,233.7,234.43,1200,105,1,2,233.66,234.5,1,63,1,4,233.58,234.75,505,1,2,1,233.53,234.79,10,2000,1,1,233.5,234.89,100,2,1,2,233.45,235.0,15,213,1,6,JPM
2024-10-21T12:13:45.811695806Z,2024-10-21T12:13:45.811530148Z,10,2,38,C,B,1,233.9,100,130,165658,12400078,233.92,234.12,100,26,1,1,233.77,234.13,200,400,1,1,233.76,234.17,29,1,1,1,233.7,234.41,1200,600,1,2,233.66,234.43,1,105,1,2,233.58,234.5,505,63,2,4,233.53,234.75,10,1,1,1,233.5,234.79,100,2000,1,1,233.45,234.89,15,2,1,2,233.4,235.0,110,213,2,6,JPM
2024-10-21T12:13:45.811710080Z,2024-10-21T12:13:45.811542984Z,10,2,38,A,B,0,233.96,100,130,167096,12400079,233.96,234.12,100,26,1,1,233.92,234.13,100,400,1,1,233.77,234.17,200,1,1,1,233.76,234.41,29,600,1,2,233.7,234.43,1200,105,1,2,233.66,234.5,1,63,1,4,233.58,234.75,505,1,2,1,233.53,234.79,10,2000,1,1,233.5,234.89,100,2,1,2,233.45,235.0,15,213,1,6,JPM
2024-10-21T12:13:45.811712078Z,2024-10-21T12:13:45.811544514Z,10,2,38,A,B,0,233.96,24,130,167564,12400080,233.96,234.12,124,26,2,1,233.92,234.13,100,400,1,1,233.77,234.17,200,1,1,1,233.76,234.41,29,600,1,2,233.7,234.43,1200,105,1,2,233.66,234.5,1,63,1,4,233.58,234.75,505,1,2,1,233.53,234.79,10,2000,1,1,233.5,234.89,100,2,1,2,233.45,235.0,15,213,1,6,JPM
2024-10-21T12:13:45.811715761Z,2024-10-21T12:13:45.811549682Z,10,2,38,A,B,1,233.94,100,130,166079,12400081,233.96,234.12,124,26,2,1,233.94,234.13,100,400,1,1,233.92,234.17,100,1,1,1,233.77,234.41,200,600,1,2,233.76,234.43,29,105,1,2,233.7,234.5,1200,63,1,4,233.66,234.75,1,1,1,1,233.58,234.79,505,2000,2,1,233.53,234.89,10,2,1,2,233.5,235.0,100,213,1,6,JPM
2024-10-21T12:13:45.811718296Z,2024-10-21T12:13:45.811550754Z,10,2,38,A,B,0,233.96,28,130,167542,12400082,233.96,234.12,152,26,3,1,233.94,234.13,100,400,1,1,233.92,234.17,100,1,1,1,233.77,234.41,200,600,1,2,233.76,234.43,29,105,1,2,233.7,234.5,1200,63,1,4,233.66,234.75,1,1,1,1,233.58,234.79,505,2000,2,1,233.53,234.89,10,2,1,2,233.5,235.0,100,213,1,6,JPM
2024-10-21T12:13:45.811721349Z,2024-10-21T12:13:45.811554820Z,10,2,38,A,B,0,233.96,100,130,166529,12400083,233.96,234.12,252,26,4,1,233.94,234.13,100,400,1,1,233.92,234.17,100,1,1,1,233.77,234.41,200,600,1,2,233.76,234.43,29,105,1,2,233.7,234.5,1200,63,1,4,233.66,234.75,1,1,1,1,233.58,234.79,505,2000,2,1,233.53,234.89,10,2,1,2,233.5,235.0,100,213,1,6,JPM
2024-10-21T12:13:45.811732936Z,2024-10-21T12:13:45.811565809Z,10,2,38,A,B,0,233.96,100,128,167127,12400085,233.96,234.12,352,26,5,1,233.94,234.13,100,400,1,1,233.93,234.17,28,1,1,1,233.92,234.41,100,600,1,2,233.77,234.43,200,105,1,2,233.76,234.5,29,63,1,4,233.7,234.75,1200,1,1,1,233.66,234.79,1,2000,1,1,233.58,234.89,505,2,2,2,233.53,235.0,10,213,1,6,JPM
2024-10-21T12:13:45.811742859Z,2024-10-21T12:13:45.811576962Z,10,2,38,A,B,0,233.96,100,130,165897,12400087,233.96,234.12,452,26,6,1,233.94,234.13,100,400,1,1,233.93,234.17,28,1,1,1,233.92,234.41,100,600,1,2,233.77,234.43,200,105,1,2,233.76,234.5,29,63,1,4,233.7,234.75,1200,1,1,1,233.66,234.79,1,2000,1,1,233.58,234.89,505,2,2,2,233.53,235.0,10,213,1,6,JPM
2024-10-21T12:13:45.811753896Z,2024-10-21T12:13:45.811587865Z,10,2,38,A,B,0,233.96,100,130,166031,12400088,233.96,234.12,552,26,7,1,233.94,234.13,100,400,1,1,233.93,234.17,28,1,1,1,233.92,234.41,100,600,1,2,233.77,234.43,200,105,1,2,233.76,234.5,29,63,1,4,233.7,234.75,1200,1,1,1,233.66,234.79,1,2000,1,1,233.58,234.89,505,2,2,2,233.53,235.0,10,213,1,6,JPM
2024-10-21T12:13:45.811765786Z,2024-10-21T12:13:45.811599315Z,10,2,38,A,B,1,233.94,100,130,166471,12400089,233.96,234.12,552,26,7,1,233.94,234.13,200,400,2,1,233.93,234.17,28,1,1,1,233.92,234.41,100,600,1,2,233.77,234.43,200,105,1,2,233.76,234.5,29,63,1,4,233.7,234.75,1200,1,1,1,233.66,234.79,1,2000,1,1,233.58,234.89,505,2,2,2,233.53,235.0,10,213,1,6,JPM
2024-10-21T12:13:45.811791584Z,2024-10-21T12:13:45.811625820Z,10,2,38,C,B,0,233.96,100,130,165764,12400091,233.96,234.12,452,26,6,1,233.94,234.13,200,400,2,1,233.93,234.17,28,1,1,1,233.92,234.41,100,600,1,2,233.77,234.43,200,105,1,2,233.76,234.5,29,63,1,4,233.7,234.75,1200,1,1,1,233.66,234.79,1,2000,1,1,233.58,234.89,505,2,2,2,233.53,235.0,10,213,1,6,JPM
2024-10-21T12:13:45.811800458Z,2024-10-21T12:13:45.811631245Z,10,2,38,T,N,0,234.0,145,130,169213,12400092,233.96,234.12,452,26,6,1,233.94,234.13,200,400,2,1,233.93,234.17,28,1,1,1,233.92,234.41,100,600,1,2,233.77,234.43,200,105,1,2,233.76,234.5,29,63,1,4,233.7,234.75,1200,1,1,1,233.66,234.79,1,2000,1,1,233.58,234.89,505,2,2,2,233.53,235.0,10,213,1,6,JPM
2024-10-21T12:13:45.811805292Z,2024-10-21T12:13:45.811639570Z,10,2,38,C,B,1,233.94,100,130,165722,12400093,233.96,234.12,452,26,6,1,233.94,234.13,100,400,1,1,233.93,234.17,28,1,1,1,233.92,234.41,100,600,1,2,233.77,234.43,200,105,1,2,233.76,234.5,29,63,1,4,233.7,234.75,1200,1,1,1,233.66,234.79,1,2000,1,1,233.58,234.89,505,2,2,2,233.53,235.0,10,213,1,6,JPM
2024-10-21T12:13:45.811808010Z,2024-10-21T12:13:45.811642361Z,10,2,38,C,B,0,233.96,100,130,165649,12400094,233.96,234.12,352,26,5,1,233.94,234.13,100,400,1,1,233.93,234.17,28,1,1,1,233.92,234.41,100,600,1,2,233.77,234.43,200,105,1,2,233.76,234.5,29,63,1,4,233.7,234.75,1200,1,1,1,233.66,234.79,1,2000,1,1,233.58,234.89,505,2,2,2,233.53,235.0,10,213,1,6,JPM
2024-10-21T12:13:45.811822560Z,2024-10-21T12:13:45.811656818Z,10,2,38,C,B,0,233.96,100,130,165742,12400095,233.96,234.12,252,26,4,1,233.94,234.13,100,400,1,1,233.93,234.17,28,1,1,1,233.92,234.41,100,600,1,2,233.77,234.43,200,105,1,2,233.76,234.5,29,63,1,4,233.7,234.75,1200,1,1,1,233.66,234.79,1,2000,1,1,233.58,234.89,505,2,2,2,233.53,235.0,10,213,1,6,JPM
2024-10-21T12:13:45.811837891Z,2024-10-21T12:13:45.811672313Z,10,2,38,C,B,0,233.96,100,130,165578,12400096,233.96,234.12,152,26,3,1,233.94,234.13,100,400,1,1,233.93,234.17,28,1,1,1,233.92,234.41,100,600,1,2,233.77,234.43,200,105,1,2,233.76,234.5,29,63,1,4,233.7,234.75,1200,1,1,1,233.66,234.79,1,2000,1,1,233.58,234.89,505,2,2,2,233.53,235.0,10,213,1,6,JPM
2024-10-21T12:13:45.811853381Z,2024-10-21T12:13:45.811687403Z,10,2,38,C,B,0,233.96,100,130,165978,12400097,233.96,234.12,52,26,2,1,233.94,234.13,100,400,1,1,233.93,234.17,28,1,1,1,233.92,234.41,100,600,1,2,233.77,234.43,200,105,1,2,233.76,234.5,29,63,1,4,233.7,234.75,1200,1,1,1,233.66,234.79,1,2000,1,1,233.58,234.89,505,2,2,2,233.53,235.0,10,213,1,6,JPM
2024-10-21T12:13:45.811867704Z,2024-10-21T12:13:45.811702067Z,10,2,38,C,B,1,233.94,100,130,165637,12400098,233.96,234.12,52,26,2,1,233.93,234.13,28,400,1,1,233.92,234.17,100,1,1,1,233.77,234.41,200,600,1,2,233.76,234.43,29,105,1,2,233.7,234.5,1200,63,1,4,233.66,234.75,1,1,1,1,233.58,234.79,505,2000,2,1,233.53,234.89,10,2,1,2,233.5,235.0,100,213,1,6,JPM
2024-10-21T12:13:45.812203001Z,2024-10-21T12:13:45.812035805Z,10,2,38,A,B,3,233.9,100,130,167196,12400100,233.96,234.12,52,26,2,1,233.93,234.13,28,400,1,1,233.92,234.17,100,1,1,1,233.9,234.41,100,600,1,2,233.77,234.43,200,105,1,2,233.76,234.5,29,63,1,4,233.7,234.75,1200,1,1,1,233.66,234.79,1,2000,1,1,233.58,234.89,505,2,2,2,233.53,235.0,10,213,1,6,JPM
2024-10-21T12:13:45.812647427Z,2024-10-21T12:13:45.812481448Z,10,2,38,C,B,3,233.9,100,130,165979,12400102,233.96,234.12,52,26,2,1,233.93,234.13,28,400,1,1,233.92,234.17,100,1,1,1,233.77,234.41,200,600,1,2,233.76,234.43,29,105,1,2,233.7,234.5,1200,63,1,4,233.66,234.75,1,1,1,1,233.58,234.79,505,2000,2,1,233.53,234.89,10,2,1,2,233.5,235.0,100,213,1,6,JPM
2024-10-21T12:13:45.813181508Z,2024-10-21T12:13:45.813014463Z,10,2,38,T,N,0,234.08,1,130,167045,12400103,233.96,234.12,52,26,2,1,233.93,234.13,28,400,1,1,233.92,234.17,100,1,1,1,233.77,234.41,200,600,1,2,233.76,234.43,29,105,1,2,233.7,234.5,1200,63,1,4,233.66,234.75,1,1,1,1,233.58,234.79,505,2000,2,1,233.53,234.89,10,2,1,2,233.5,235.0,100,213,1,6,JPM
2024-10-21T12:13:45.813988388Z,2024-10-21T12:13:45.813822327Z,10,2,38,C,B,2,233.92,100,130,166061,12400110,233.96,234.12,52,26,2,1,233.93,234.13,28,400,1,1,233.77,234.17,200,1,1,1,233.76,234.41,29,600,1,2,233.7,234.43,1200,105,1,2,233.66,234.5,1,63,1,4,233.58,234.75,505,1,2,1,233.53,234.79,10,2000,1,1,233.5,234.89,100,2,1,2,233.45,235.0,15,213,1,6,JPM
2024-10-21T12:13:45.885716957Z,2024-10-21T12:13:45.885550872Z,10,2,38,C,A,0,234.12,26,130,166085,12401368,233.96,234.13,52,400,2,1,233.93,234.17,28,1,1,1,233.77,234.41,200,600,1,2,233.76,234.43,29,105,1,2,233.7,234.5,1200,63,1,4,233.66,234.75,1,1,1,1,233.58,234.79,505,2000,2,1,233.53,234.89,10,2,1,2,233.5,235.0,100,213,1,6,233.45,235.03,15,2,1,1,JPM
2024-10-21T12:13:45.885769234Z,2024-10-21T12:13:45.885603142Z,10,2,38,A,A,2,234.18,27,130,166092,12401370,233.96,234.13,52,400,2,1,233.93,234.17,28,1,1,1,233.77,234.18,200,27,1,1,233.76,234.41,29,600,1,2,233.7,234.43,1200,105,1,2,233.66,234.5,1,63,1,4,233.58,234.75,505,1,2,1,233.53,234.79,10,2000,1,1,233.5,234.89,100,2,1,2,233.45,235.0,15,213,1,6,JPM
2024-10-21T12:13:45.911785815Z,2024-10-21T12:13:45.911619430Z,10,2,38,C,B,0,233.96,24,130,166385,12401559,233.96,234.13,28,400,1,1,233.93,234.17,28,1,1,1,233.77,234.18,200,27,1,1,233.76,234.41,29,600,1,2,233.7,234.43,1200,105,1,2,233.66,234.5,1,63,1,4,233.58,234.75,505,1,2,1,233.53,234.79,10,2000,1,1,233.5,234.89,100,2,1,2,233.45,235.0,15,213,1,6,JPM
2024-10-21T12:13:45.911812280Z,2024-10-21T12:13:45.911645974Z,10,2,38,C,B,1,233.93,28,130,166306,12401560,233.96,234.13,28,400,1,1,233.77,234.17,200,1,1,1,233.76,234.18,29,27,1,1,233.7,234.41,1200,600,1,2,233.66,234.43,1,105,1,2,233.58,234.5,505,63,2,4,233.53,234.75,10,1,1,1,233.5,234.79,100,2000,1,1,233.45,234.89,15,2,1,2,233.4,235.0,110,213,2,6,JPM
2024-10-21T12:13:45.935434703Z,2024-10-21T12:13:45.935267342Z,10,2,38,A,B,1,233.78,200,128,167361,12401727,233.96,234.13,28,400,1,1,233.78,234.17,200,1,1,1,233.76,234.18,29,27,1,1,233.7,234.41,1200,600,1,2,233.66,234.43,1,105,1,2,233.58,234.5,505,63,2,4,233.53,234.75,10,1,1,1,233.5,234.79,100,2000,1,1,233.45,234.89,15,2,1,2,233.4,235.0,110,213,2,6,JPM
2024-10-21T12:13:45.969762895Z,2024-10-21T12:13:45.969596688Z,10,2,38,A,A,0,234.12,200,130,166207,12401874,233.96,234.12,28,200,1,1,233.78,234.13,200,400,1,1,233.76,234.17,29,1,1,1,233.7,234.18,1200,27,1,1,233.66,234.41,1,600,1,2,233.58,234.43,505,105,2,2,233.53,234.5,10,63,1,4,233.5,234.75,100,1,1,1,233.45,234.79,15,2000,1,1,233.4,234.89,110,2,2,2,JPM
2024-10-21T12:13:45.972375870Z,2024-10-21T12:13:45.972210032Z,10,2,38,C,A,0,234.12,200,130,165838,12401877,233.96,234.13,28,400,1,1,233.78,234.17,200,1,1,1,233.76,234.18,29,27,1,1,233.7,234.41,1200,600,1,2,233.66,234.43,1,105,1,2,233.58,234.5,505,63,2,4,233.53,234.75,10,1,1,1,233.5,234.79,100,2000,1,1,233.45,234.89,15,2,1,2,233.4,235.0,110,213,2,6,JPM
2024-10-21T12:13:45.973746612Z,2024-10-21T12:13:45.973580511Z,10,2,38,A,A,3,234.19,200,130,166101,12401884,233.96,234.13,28,400,1,1,233.78,234.17,200,1,1,1,233.76,234.18,29,27,1,1,233.7,234.19,1200,200,1,1,233.66,234.41,1,600,1,2,233.58,234.43,505,105,2,2,233.53,234.5,10,63,1,4,233.5,234.75,100,1,1,1,233.45,234.79,15,2000,1,1,233.4,234.89,110,2,2,2,JPM
2024-10-21T12:13:46.001542260Z,2024-10-21T12:13:46.001375930Z,10,2,38,A,A,3,234.19,200,130,166330,12401962,233.96,234.13,28,400,1,1,233.78,234.17,200,1,1,1,233.76,234.18,29,27,1,1,233.7,234.19,1200,400,1,2,233.66,234.41,1,600,1,2,233.58,234.43,505,105,2,2,233.53,234.5,10,63,1,4,233.5,234.75,100,1,1,1,233.45,234.79,15,2000,1,1,233.4,234.89,110,2,2,2,JPM
2024-10-21T12:13:46.030544628Z,2024-10-21T12:13:46.030378750Z,10,2,38,C,A,3,234.19,200,130,165878,12402092,233.96,234.13,28,400,1,1,233.78,234.17,200,1,1,1,233.76,234.18,29,27,1,1,233.7,234.19,1200,200,1,1,233.66,234.41,1,600,1,2,233.58,234.43,505,105,2,2,233.53,234.5,10,63,1,4,233.5,234.75,100,1,1,1,233.45,234.79,15,2000,1,1,233.4,234.89,110,2,2,2,JPM
2024-10-21T12:13:46.030557325Z,2024-10-21T12:13:46.030391116Z,10,2,38,A,A,0,234.12,400,130,166209,12402093,233.96,234.12,28,400,1,1,233.78,234.13,200,400,1,1,233.76,234.17,29,1,1,1,233.7,234.18,1200,27,1,1,233.66,234.41,1,600,1,2,233.58,234.43,505,105,2,2,233.53,234.5,10,63,1,4,233.5,234.75,100,1,1,1,233.45,234.79,15,2000,1,1,233.4,234.89,110,2,2,2,JPM
2024-10-21T12:13:46.063401404Z,2024-10-21T12:13:46.063235483Z,10,2,38,C,B,0,233.96,28,130,165921,12402125,233.78,234.12,200,400,1,1,233.76,234.13,29,400,1,1,233.7,234.17,1200,1,1,1,233.66,234.18,1,27,1,1,233.58,234.41,505,600,2,2,233.53,234.43,10,105,1,2,233.5,234.5,100,63,1,4,233.45,234.75,15,1,1,1,233.4,234.79,110,2000,2,1,233.39,234.89,10,2,1,2,JPM
2024-10-21T12:13:46.072888556Z,2024-10-21T12:13:46.072722298Z,10,2,38,C,A,0,234.12,400,130,166258,12402143,233.78,234.13,200,400,1,1,233.76,234.17,29,1,1,1,233.7,234.18,1200,27,1,1,233.66,234.41,1,600,1,2,233.58,234.43,505,105,2,2,233.53,234.5,10,63,1,4,233.5,234.75,100,1,1,1,233.45,234.79,15,2000,1,1,233.4,234.89,110,2,2,2,233.39,235.0,10,213,1,6,JPM
2024-10-21T12:13:46.072911952Z,2024-10-21T12:13:46.072745549Z,10,2,38,A,A,0,234.13,200,130,166403,12402144,233.78,234.13,200,600,1,2,233.76,234.17,29,1,1,1,233.7,234.18,1200,27,1,1,233.66,234.41,1,600,1,2,233.58,234.43,505,105,2,2,233.53,234.5,10,63,1,4,233.5,234.75,100,1,1,1,233.45,234.79,15,2000,1,1,233.4,234.89,110,2,2,2,233.39,235.0,10,213,1,6,JPM
2024-10-21T12:13:46.073218239Z,2024-10-21T12:13:46.073052339Z,10,2,38,C,B,1,233.76,29,130,165900,12402146,233.78,234.13,200,600,1,2,233.7,234.17,1200,1,1,1,233.66,234.18,1,27,1,1,233.58,234.41,505,600,2,2,233.53,234.43,10,105,1,2,233.5,234.5,100,63,1,4,233.45,234.75,15,1,1,1,233.4,234.79,110,2000,2,1,233.39,234.89,10,2,1,2,233.31,235.0,110,213,2,6,JPM
2024-10-21T12:13:46.073303600Z,2024-10-21T12:13:46.073137112Z,10,2,38,A,B,0,233.81,27,130,166488,12402147,233.81,234.13,27,600,1,2,233.78,234.17,200,1,1,1,233.7,234.18,1200,27,1,1,233.66,234.41,1,600,1,2,233.58,234.43,505,105,2,2,233.53,234.5,10,63,1,4,233.5,234.75,100,1,1,1,233.45,234.79,15,2000,1,1,233.4,234.89,110,2,2,2,233.39,235.0,10,213,1,6,JPM
2024-10-21T12:13:46.123490913Z,2024-10-21T12:13:46.123324204Z,10,2,38,A,B,0,233.83,200,130,166709,12402220,233.83,234.13,200,600,1,2,233.81,234.17,27,1,1,1,233.7,234.18,1200,27,1,1,233.66,234.41,1,600,1,2,233.58,234.43,505,105,2,2,233.53,234.5,10,63,1,4,233.5,234.75,100,1,1,1,233.45,234.79,15,2000,1,1,233.4,234.89,110,2,2,2,233.39,235.0,10,213,1,6,JPM
2024-10-21T12:13:46.134519400Z,2024-10-21T12:13:46.134353286Z,10,2,38,C,B,0,233.83,200,130,166114,12402230,233.81,234.13,27,600,1,2,233.7,234.17,1200,1,1,1,233.66,234.18,1,27,1,1,233.58,234.41,505,600,2,2,233.53,234.43,10,105,1,2,233.5,234.5,100,63,1,4,233.45,234.75,15,1,1,1,233.4,234.79,110,2000,2,1,233.39,234.89,10,2,1,2,233.31,235.0,110,213,2,6,JPM
2024-10-21T12:13:46.134533664Z,2024-10-21T12:13:46.134366429Z,10,2,38,A,B,1,233.78,200,130,167235,12402231,233.81,234.13,27,600,1,2,233.78,234.17,200,1,1,1,233.7,234.18,1200,27,1,1,233.66,234.41,1,600,1,2,233.58,234.43,505,105,2,2,233.53,234.5,10,63,1,4,233.5,234.75,100,1,1,1,233.45,234.79,15,2000,1,1,233.4,234.89,110,2,2,2,233.39,235.0,10,213,1,6,JPM
2024-10-21T12:13:46.134975052Z,2024-10-21T12:13:46.134809159Z,10,2,38,C,B,0,233.81,27,130,165893,12402233,233.78,234.13,200,600,1,2,233.7,234.17,1200,1,1,1,233.66,234.18,1,27,1,1,233.58,234.41,505,600,2,2,233.53,234.43,10,105,1,2,233.5,234.5,100,63,1,4,233.45,234.75,15,1,1,1,233.4,234.79,110,2000,2,1,233.39,234.89,10,2,1,2,233.31,235.0,110,213,2,6,JPM
2024-10-21T12:13:47.415528384Z,2024-10-21T12:13:47.415362307Z,10,2,38,A,B,1,233.76,27,130,166077,12403393,233.78,234.13,200,600,1,2,233.76,234.17,27,1,1,1,233.7,234.18,1200,27,1,1,233.66,234.41,1,600,1,2,233.58,234.43,505,105,2,2,233.53,234.5,10,63,1,4,233.5,234.75,100,1,1,1,233.45,234.79,15,2000,1,1,233.4,234.89,110,2,2,2,233.39,235.0,10,213,1,6,JPM
2024-10-21T12:13:48.136535794Z,2024-10-21T12:13:48.136368928Z,10,2,38,C,A,0,234.13,200,130,166866,12404229,233.78,234.13,200,400,1,1,233.76,234.17,27,1,1,1,233.7,234.18,1200,27,1,1,233.66,234.41,1,600,1,2,233.58,234.43,505,105,2,2,233.53,234.5,10,63,1,4,233.5,234.75,100,1,1,1,233.45,234.79,15,2000,1,1,233.4,234.89,110,2,2,2,233.39,235.0,10,213,1,6,JPM
2024-10-21T12:13:48.136548342Z,2024-10-21T12:13:48.136382005Z,10,2,38,A,A,1,234.16,200,130,166337,12404230,233.78,234.13,200,400,1,1,233.76,234.16,27,200,1,1,233.7,234.17,1200,1,1,1,233.66,234.18,1,27,1,1,233.58,234.41,505,600,2,2,233.53,234.43,10,105,1,2,233.5,234.5,100,63,1,4,233.45,234.75,15,1,1,1,233.4,234.79,110,2000,2,1,233.39,234.89,10,2,1,2,JPM
2024-10-21T12:13:54.483454950Z,2024-10-21T12:13:54.483288659Z,10,2,38,A,A,1,234.16,200,130,166291,12409382,233.78,234.13,200,400,1,1,233.76,234.16,27,400,1,2,233.7,234.17,1200,1,1,1,233.66,234.18,1,27,1,1,233.58,234.41,505,600,2,2,233.53,234.43,10,105,1,2,233.5,234.5,100,63,1,4,233.45,234.75,15,1,1,1,233.4,234.79,110,2000,2,1,233.39,234.89,10,2,1,2,JPM
2024-10-21T12:13:54.519925421Z,2024-10-21T12:13:54.519759447Z,10,2,38,C,A,1,234.16,200,130,165974,12409407,233.78,234.13,200,400,1,1,233.76,234.16,27,200,1,1,233.7,234.17,1200,1,1,1,233.66,234.18,1,27,1,1,233.58,234.41,505,600,2,2,233.53,234.43,10,105,1,2,233.5,234.5,100,63,1,4,233.45,234.75,15,1,1,1,233.4,234.79,110,2000,2,1,233.39,234.89,10,2,1,2,JPM
2024-10-21T12:13:54.519938916Z,2024-10-21T12:13:54.519772638Z,10,2,38,A,A,1,234.15,200,130,166278,12409408,233.78,234.13,200,400,1,1,233.76,234.15,27,200,1,1,233.7,234.17,1200,1,1,1,233.66,234.18,1,27,1,1,233.58,234.41,505,600,2,2,233.53,234.43,10,105,1,2,233.5,234.5,100,63,1,4,233.45,234.75,15,1,1,1,233.4,234.79,110,2000,2,1,233.39,234.89,10,2,1,2,JPM
2024-10-21T12:13:55.034277634Z,2024-10-21T12:13:55.034111535Z,10,2,38,C,A,3,234.18,27,130,166099,12410122,233.78,234.13,200,400,1,1,233.76,234.15,27,200,1,1,233.7,234.17,1200,1,1,1,233.66,234.41,1,600,1,2,233.58,234.43,505,105,2,2,233.53,234.5,10,63,1,4,233.5,234.75,100,1,1,1,233.45,234.79,15,2000,1,1,233.4,234.89,110,2,2,2,233.39,235.0,10,213,1,6,JPM
2024-10-21T12:13:55.034369213Z,2024-10-21T12:13:55.034202690Z,10,2,38,A,A,2,234.17,28,130,166523,12410123,233.78,234.13,200,400,1,1,233.76,234.15,27,200,1,1,233.7,234.17,1200,29,1,2,233.66,234.41,1,600,1,2,233.58,234.43,505,105,2,2,233.53,234.5,10,63,1,4,233.5,234.75,100,1,1,1,233.45,234.79,15,2000,1,1,233.4,234.89,110,2,2,2,233.39,235.0,10,213,1,6,JPM
2024-10-21T12:13:56.094704759Z,2024-10-21T12:13:56.094538941Z,10,2,38,C,B,0,233.78,200,130,165818,12410937,233.76,234.13,27,400,1,1,233.7,234.15,1200,200,1,1,233.66,234.17,1,29,1,2,233.58,234.41,505,600,2,2,233.53,234.43,10,105,1,2,233.5,234.5,100,63,1,4,233.45,234.75,15,1,1,1,233.4,234.79,110,2000,2,1,233.39,234.89,10,2,1,2,233.31,235.0,110,213,2,6,JPM
2024-10-21T12:13:56.094717739Z,2024-10-21T12:13:56.094551306Z,10,2,38,A,B,0,233.76,200,130,166433,12410939,233.76,234.13,227,400,2,1,233.7,234.15,1200,200,1,1,233.66,234.17,1,29,1,2,233.58,234.41,505,600,2,2,233.53,234.43,10,105,1,2,233.5,234.5,100,63,1,4,233.45,234.75,15,1,1,1,233.4,234.79,110,2000,2,1,233.39,234.89,10,2,1,2,233.31,235.0,110,213,2,6,JPM
2024-10-21T12:13:56.154373830Z,2024-10-21T12:13:56.154206963Z,10,2,38,A,A,1,234.15,200,130,166867,12411142,233.76,234.13,227,400,2,1,233.7,234.15,1200,400,1,2,233.66,234.17,1,29,1,2,233.58,234.41,505,600,2,2,233.53,234.43,10,105,1,2,233.5,234.5,100,63,1,4,233.45,234.75,15,1,1,1,233.4,234.79,110,2000,2,1,233.39,234.89,10,2,1,2,233.31,235.0,110,213,2,6,JPM
2024-10-21T12:13:56.211883968Z,2024-10-21T12:13:56.211718188Z,10,2,38,C,A,1,234.15,200,130,165780,12411252,233.76,234.13,227,400,2,1,233.7,234.15,1200,200,1,1,233.66,234.17,1,29,1,2,233.58,234.41,505,600,2,2,233.53,234.43,10,105,1,2,233.5,234.5,100,63,1,4,233.45,234.75,15,1,1,1,233.4,234.79,110,2000,2,1,233.39,234.89,10,2,1,2,233.31,235.0,110,213,2,6,JPM
2024-10-21T12:13:56.211897481Z,2024-10-21T12:13:56.211731379Z,10,2,38,A,A,1,234.14,200,130,166102,12411253,233.76,234.13,227,400,2,1,233.7,234.14,1200,200,1,1,233.66,234.17,1,29,1,2,233.58,234.41,505,600,2,2,233.53,234.43,10,105,1,2,233.5,234.5,100,63,1,4,233.45,234.75,15,1,1,1,233.4,234.79,110,2000,2,1,233.39,234.89,10,2,1,2,233.31,235.0,110,213,2,6,JPM
2024-10-21T12:14:01.071130699Z,2024-10-21T12:14:01.070964390Z,10,2,38,C,A,2,234.17,28,130,166309,12416529,233.76,234.13,227,400,2,1,233.7,234.14,1200,200,1,1,233.66,234.17,1,1,1,1,233.58,234.41,505,600,2,2,233.53,234.43,10,105,1,2,233.5,234.5,100,63,1,4,233.45,234.75,15,1,1,1,233.4,234.79,110,2000,2,1,233.39,234.89,10,2,1,2,233.31,235.0,110,213,2,6,JPM
2024-10-21T12:14:01.071182062Z,2024-10-21T12:14:01.071015450Z,10,2,38,A,A,2,234.16,27,130,166612,12416530,233.76,234.13,227,400,2,1,233.7,234.14,1200,200,1,1,233.66,234.16,1,27,1,1,233.58,234.17,505,1,2,1,233.53,234.41,10,600,1,2,233.5,234.43,100,105,1,2,233.45,234.5,15,63,1,4,233.4,234.75,110,1,2,1,233.39,234.79,10,2000,1,1,233.31,234.89,110,2,2,2,JPM
2024-10-21T12:14:01.088302919Z,2024-10-21T12:14:01.088137086Z,10,2,38,C,B,0,233.76,27,130,165833,12416650,233.76,234.13,200,400,1,1,233.7,234.14,1200,200,1,1,233.66,234.16,1,27,1,1,233.58,234.17,505,1,2,1,233.53,234.41,10,600,1,2,233.5,234.43,100,105,1,2,233.45,234.5,15,63,1,4,233.4,234.75,110,1,2,1,233.39,234.79,10,2000,1,1,233.31,234.89,110,2,2,2,JPM
2024-10-21T12:14:06.103621053Z,2024-10-21T12:14:06.103454338Z,10,2,38,A,B,0,233.97,5,130,166715,12421860,233.97,234.13,5,400,1,1,233.76,234.14,200,200,1,1,233.7,234.16,1200,27,1,1,233.66,234.17,1,1,1,1,233.58,234.41,505,600,2,2,233.53,234.43,10,105,1,2,233.5,234.5,100,63,1,4,233.45,234.75,15,1,1,1,233.4,234.79,110,2000,2,1,233.39,234.89,10,2,1,2,JPM
2024-10-21T12:14:07.746906258Z,2024-10-21T12:14:07.746740079Z,10,2,38,C,B,1,233.76,200,130,166179,12423513,233.97,234.13,5,400,1,1,233.7,234.14,1200,200,1,1,233.66,234.16,1,27,1,1,233.58,234.17,505,1,2,1,233.53,234.41,10,600,1,2,233.5,234.43,100,105,1,2,233.45,234.5,15,63,1,4,233.4,234.75,110,1,2,1,233.39,234.79,10,2000,1,1,233.31,234.89,110,2,2,2,JPM
2024-10-21T12:14:07.746920572Z,2024-10-21T12:14:07.746754069Z,10,2,38,A,B,1,233.73,200,130,166503,12423514,233.97,234.13,5,400,1,1,233.73,234.14,200,200,1,1,233.7,234.16,1200,27,1,1,233.66,234.17,1,1,1,1,233.58,234.41,505,600,2,2,233.53,234.43,10,105,1,2,233.5,234.5,100,63,1,4,233.45,234.75,15,1,1,1,233.4,234.79,110,2000,2,1,233.39,234.89,10,2,1,2,JPM
2024-10-21T12:14:10.801508542Z,2024-10-21T12:14:10.801342166Z,10,2,38,A,B,1,233.8,200,130,166376,12425721,233.97,234.13,5,400,1,1,233.8,234.14,200,200,1,1,233.7,234.16,1200,27,1,1,233.66,234.17,1,1,1,1,233.58,234.41,505,600,2,2,233.53,234.43,10,105,1,2,233.5,234.5,100,63,1,4,233.45,234.75,15,1,1,1,233.4,234.79,110,2000,2,1,233.39,234.89,10,2,1,2,JPM
2024-10-21T12:14:17.947604712Z,2024-10-21T12:14:17.947438449Z,10,2,38,A,B,1,233.81,200,130,166263,12431541,233.97,234.13,5,400,1,1,233.81,234.14,200,200,1,1,233.7,234.16,1200,27,1,1,233.66,234.17,1,1,1,1,233.58,234.41,505,600,2,2,233.53,234.43,10,105,1,2,233.5,234.5,100,63,1,4,233.45,234.75,15,1,1,1,233.4,234.79,110,2000,2,1,233.39,234.89,10,2,1,2,JPM
2024-10-21T12:14:17.957549086Z,2024-10-21T12:14:17.957382887Z,10,2,38,C,B,1,233.81,200,130,166199,12431585,233.97,234.13,5,400,1,1,233.7,234.14,1200,200,1,1,233.66,234.16,1,27,1,1,233.58,234.17,505,1,2,1,233.53,234.41,10,600,1,2,233.5,234.43,100,105,1,2,233.45,234.5,15,63,1,4,233.4,234.75,110,1,2,1,233.39,234.79,10,2000,1,1,233.31,234.89,110,2,2,2,JPM
2024-10-21T12:14:17.957562118Z,2024-10-21T12:14:17.957395933Z,10,2,38,A,B,1,233.74,200,130,166185,12431586,233.97,234.13,5,400,1,1,233.74,234.14,200,200,1,1,233.7,234.16,1200,27,1,1,233.66,234.17,1,1,1,1,233.58,234.41,505,600,2,2,233.53,234.43,10,105,1,2,233.5,234.5,100,63,1,4,233.45,234.75,15,1,1,1,233.4,234.79,110,2000,2,1,233.39,234.89,10,2,1,2,JPM
2024-10-21T12:14:17.957619401Z,2024-10-21T12:14:17.957453277Z,10,2,38,C,A,1,234.14,200,130,166124,12431587,233.97,234.13,5,400,1,1,233.74,234.16,200,27,1,1,233.7,234.17,1200,1,1,1,233.66,234.41,1,600,1,2,233.58,234.43,505,105,2,2,233.53,234.5,10,63,1,4,233.5,234.75,100,1,1,1,233.45,234.79,15,2000,1,1,233.4,234.89,110,2,2,2,233.39,235.0,10,213,1,6,JPM
2024-10-21T12:14:17.957631871Z,2024-10-21T12:14:17.957465815Z,10,2,38,A,A,1,234.15,200,130,166056,12431588,233.97,234.13,5,400,1,1,233.74,234.15,200,200,1,1,233.7,234.16,1200,27,1,1,233.66,234.17,1,1,1,1,233.58,234.41,505,600,2,2,233.53,234.43,10,105,1,2,233.5,234.5,100,63,1,4,233.45,234.75,15,1,1,1,233.4,234.79,110,2000,2,1,233.39,234.89,10,2,1,2,JPM
2024-10-21T12:14:18.057051301Z,2024-10-21T12:14:18.056884935Z,10,2,38,A,B,1,233.75,200,130,166366,12431913,233.97,234.13,5,400,1,1,233.75,234.15,200,200,1,1,233.7,234.16,1200,27,1,1,233.66,234.17,1,1,1,1,233.58,234.41,505,600,2,2,233.53,234.43,10,105,1,2,233.5,234.5,100,63,1,4,233.45,234.75,15,1,1,1,233.4,234.79,110,2000,2,1,233.39,234.89,10,2,1,2,JPM
2024-10-21T12:14:21.022420708Z,2024-10-21T12:14:21.022254267Z,10,2,38,A,B,1,233.77,200,130,166441,12433640,233.97,234.13,5,400,1,1,233.77,234.15,200,200,1,1,233.7,234.16,1200,27,1,1,233.66,234.17,1,1,1,1,233.58,234.41,505,600,2,2,233.53,234.43,10,105,1,2,233.5,234.5,100,63,1,4,233.45,234.75,15,1,1,1,233.4,234.79,110,2000,2,1,233.39,234.89,10,2,1,2,JPM
2024-10-21T12:14:21.336855528Z,2024-10-21T12:14:21.336689135Z,10,2,38,C,A,1,234.15,200,130,166393,12433903,233.97,234.13,5,400,1,1,233.77,234.16,200,27,1,1,233.7,234.17,1200,1,1,1,233.66,234.41,1,600,1,2,233.58,234.43,505,105,2,2,233.53,234.5,10,63,1,4,233.5,234.75,100,1,1,1,233.45,234.79,15,2000,1,1,233.4,234.89,110,2,2,2,233.39,235.0,10,213,1,6,JPM
2024-10-21T12:14:21.336867325Z,2024-10-21T12:14:21.336700928Z,10,2,38,A,A,2,234.17,200,130,166397,12433905,233.97,234.13,5,400,1,1,233.77,234.16,200,27,1,1,233.7,234.17,1200,201,1,2,233.66,234.41,1,600,1,2,233.58,234.43,505,105,2,2,233.53,234.5,10,63,1,4,233.5,234.75,100,1,1,1,233.45,234.79,15,2000,1,1,233.4,234.89,110,2,2,2,233.39,235.0,10,213,1,6,JPM
2024-10-21T12:14:21.392793975Z,2024-10-21T12:14:21.392627701Z,10,2,38,A,B,1,233.78,200,130,166274,12433982,233.97,234.13,5,400,1,1,233.78,234.16,200,27,1,1,233.7,234.17,1200,201,1,2,233.66,234.41,1,600,1,2,233.58,234.43,505,105,2,2,233.53,234.5,10,63,1,4,233.5,234.75,100,1,1,1,233.45,234.79,15,2000,1,1,233.4,234.89,110,2,2,2,233.39,235.0,10,213,1,6,JPM
2024-10-21T12:14:21.427147627Z,2024-10-21T12:14:21.426981432Z,10,2,38,C,A,1,234.16,27,130,166195,12434166,233.97,234.13,5,400,1,1,233.78,234.17,200,201,1,2,233.7,234.41,1200,600,1,2,233.66,234.43,1,105,1,2,233.58,234.5,505,63,2,4,233.53,234.75,10,1,1,1,233.5,234.79,100,2000,1,1,233.45,234.89,15,2,1,2,233.4,235.0,110,213,2,6,233.39,235.03,10,2,1,1,JPM
2024-10-21T12:14:21.740752948Z,2024-10-21T12:14:21.740586460Z,10,2,38,A,B,2,233.76,29,130,166488,12434650,233.97,234.13,5,400,1,1,233.78,234.17,200,201,1,2,233.76,234.41,29,600,1,2,233.7,234.43,1200,105,1,2,233.66,234.5,1,63,1,4,233.58,234.75,505,1,2,1,233.53,234.79,10,2000,1,1,233.5,234.89,100,2,1,2,233.45,235.0,15,213,1,6,233.4,235.03,110,2,2,1,JPM
2024-10-21T12:14:21.740783568Z,2024-10-21T12:14:21.740617322Z,10,2,38,A,A,2,234.18,28,130,166246,12434651,233.97,234.13,5,400,1,1,233.78,234.17,200,201,1,2,233.76,234.18,29,28,1,1,233.7,234.41,1200,600,1,2,233.66,234.43,1,105,1,2,233.58,234.5,505,63,2,4,233.53,234.75,10,1,1,1,233.5,234.79,100,2000,1,1,233.45,234.89,15,2,1,2,233.4,235.0,110,213,2,6,JPM
2024-10-21T12:14:28.747385812Z,2024-10-21T12:14:28.747219089Z,10,2,38,A,B,1,233.79,200,130,166723,12439708,233.97,234.13,5,400,1,1,233.79,234.17,200,201,1,2,233.76,234.18,29,28,1,1,233.7,234.41,1200,600,1,2,233.66,234.43,1,105,1,2,233.58,234.5,505,63,2,4,233.53,234.75,10,1,1,1,233.5,234.79,100,2000,1,1,233.45,234.89,15,2,1,2,233.4,235.0,110,213,2,6,JPM
2024-10-21T12:14:37.348331123Z,2024-10-21T12:14:37.348164372Z,10,2,38,C,B,1,233.79,200,130,166751,12446142,233.97,234.13,5,400,1,1,233.76,234.17,29,201,1,2,233.7,234.18,1200,28,1,1,233.66,234.41,1,600,1,2,233.58,234.43,505,105,2,2,233.53,234.5,10,63,1,4,233.5,234.75,100,1,1,1,233.45,234.79,15,2000,1,1,233.4,234.89,110,2,2,2,233.39,235.0,10,213,1,6,JPM
2024-10-21T12:14:37.348344285Z,2024-10-21T12:14:37.348177626Z,10,2,38,A,B,1,233.77,200,130,166659,12446143,233.97,234.13,5,400,1,1,233.77,234.17,200,201,1,2,233.76,234.18,29,28,1,1,233.7,234.41,1200,600,1,2,233.66,234.43,1,105,1,2,233.58,234.5,505,63,2,4,233.53,234.75,10,1,1,1,233.5,234.79,100,2000,1,1,233.45,234.89,15,2,1,2,233.4,235.0,110,213,2,6,JPM
2024-10-21T12:14:37.485597454Z,2024-10-21T12:14:37.485431160Z,10,2,38,A,B,1,233.78,200,130,166294,12446234,233.97,234.13,5,400,1,1,233.78,234.17,200,201,1,2,233.76,234.18,29,28,1,1,233.7,234.41,1200,600,1,2,233.66,234.43,1,105,1,2,233.58,234.5,505,63,2,4,233.53,234.75,10,1,1,1,233.5,234.79,100,2000,1,1,233.45,234.89,15,2,1,2,233.4,235.0,110,213,2,6,JPM
2024-10-21T12:14:41.549332947Z,2024-10-21T12:14:41.549166803Z,10,2,38,C,B,2,233.76,29,130,166144,12448595,233.97,234.13,5,400,1,1,233.78,234.17,200,201,1,2,233.7,234.18,1200,28,1,1,233.66,234.41,1,600,1,2,233.58,234.43,505,105,2,2,233.53,234.5,10,63,1,4,233.5,234.75,100,1,1,1,233.45,234.79,15,2000,1,1,233.4,234.89,110,2,2,2,233.39,235.0,10,213,1,6,JPM
2024-10-21T12:14:41.549378383Z,2024-10-21T12:14:41.549212050Z,10,2,38,A,B,1,233.81,28,130,166333,12448596,233.97,234.13,5,400,1,1,233.81,234.17,28,201,1,2,233.78,234.18,200,28,1,1,233.7,234.41,1200,600,1,2,233.66,234.43,1,105,1,2,233.58,234.5,505,63,2,4,233.53,234.75,10,1,1,1,233.5,234.79,100,2000,1,1,233.45,234.89,15,2,1,2,233.4,235.0,110,213,2,6,JPM
2024-10-21T12:14:41.599757577Z,2024-10-21T12:14:41.599590898Z,10,2,38,A,B,1,233.87,200,130,166679,12448666,233.97,234.13,5,400,1,1,233.87,234.17,200,201,1,2,233.81,234.18,28,28,1,1,233.7,234.41,1200,600,1,2,233.66,234.43,1,105,1,2,233.58,234.5,505,63,2,4,233.53,234.75,10,1,1,1,233.5,234.79,100,2000,1,1,233.45,234.89,15,2,1,2,233.4,235.0,110,213,2,6,JPM
2024-10-21T12:14:43.206124405Z,2024-10-21T12:14:43.205958056Z,10,2,38,A,A,1,234.16,200,130,166349,12449507,233.97,234.13,5,400,1,1,233.87,234.16,200,200,1,1,233.81,234.17,28,1,1,1,233.7,234.18,1200,28,1,1,233.66,234.41,1,600,1,2,233.58,234.43,505,105,2,2,233.53,234.5,10,63,1,4,233.5,234.75,100,1,1,1,233.45,234.79,15,2000,1,1,233.4,234.89,110,2,2,2,JPM
2024-10-21T12:14:49.824860694Z,2024-10-21T12:14:49.824694031Z,10,2,38,A,A,1,234.16,200,130,166663,12453535,233.97,234.13,5,400,1,1,233.87,234.16,200,400,1,2,233.81,234.17,28,1,1,1,233.7,234.18,1200,28,1,1,233.66,234.41,1,600,1,2,233.58,234.43,505,105,2,2,233.53,234.5,10,63,1,4,233.5,234.75,100,1,1,1,233.45,234.79,15,2000,1,1,233.4,234.89,110,2,2,2,JPM
2024-10-21T12:14:52.414059791Z,2024-10-21T12:14:52.413893215Z,10,2,38,C,B,1,233.87,200,130,166576,12455999,233.97,234.13,5,400,1,1,233.81,234.16,28,400,1,2,233.7,234.17,1200,1,1,1,233.66,234.18,1,28,1,1,233.58,234.41,505,600,2,2,233.53,234.43,10,105,1,2,233.5,234.5,100,63,1,4,233.45,234.75,15,1,1,1,233.4,234.79,110,2000,2,1,233.39,234.89,10,2,1,2,JPM
2024-10-21T12:14:52.414071390Z,2024-10-21T12:14:52.413904869Z,10,2,38,A,B,1,233.85,200,130,166521,12456000,233.97,234.13,5,400,1,1,233.85,234.16,200,400,1,2,233.81,234.17,28,1,1,1,233.7,234.18,1200,28,1,1,233.66,234.41,1,600,1,2,233.58,234.43,505,105,2,2,233.53,234.5,10,63,1,4,233.5,234.75,100,1,1,1,233.45,234.79,15,2000,1,1,233.4,234.89,110,2,2,2,JPM
2024-10-21T12:14:52.473505418Z,2024-10-21T12:14:52.473339217Z,10,2,38,C,A,1,234.16,200,130,166201,12456232,233.97,234.13,5,400,1,1,233.85,234.16,200,200,1,1,233.81,234.17,28,1,1,1,233.7,234.18,1200,28,1,1,233.66,234.41,1,600,1,2,233.58,234.43,505,105,2,2,233.53,234.5,10,63,1,4,233.5,234.75,100,1,1,1,233.45,234.79,15,2000,1,1,233.4,234.89,110,2,2,2,JPM
2024-10-21T12:14:52.473518693Z,2024-10-21T12:14:52.473352225Z,10,2,38,A,A,1,234.15,200,130,166468,12456234,233.97,234.13,5,400,1,1,233.85,234.15,200,200,1,1,233.81,234.17,28,1,1,1,233.7,234.18,1200,28,1,1,233.66,234.41,1,600,1,2,233.58,234.43,505,105,2,2,233.53,234.5,10,63,1,4,233.5,234.75,100,1,1,1,233.45,234.79,15,2000,1,1,233.4,234.89,110,2,2,2,JPM
2024-10-21T12:14:52.474565706Z,2024-10-21T12:14:52.474399706Z,10,2,38,C,A,3,234.18,28,130,166000,12456246,233.97,234.13,5,400,1,1,233.85,234.15,200,200,1,1,233.81,234.17,28,1,1,1,233.7,234.41,1200,600,1,2,233.66,234.43,1,105,1,2,233.58,234.5,505,63,2,4,233.53,234.75,10,1,1,1,233.5,234.79,100,2000,1,1,233.45,234.89,15,2,1,2,233.4,235.0,110,213,2,6,JPM
2024-10-21T12:14:52.474619355Z,2024-10-21T12:14:52.474453011Z,10,2,38,A,A,2,234.17,29,130,166344,12456247,233.97,234.13,5,400,1,1,233.85,234.15,200,200,1,1,233.81,234.17,28,30,1,2,233.7,234.41,1200,600,1,2,233.66,234.43,1,105,1,2,233.58,234.5,505,63,2,4,233.53,234.75,10,1,1,1,233.5,234.79,100,2000,1,1,233.45,234.89,15,2,1,2,233.4,235.0,110,213,2,6,JPM
2024-10-21T12:14:53.024832003Z,2024-10-21T12:14:53.024665699Z,10,2,38,A,A,1,234.15,200,130,166304,12457068,233.97,234.13,5,400,1,1,233.85,234.15,200,400,1,2,233.81,234.17,28,30,1,2,233.7,234.41,1200,600,1,2,233.66,234.43,1,105,1,2,233.58,234.5,505,63,2,4,233.53,234.75,10,1,1,1,233.5,234.79,100,2000,1,1,233.45,234.89,15,2,1,2,233.4,235.0,110,213,2,6,JPM
2024-10-21T12:14:59.069231899Z,2024-10-21T12:14:59.069065580Z,10,2,38,A,B,1,233.86,200,130,166319,12461167,233.97,234.13,5,400,1,1,233.86,234.15,200,400,1,2,233.81,234.17,28,30,1,2,233.7,234.41,1200,600,1,2,233.66,234.43,1,105,1,2,233.58,234.5,505,63,2,4,233.53,234.75,10,1,1,1,233.5,234.79,100,2000,1,1,233.45,234.89,15,2,1,2,233.4,235.0,110,213,2,6,JPM
2024-10-21T12:15:05.174166268Z,2024-10-21T12:15:05.174000161Z,10,2,38,C,A,1,234.15,200,130,166107,12470009,233.97,234.13,5,400,1,1,233.86,234.15,200,200,1,1,233.81,234.17,28,30,1,2,233.7,234.41,1200,600,1,2,233.66,234.43,1,105,1,2,233.58,234.5,505,63,2,4,233.53,234.75,10,1,1,1,233.5,234.79,100,2000,1,1,233.45,234.89,15,2,1,2,233.4,235.0,110,213,2,6,JPM
2024-10-21T12:15:05.174176083Z,2024-10-21T12:15:05.174010189Z,10,2,38,C,A,1,234.15,200,130,165894,12470010,233.97,234.13,5,400,1,1,233.86,234.17,200,30,1,2,233.81,234.41,28,600,1,2,233.7,234.43,1200,105,1,2,233.66,234.5,1,63,1,4,233.58,234.75,505,1,2,1,233.53,234.79,10,2000,1,1,233.5,234.89,100,2,1,2,233.45,235.0,15,213,1,6,233.4,235.03,110,2,2,1,JPM
2024-10-21T12:15:05.174191104Z,2024-10-21T12:15:05.174024191Z,10,2,38,A,A,1,234.16,200,130,166913,12470011,233.97,234.13,5,400,1,1,233.86,234.16,200,200,1,1,233.81,234.17,28,30,1,2,233.7,234.41,1200,600,1,2,233.66,234.43,1,105,1,2,233.58,234.5,505,63,2,4,233.53,234.75,10,1,1,1,233.5,234.79,100,2000,1,1,233.45,234.89,15,2,1,2,233.4,235.0,110,213,2,6,JPM
2024-10-21T12:15:08.174832295Z,2024-10-21T12:15:08.174665588Z,10,2,38,A,A,1,234.16,200,130,166707,12472897,233.97,234.13,5,400,1,1,233.86,234.16,200,400,1,2,233.81,234.17,28,30,1,2,233.7,234.41,1200,600,1,2,233.66,234.43,1,105,1,2,233.58,234.5,505,63,2,4,233.53,234.75,10,1,1,1,233.5,234.79,100,2000,1,1,233.45,234.89,15,2,1,2,233.4,235.0,110,213,2,6,JPM
2024-10-21T12:15:12.192782193Z,2024-10-21T12:15:12.192615974Z,10,2,38,A,A,0,234.07,100,130,166219,12475949,233.97,234.07,5,100,1,1,233.86,234.13,200,400,1,1,233.81,234.16,28,400,1,2,233.7,234.17,1200,30,1,2,233.66,234.41,1,600,1,2,233.58,234.43,505,105,2,2,233.53,234.5,10,63,1,4,233.5,234.75,100,1,1,1,233.45,234.79,15,2000,1,1,233.4,234.89,110,2,2,2,JPM
2024-10-21T12:15:12.193180932Z,2024-10-21T12:15:12.193015032Z,10,2,38,C,A,0,234.07,100,130,165900,12475950,233.97,234.13,5,400,1,1,233.86,234.16,200,400,1,2,233.81,234.17,28,30,1,2,233.7,234.41,1200,600,1,2,233.66,234.43,1,105,1,2,233.58,234.5,505,63,2,4,233.53,234.75,10,1,1,1,233.5,234.79,100,2000,1,1,233.45,234.89,15,2,1,2,233.4,235.0,110,213,2,6,JPM
2024-10-21T12:15:12.197936547Z,2024-10-21T12:15:12.197769369Z,10,2,38,A,A,0,234.07,148,128,167178,12475955,233.97,234.07,5,148,1,1,233.86,234.13,200,400,1,1,233.81,234.16,28,400,1,2,233.7,234.17,1200,30,1,2,233.66,234.41,1,600,1,2,233.58,234.43,505,105,2,2,233.53,234.5,10,63,1,4,233.5,234.75,100,1,1,1,233.45,234.79,15,2000,1,1,233.4,234.89,110,2,2,2,JPM
2024-10-21T12:15:12.197969503Z,2024-10-21T12:15:12.197802997Z,10,2,38,C,B,1,233.86,200,130,166506,12475958,233.97,234.07,5,148,1,1,233.81,234.13,28,400,1,1,233.7,234.16,1200,400,1,2,233.66,234.17,1,30,1,2,233.58,234.41,505,600,2,2,233.53,234.43,10,105,1,2,233.5,234.5,100,63,1,4,233.45,234.75,15,1,1,1,233.4,234.79,110,2000,2,1,233.39,234.89,10,2,1,2,JPM
2024-10-21T12:15:12.202040946Z,2024-10-21T12:15:12.201874823Z,10,2,38,C,A,0,234.07,148,130,166123,12475962,233.97,234.13,5,400,1,1,233.81,234.16,28,400,1,2,233.7,234.17,1200,30,1,2,233.66,234.41,1,600,1,2,233.58,234.43,505,105,2,2,233.53,234.5,10,63,1,4,233.5,234.75,100,1,1,1,233.45,234.79,15,2000,1,1,233.4,234.89,110,2,2,2,233.39,235.0,10,213,1,6,JPM
2024-10-21T12:15:12.264617436Z,2024-10-21T12:15:12.264450843Z,10,2,38,A,B,2,233.75,28,130,166593,12476000,233.97,234.13,5,400,1,1,233.81,234.16,28,400,1,2,233.75,234.17,28,30,1,2,233.7,234.41,1200,600,1,2,233.66,234.43,1,105,1,2,233.58,234.5,505,63,2,4,233.53,234.75,10,1,1,1,233.5,234.79,100,2000,1,1,233.45,234.89,15,2,1,2,233.4,235.0,110,213,2,6,JPM
2024-10-21T12:15:12.264644369Z,2024-10-21T12:15:12.264477828Z,10,2,38,C,B,1,233.81,28,130,166541,12476001,233.97,234.13,5,400,1,1,233.75,234.16,28,400,1,2,233.7,234.17,1200,30,1,2,233.66,234.41,1,600,1,2,233.58,234.43,505,105,2,2,233.53,234.5,10,63,1,4,233.5,234.75,100,1,1,1,233.45,234.79,15,2000,1,1,233.4,234.89,110,2,2,2,233.39,235.0,10,213,1,6,JPM
2024-10-21T12:15:12.268501792Z,2024-10-21T12:15:12.268335051Z,10,2,38,A,B,4,233.63,200,130,166741,12476005,233.97,234.13,5,400,1,1,233.75,234.16,28,400,1,2,233.7,234.17,1200,30,1,2,233.66,234.41,1,600,1,2,233.63,234.43,200,105,1,2,233.58,234.5,505,63,2,4,233.53,234.75,10,1,1,1,233.5,234.79,100,2000,1,1,233.45,234.89,15,2,1,2,233.4,235.0,110,213,2,6,JPM
2024-10-21T12:15:12.268802483Z,2024-10-21T12:15:12.268635983Z,10,2,38,C,B,1,233.75,28,130,166500,12476006,233.97,234.13,5,400,1,1,233.7,234.16,1200,400,1,2,233.66,234.17,1,30,1,2,233.63,234.41,200,600,1,2,233.58,234.43,505,105,2,2,233.53,234.5,10,63,1,4,233.5,234.75,100,1,1,1,233.45,234.79,15,2000,1,1,233.4,234.89,110,2,2,2,233.39,235.0,10,213,1,6,JPM
2024-10-21T12:15:12.270394146Z,2024-10-21T12:15:12.270227323Z,10,2,38,C,A,2,234.17,29,130,166823,12476010,233.97,234.13,5,400,1,1,233.7,234.16,1200,400,1,2,233.66,234.17,1,1,1,1,233.63,234.41,200,600,1,2,233.58,234.43,505,105,2,2,233.53,234.5,10,63,1,4,233.5,234.75,100,1,1,1,233.45,234.79,15,2000,1,1,233.4,234.89,110,2,2,2,233.39,235.0,10,213,1,6,JPM
2024-10-21T12:15:12.270492635Z,2024-10-21T12:15:12.270326143Z,10,2,38,A,A,0,234.12,27,130,166492,12476011,233.97,234.12,5,27,1,1,233.7,234.13,1200,400,1,1,233.66,234.16,1,400,1,2,233.63,234.17,200,1,1,1,233.58,234.41,505,600,2,2,233.53,234.43,10,105,1,2,233.5,234.5,100,63,1,4,233.45,234.75,15,1,1,1,233.4,234.79,110,2000,2,1,233.39,234.89,10,2,1,2,JPM
2024-10-21T12:15:12.270531958Z,2024-10-21T12:15:12.270365637Z,10,2,38,A,A,2,234.15,26,130,166321,12476012,233.97,234.12,5,27,1,1,233.7,234.13,1200,400,1,1,233.66,234.15,1,26,1,1,233.63,234.16,200,400,1,2,233.58,234.17,505,1,2,1,233.53,234.41,10,600,1,2,233.5,234.43,100,105,1,2,233.45,234.5,15,63,1,4,233.4,234.75,110,1,2,1,233.39,234.79,10,2000,1,1,JPM
2024-10-21T12:15:12.319033039Z,2024-10-21T12:15:12.318866641Z,10,2,38,A,B,3,233.64,200,130,166398,12476109,233.97,234.12,5,27,1,1,233.7,234.13,1200,400,1,1,233.66,234.15,1,26,1,1,233.64,234.16,200,400,1,2,233.58,234.17,505,1,2,1,233.53,234.41,10,600,1,2,233.5,234.43,100,105,1,2,233.45,234.5,15,63,1,4,233.4,234.75,110,1,2,1,233.39,234.79,10,2000,1,1,JPM
2024-10-21T12:15:12.319045020Z,2024-10-21T12:15:12.318878820Z,10,2,38,C,A,3,234.16,200,130,166200,12476110,233.97,234.12,5,27,1,1,233.7,234.13,1200,400,1,1,233.66,234.15,1,26,1,1,233.64,234.16,200,200,1,1,233.58,234.17,505,1,2,1,233.53,234.41,10,600,1,2,233.5,234.43,100,105,1,2,233.45,234.5,15,63,1,4,233.4,234.75,110,1,2,1,233.39,234.79,10,2000,1,1,JPM
2024-10-21T12:15:12.319057841Z,2024-10-21T12:15:12.318890689Z,10,2,38,A,A,2,234.15,400,130,167152,12476111,233.97,234.12,5,27,1,1,233.7,234.13,1200,400,1,1,233.66,234.15,1,426,1,2,233.64,234.17,200,1,1,1,233.58,234.41,505,600,2,2,233.53,234.43,10,105,1,2,233.5,234.5,100,63,1,4,233.45,234.75,15,1,1,1,233.4,234.79,110,2000,2,1,233.39,234.89,10,2,1,2,JPM
2024-10-21T12:15:12.327981136Z,2024-10-21T12:15:12.327814809Z,10,2,38,A,A,0,234.05,200,130,166327,12476126,233.97,234.05,5,200,1,1,233.7,234.12,1200,27,1,1,233.66,234.13,1,400,1,1,233.64,234.15,200,26,1,1,233.58,234.17,505,1,2,1,233.53,234.41,10,600,1,2,233.5,234.43,100,105,1,2,233.45,234.5,15,63,1,4,233.4,234.75,110,1,2,1,233.39,234.79,10,2000,1,1,JPM
2024-10-21T12:15:12.391178086Z,2024-10-21T12:15:12.391011950Z,10,2,38,C,A,1,234.12,27,130,166136,12476246,233.97,234.05,5,200,1,1,233.7,234.13,1200,400,1,1,233.66,234.15,1,26,1,1,233.64,234.17,200,1,1,1,233.58,234.41,505,600,2,2,233.53,234.43,10,105,1,2,233.5,234.5,100,63,1,4,233.45,234.75,15,1,1,1,233.4,234.79,110,2000,2,1,233.39,234.89,10,2,1,2,JPM
2024-10-21T12:15:12.404855221Z,2024-10-21T12:15:12.404688523Z,10,2,38,A,B,3,233.65,200,130,166698,12476254,233.97,234.05,5,200,1,1,233.7,234.13,1200,400,1,1,233.66,234.15,1,26,1,1,233.65,234.17,200,1,1,1,233.58,234.41,505,600,2,2,233.53,234.43,10,105,1,2,233.5,234.5,100,63,1,4,233.45,234.75,15,1,1,1,233.4,234.79,110,2000,2,1,233.39,234.89,10,2,1,2,JPM
2024-10-21T12:15:12.446982743Z,2024-10-21T12:15:12.446815675Z,10,2,38,A,B,2,233.69,200,130,167068,12476283,233.97,234.05,5,200,1,1,233.7,234.13,1200,400,1,1,233.69,234.15,200,26,1,1,233.66,234.17,1,1,1,1,233.58,234.41,505,600,2,2,233.53,234.43,10,105,1,2,233.5,234.5,100,63,1,4,233.45,234.75,15,1,1,1,233.4,234.79,110,2000,2,1,233.39,234.89,10,2,1,2,JPM
2024-10-21T12:15:12.518924447Z,2024-10-21T12:15:12.518757844Z,10,2,38,A,B,2,233.69,200,130,166603,12476376,233.97,234.05,5,200,1,1,233.7,234.13,1200,400,1,1,233.69,234.15,400,26,2,1,233.66,234.17,1,1,1,1,233.58,234.41,505,600,2,2,233.53,234.43,10,105,1,2,233.5,234.5,100,63,1,4,233.45,234.75,15,1,1,1,233.4,234.79,110,2000,2,1,233.39,234.89,10,2,1,2,JPM
2024-10-21T12:15:12.519057354Z,2024-10-21T12:15:12.518889885Z,10,2,38,C,A,0,234.05,200,130,167469,12476377,233.97,234.13,5,400,1,1,233.7,234.15,1200,26,1,1,233.69,234.17,400,1,2,1,233.66,234.41,1,600,1,2,233.58,234.43,505,105,2,2,233.53,234.5,10,63,1,4,233.5,234.75,100,1,1,1,233.45,234.79,15,2000,1,1,233.4,234.89,110,2,2,2,233.39,235.0,10,213,1,6,JPM
2024-10-21T12:15:12.519068158Z,2024-10-21T12:15:12.518901713Z,10,2,38,A,A,0,234.1,400,130,166445,12476378,233.97,234.1,5,400,1,1,233.7,234.13,1200,400,1,1,233.69,234.15,400,26,2,1,233.66,234.17,1,1,1,1,233.58,234.41,505,600,2,2,233.53,234.43,10,105,1,2,233.5,234.5,100,63,1,4,233.45,234.75,15,1,1,1,233.4,234.79,110,2000,2,1,233.39,234.89,10,2,1,2,JPM
2024-10-21T12:15:12.521808610Z,2024-10-21T12:15:12.521642022Z,10,2,38,C,A,0,234.1,200,130,166588,12476383,233.97,234.1,5,200,1,1,233.7,234.13,1200,400,1,1,233.69,234.15,400,26,2,1,233.66,234.17,1,1,1,1,233.58,234.41,505,600,2,2,233.53,234.43,10,105,1,2,233.5,234.5,100,63,1,4,233.45,234.75,15,1,1,1,233.4,234.79,110,2000,2,1,233.39,234.89,10,2,1,2,JPM
2024-10-21T12:15:12.529759184Z,2024-10-21T12:15:12.529592990Z,10,2,38,C,B,2,233.69,200,130,166194,12476384,233.97,234.1,5,200,1,1,233.7,234.13,1200,400,1,1,233.69,234.15,200,26,1,1,233.66,234.17,1,1,1,1,233.58,234.41,505,600,2,2,233.53,234.43,10,105,1,2,233.5,234.5,100,63,1,4,233.45,234.75,15,1,1,1,233.4,234.79,110,2000,2,1,233.39,234.89,10,2,1,2,JPM
2024-10-21T12:15:12.529771785Z,2024-10-21T12:15:12.529605412Z,10,2,38,A,B,1,233.7,400,130,166373,12476385,233.97,234.1,5,200,1,1,233.7,234.13,1600,400,2,1,233.66,234.15,1,26,1,1,233.58,234.17,505,1,2,1,233.53,234.41,10,600,1,2,233.5,234.43,100,105,1,2,233.45,234.5,15,63,1,4,233.4,234.75,110,1,2,1,233.39,234.79,10,2000,1,1,233.31,234.89,110,2,2,2,JPM
2024-10-21T12:15:12.575269816Z,2024-10-21T12:15:12.575103526Z,10,2,38,A,B,1,233.87,400,130,166290,12476419,233.97,234.1,5,200,1,1,233.87,234.13,400,400,1,1,233.7,234.15,1200,26,1,1,233.66,234.17,1,1,1,1,233.58,234.41,505,600,2,2,233.53,234.43,10,105,1,2,233.5,234.5,100,63,1,4,233.45,234.75,15,1,1,1,233.4,234.79,110,2000,2,1,233.39,234.89,10,2,1,2,JPM
2024-10-21T12:15:12.619539368Z,2024-10-21T12:15:12.619373396Z,10,2,38,C,A,0,234.1,200,130,165972,12476439,233.97,234.13,5,400,1,1,233.87,234.15,400,26,1,1,233.7,234.17,1200,1,1,1,233.66,234.41,1,600,1,2,233.58,234.43,505,105,2,2,233.53,234.5,10,63,1,4,233.5,234.75,100,1,1,1,233.45,234.79,15,2000,1,1,233.4,234.89,110,2,2,2,233.39,235.0,10,213,1,6,JPM
2024-10-21T12:15:12.619552121Z,2024-10-21T12:15:12.619385902Z,10,2,38,A,A,1,234.15,200,130,166219,12476440,233.97,234.13,5,400,1,1,233.87,234.15,400,226,1,2,233.7,234.17,1200,1,1,1,233.66,234.41,1,600,1,2,233.58,234.43,505,105,2,2,233.53,234.5,10,63,1,4,233.5,234.75,100,1,1,1,233.45,234.79,15,2000,1,1,233.4,234.89,110,2,2,2,233.39,235.0,10,213,1,6,JPM
2024-10-21T12:15:12.656104126Z,2024-10-21T12:15:12.655937741Z,10,2,38,C,A,1,234.15,26,130,166385,12476454,233.97,234.13,5,400,1,1,233.87,234.15,400,200,1,1,233.7,234.17,1200,1,1,1,233.66,234.41,1,600,1,2,233.58,234.43,505,105,2,2,233.53,234.5,10,63,1,4,233.5,234.75,100,1,1,1,233.45,234.79,15,2000,1,1,233.4,234.89,110,2,2,2,233.39,235.0,10,213,1,6,JPM
2024-10-21T12:15:12.669851013Z,2024-10-21T12:15:12.669684284Z,10,2,38,A,B,1,233.9,200,130,166729,12476460,233.97,234.13,5,400,1,1,233.9,234.15,200,200,1,1,233.7,234.17,1200,1,1,1,233.66,234.41,1,600,1,2,233.58,234.43,505,105,2,2,233.53,234.5,10,63,1,4,233.5,234.75,100,1,1,1,233.45,234.79,15,2000,1,1,233.4,234.89,110,2,2,2,233.39,235.0,10,213,1,6,JPM
2024-10-21T12:15:13.051742504Z,2024-10-21T12:15:13.051576352Z,10,2,38,A,A,3,234.22,30,130,166152,12476843,233.97,234.13,5,400,1,1,233.9,234.15,200,200,1,1,233.7,234.17,1200,1,1,1,233.66,234.22,1,30,1,1,233.58,234.41,505,600,2,2,233.53,234.43,10,105,1,2,233.5,234.5,100,63,1,4,233.45,234.75,15,1,1,1,233.4,234.79,110,2000,2,1,233.39,234.89,10,2,1,2,JPM
2024-10-21T12:15:13.051772118Z,2024-10-21T12:15:13.051605161Z,10,2,38,A,B,2,233.85,27,130,166957,12476844,233.97,234.13,5,400,1,1,233.9,234.15,200,200,1,1,233.85,234.17,27,1,1,1,233.7,234.22,1200,30,1,1,233.66,234.41,1,600,1,2,233.58,234.43,505,105,2,2,233.53,234.5,10,63,1,4,233.5,234.75,100,1,1,1,233.45,234.79,15,2000,1,1,233.4,234.89,110,2,2,2,JPM
2024-10-21T12:15:13.946134251Z,2024-10-21T12:15:13.945967888Z,10,2,38,A,A,1,234.15,200,130,166363,12477920,233.97,234.13,5,400,1,1,233.9,234.15,200,400,1,2,233.85,234.17,27,1,1,1,233.7,234.22,1200,30,1,1,233.66,234.41,1,600,1,2,233.58,234.43,505,105,2,2,233.53,234.5,10,63,1,4,233.5,234.75,100,1,1,1,233.45,234.79,15,2000,1,1,233.4,234.89,110,2,2,2,JPM
2024-10-21T12:15:13.946655760Z,2024-10-21T12:15:13.946489728Z,10,2,38,C,A,3,234.22,30,130,166032,12477923,233.97,234.13,5,400,1,1,233.9,234.15,200,400,1,2,233.85,234.17,27,1,1,1,233.7,234.41,1200,600,1,2,233.66,234.43,1,105,1,2,233.58,234.5,505,63,2,4,233.53,234.75,10,1,1,1,233.5,234.79,100,2000,1,1,233.45,234.89,15,2,1,2,233.4,235.0,110,213,2,6,JPM
2024-10-21T12:15:13.946698478Z,2024-10-21T12:15:13.946532120Z,10,2,38,A,A,2,234.17,27,130,166358,12477924,233.97,234.13,5,400,1,1,233.9,234.15,200,400,1,2,233.85,234.17,27,28,1,2,233.7,234.41,1200,600,1,2,233.66,234.43,1,105,1,2,233.58,234.5,505,63,2,4,233.53,234.75,10,1,1,1,233.5,234.79,100,2000,1,1,233.45,234.89,15,2,1,2,233.4,235.0,110,213,2,6,JPM
2024-10-21T12:15:14.001175416Z,2024-10-21T12:15:14.001009338Z,10,2,38,C,A,1,234.15,200,130,166078,12478031,233.97,234.13,5,400,1,1,233.9,234.15,200,200,1,1,233.85,234.17,27,28,1,2,233.7,234.41,1200,600,1,2,233.66,234.43,1,105,1,2,233.58,234.5,505,63,2,4,233.53,234.75,10,1,1,1,233.5,234.79,100,2000,1,1,233.45,234.89,15,2,1,2,233.4,235.0,110,213,2,6,JPM
2024-10-21T12:15:14.001188780Z,2024-10-21T12:15:14.001022189Z,10,2,38,A,A,0,234.1,400,130,166591,12478032,233.97,234.1,5,400,1,1,233.9,234.13,200,400,1,1,233.85,234.17,27,28,1,2,233.7,234.41,1200,600,1,2,233.66,234.43,1,105,1,2,233.58,234.5,505,63,2,4,233.53,234.75,10,1,1,1,233.5,234.79,100,2000,1,1,233.45,234.89,15,2,1,2,233.4,235.0,110,213,2,6,JPM
2024-10-21T12:15:14.207349948Z,2024-10-21T12:15:14.207183672Z,10,2,38,A,B,1,233.9,100,130,166276,12478133,233.97,234.1,5,400,1,1,233.9,234.13,300,400,2,1,233.85,234.17,27,28,1,2,233.7,234.41,1200,600,1,2,233.66,234.43,1,105,1,2,233.58,234.5,505,63,2,4,233.53,234.75,10,1,1,1,233.5,234.79,100,2000,1,1,233.45,234.89,15,2,1,2,233.4,235.0,110,213,2,6,JPM
2024-10-21T12:15:14.207645338Z,2024-10-21T12:15:14.207479344Z,10,2,38,C,B,1,233.9,100,130,165994,12478134,233.97,234.1,5,400,1,1,233.9,234.13,200,400,1,1,233.85,234.17,27,28,1,2,233.7,234.41,1200,600,1,2,233.66,234.43,1,105,1,2,233.58,234.5,505,63,2,4,233.53,234.75,10,1,1,1,233.5,234.79,100,2000,1,1,233.45,234.89,15,2,1,2,233.4,235.0,110,213,2,6,JPM
2024-10-21T12:15:14.278543569Z,2024-10-21T12:15:14.278377067Z,10,2,38,C,A,0,234.1,200,130,166502,12478168,233.97,234.1,5,200,1,1,233.9,234.13,200,400,1,1,233.85,234.17,27,28,1,2,233.7,234.41,1200,600,1,2,233.66,234.43,1,105,1,2,233.58,234.5,505,63,2,4,233.53,234.75,10,1,1,1,233.5,234.79,100,2000,1,1,233.45,234.89,15,2,1,2,233.4,235.0,110,213,2,6,JPM
2024-10-21T12:15:14.278726070Z,2024-10-21T12:15:14.278559734Z,10,2,38,C,A,0,234.1,200,130,166336,12478169,233.97,234.13,5,400,1,1,233.9,234.17,200,28,1,2,233.85,234.41,27,600,1,2,233.7,234.43,1200,105,1,2,233.66,234.5,1,63,1,4,233.58,234.75,505,1,2,1,233.53,234.79,10,2000,1,1,233.5,234.89,100,2,1,2,233.45,235.0,15,213,1,6,233.4,235.03,110,2,2,1,JPM
2024-10-21T12:15:14.278738674Z,2024-10-21T12:15:14.278572418Z,10,2,38,A,A,1,234.16,200,130,166256,12478170,233.97,234.13,5,400,1,1,233.9,234.16,200,200,1,1,233.85,234.17,27,28,1,2,233.7,234.41,1200,600,1,2,233.66,234.43,1,105,1,2,233.58,234.5,505,63,2,4,233.53,234.75,10,1,1,1,233.5,234.79,100,2000,1,1,233.45,234.89,15,2,1,2,233.4,235.0,110,213,2,6,JPM
2024-10-21T12:15:14.279136295Z,2024-10-21T12:15:14.278970387Z,10,2,38,C,A,2,234.17,27,130,165908,12478171,233.97,234.13,5,400,1,1,233.9,234.16,200,200,1,1,233.85,234.17,27,1,1,1,233.7,234.41,1200,600,1,2,233.66,234.43,1,105,1,2,233.58,234.5,505,63,2,4,233.53,234.75,10,1,1,1,233.5,234.79,100,2000,1,1,233.45,234.89,15,2,1,2,233.4,235.0,110,213,2,6,JPM
2024-10-21T12:15:14.280757598Z,2024-10-21T12:15:14.280591359Z,10,2,38,A,A,1,234.16,200,130,166239,12478172,233.97,234.13,5,400,1,1,233.9,234.16,200,400,1,2,233.85,234.17,27,1,1,1,233.7,234.41,1200,600,1,2,233.66,234.43,1,105,1,2,233.58,234.5,505,63,2,4,233.53,234.75,10,1,1,1,233.5,234.79,100,2000,1,1,233.45,234.89,15,2,1,2,233.4,235.0,110,213,2,6,JPM
2024-10-21T12:15:15.249067573Z,2024-10-21T12:15:15.248901194Z,10,2,38,C,A,1,234.16,200,130,166379,12479022,233.97,234.13,5,400,1,1,233.9,234.16,200,200,1,1,233.85,234.17,27,1,1,1,233.7,234.41,1200,600,1,2,233.66,234.43,1,105,1,2,233.58,234.5,505,63,2,4,233.53,234.75,10,1,1,1,233.5,234.79,100,2000,1,1,233.45,234.89,15,2,1,2,233.4,235.0,110,213,2,6,JPM
2024-10-21T12:15:15.249079309Z,2024-10-21T12:15:15.248912868Z,10,2,38,A,A,1,234.15,400,130,166441,12479023,233.97,234.13,5,400,1,1,233.9,234.15,200,400,1,1,233.85,234.17,27,1,1,1,233.7,234.41,1200,600,1,2,233.66,234.43,1,105,1,2,233.58,234.5,505,63,2,4,233.53,234.75,10,1,1,1,233.5,234.79,100,2000,1,1,233.45,234.89,15,2,1,2,233.4,235.0,110,213,2,6,JPM
2024-10-21T12:15:17.923200888Z,2024-10-21T12:15:17.923034484Z,10,2,38,A,A,3,234.22,27,130,166404,12482317,233.97,234.13,5,400,1,1,233.9,234.15,200,400,1,1,233.85,234.17,27,1,1,1,233.7,234.22,1200,27,1,1,233.66,234.41,1,600,1,2,233.58,234.43,505,105,2,2,233.53,234.5,10,63,1,4,233.5,234.75,100,1,1,1,233.45,234.79,15,2000,1,1,233.4,234.89,110,2,2,2,JPM
2024-10-21T12:15:24.014356772Z,2024-10-21T12:15:24.014190176Z,10,2,38,C,B,1,233.9,200,130,166596,12489125,233.97,234.13,5,400,1,1,233.85,234.15,27,400,1,1,233.7,234.17,1200,1,1,1,233.66,234.22,1,27,1,1,233.58,234.41,505,600,2,2,233.53,234.43,10,105,1,2,233.5,234.5,100,63,1,4,233.45,234.75,15,1,1,1,233.4,234.79,110,2000,2,1,233.39,234.89,10,2,1,2,JPM
2024-10-21T12:15:24.014368498Z,2024-10-21T12:15:24.014202142Z,10,2,38,A,B,1,233.87,400,130,166356,12489126,233.97,234.13,5,400,1,1,233.87,234.15,400,400,1,1,233.85,234.17,27,1,1,1,233.7,234.22,1200,27,1,1,233.66,234.41,1,600,1,2,233.58,234.43,505,105,2,2,233.53,234.5,10,63,1,4,233.5,234.75,100,1,1,1,233.45,234.79,15,2000,1,1,233.4,234.89,110,2,2,2,JPM
2024-10-21T12:15:24.015016662Z,2024-10-21T12:15:24.014850794Z,10,2,38,C,B,2,233.85,27,130,165868,12489129,233.97,234.13,5,400,1,1,233.87,234.15,400,400,1,1,233.7,234.17,1200,1,1,1,233.66,234.22,1,27,1,1,233.58,234.41,505,600,2,2,233.53,234.43,10,105,1,2,233.5,234.5,100,63,1,4,233.45,234.75,15,1,1,1,233.4,234.79,110,2000,2,1,233.39,234.89,10,2,1,2,JPM
2024-10-21T12:15:24.015063463Z,2024-10-21T12:15:24.014897264Z,10,2,38,A,B,2,233.79,29,130,166199,12489130,233.97,234.13,5,400,1,1,233.87,234.15,400,400,1,1,233.79,234.17,29,1,1,1,233.7,234.22,1200,27,1,1,233.66,234.41,1,600,1,2,233.58,234.43,505,105,2,2,233.53,234.5,10,63,1,4,233.5,234.75,100,1,1,1,233.45,234.79,15,2000,1,1,233.4,234.89,110,2,2,2,JPM
2024-10-21T12:15:24.015171797Z,2024-10-21T12:15:24.015005588Z,10,2,38,C,A,3,234.22,27,130,166209,12489131,233.97,234.13,5,400,1,1,233.87,234.15,400,400,1,1,233.79,234.17,29,1,1,1,233.7,234.41,1200,600,1,2,233.66,234.43,1,105,1,2,233.58,234.5,505,63,2,4,233.53,234.75,10,1,1,1,233.5,234.79,100,2000,1,1,233.45,234.89,15,2,1,2,233.4,235.0,110,213,2,6,JPM
2024-10-21T12:15:24.015226111Z,2024-10-21T12:15:24.015059897Z,10,2,38,A,A,2,234.17,30,130,166214,12489132,233.97,234.13,5,400,1,1,233.87,234.15,400,400,1,1,233.79,234.17,29,31,1,2,233.7,234.41,1200,600,1,2,233.66,234.43,1,105,1,2,233.58,234.5,505,63,2,4,233.53,234.75,10,1,1,1,233.5,234.79,100,2000,1,1,233.45,234.89,15,2,1,2,233.4,235.0,110,213,2,6,JPM
2024-10-21T12:15:24.066676377Z,2024-10-21T12:15:24.066509814Z,10,2,38,A,A,0,234.1,200,130,166563,12489179,233.97,234.1,5,200,1,1,233.87,234.13,400,400,1,1,233.79,234.17,29,31,1,2,233.7,234.41,1200,600,1,2,233.66,234.43,1,105,1,2,233.58,234.5,505,63,2,4,233.53,234.75,10,1,1,1,233.5,234.79,100,2000,1,1,233.45,234.89,15,2,1,2,233.4,235.0,110,213,2,6,JPM
2024-10-21T12:15:27.519404999Z,2024-10-21T12:15:27.519238798Z,10,2,38,C,B,1,233.87,400,130,166201,12491655,233.97,234.1,5,200,1,1,233.79,234.13,29,400,1,1,233.7,234.17,1200,31,1,2,233.66,234.41,1,600,1,2,233.58,234.43,505,105,2,2,233.53,234.5,10,63,1,4,233.5,234.75,100,1,1,1,233.45,234.79,15,2000,1,1,233.4,234.89,110,2,2,2,233.39,235.0,10,213,1,6,JPM
2024-10-21T12:15:27.519418174Z,2024-10-21T12:15:27.519251700Z,10,2,38,A,B,1,233.84,200,130,166474,12491656,233.97,234.1,5,200,1,1,233.84,234.13,200,400,1,1,233.79,234.17,29,31,1,2,233.7,234.41,1200,600,1,2,233.66,234.43,1,105,1,2,233.58,234.5,505,63,2,4,233.53,234.75,10,1,1,1,233.5,234.79,100,2000,1,1,233.45,234.89,15,2,1,2,233.4,235.0,110,213,2,6,JPM
2024-10-21T12:15:29.175384059Z,2024-10-21T12:15:29.175215826Z,10,2,38,T,A,0,233.97,5,0,168233,12493180,233.97,234.1,5,200,1,1,233.84,234.13,200,400,1,1,233.79,234.17,29,31,1,2,233.7,234.41,1200,600,1,2,233.66,234.43,1,105,1,2,233.58,234.5,505,63,2,4,233.53,234.75,10,1,1,1,233.5,234.79,100,2000,1,1,233.45,234.89,15,2,1,2,233.4,235.0,110,213,2,6,JPM
2024-10-21T12:15:29.175384059Z,2024-10-21T12:15:29.175215826Z,10,2,38,A,N,0,233.95,295,130,168233,12493181,233.84,233.95,200,295,1,1,233.79,234.1,29,200,1,1,233.7,234.13,1200,400,1,1,233.66,234.17,1,31,1,2,233.58,234.41,505,600,2,2,233.53,234.43,10,105,1,2,233.5,234.5,100,63,1,4,233.45,234.75,15,1,1,1,233.4,234.79,110,2000,2,1,233.39,234.89,10,2,1,2,JPM
2024-10-21T12:15:29.175406869Z,2024-10-21T12:15:29.175239385Z,10,2,38,A,A,1,234.07,100,130,167484,12493182,233.84,233.95,200,295,1,1,233.79,234.07,29,100,1,1,233.7,234.1,1200,200,1,1,233.66,234.13,1,400,1,1,233.58,234.17,505,31,2,2,233.53,234.41,10,600,1,2,233.5,234.43,100,105,1,2,233.45,234.5,15,63,1,4,233.4,234.75,110,1,2,1,233.39,234.79,10,2000,1,1,JPM
2024-10-21T12:15:29.175410757Z,2024-10-21T12:15:29.175244705Z,10,2,38,A,A,1,234.04,38,130,166052,12493183,233.84,233.95,200,295,1,1,233.79,234.04,29,38,1,1,233.7,234.07,1200,100,1,1,233.66,234.1,1,200,1,1,233.58,234.13,505,400,2,1,233.53,234.17,10,31,1,2,233.5,234.41,100,600,1,2,233.45,234.43,15,105,1,2,233.4,234.5,110,63,2,4,233.39,234.75,10,1,1,1,JPM
2024-10-21T12:15:29.175418381Z,2024-10-21T12:15:29.175252395Z,10,2,38,A,A,2,234.07,100,130,165986,12493184,233.84,233.95,200,295,1,1,233.79,234.04,29,38,1,1,233.7,234.07,1200,200,1,2,233.66,234.1,1,200,1,1,233.58,234.13,505,400,2,1,233.53,234.17,10,31,1,2,233.5,234.41,100,600,1,2,233.45,234.43,15,105,1,2,233.4,234.5,110,63,2,4,233.39,234.75,10,1,1,1,JPM
2024-10-21T12:15:29.175428571Z,2024-10-21T12:15:29.175261243Z,10,2,38,T,B,0,233.95,187,130,167328,12493185,233.84,233.95,200,295,1,1,233.79,234.04,29,38,1,1,233.7,234.07,1200,200,1,2,233.66,234.1,1,200,1,1,233.58,234.13,505,400,2,1,233.53,234.17,10,31,1,2,233.5,234.41,100,600,1,2,233.45,234.43,15,105,1,2,233.4,234.5,110,63,2,4,233.39,234.75,10,1,1,1,JPM
2024-10-21T12:15:29.175428571Z,2024-10-21T12:15:29.175261243Z,10,2,38,C,A,0,233.95,187,130,167328,12493185,233.84,233.95,200,108,1,1,233.79,234.04,29,38,1,1,233.7,234.07,1200,200,1,2,233.66,234.1,1,200,1,1,233.58,234.13,505,400,2,1,233.53,234.17,10,31,1,2,233.5,234.41,100,600,1,2,233.45,234.43,15,105,1,2,233.4,234.5,110,63,2,4,233.39,234.75,10,1,1,1,JPM
2024-10-21T12:15:29.175431546Z,2024-10-21T12:15:29.175265540Z,10,2,38,A,A,1,234.04,38,130,166006,12493186,233.84,233.95,200,108,1,1,233.79,234.04,29,76,1,2,233.7,234.07,1200,200,1,2,233.66,234.1,1,200,1,1,233.58,234.13,505,400,2,1,233.53,234.17,10,31,1,2,233.5,234.41,100,600,1,2,233.45,234.43,15,105,1,2,233.4,234.5,110,63,2,4,233.39,234.75,10,1,1,1,JPM
2024-10-21T12:15:29.175437237Z,2024-10-21T12:15:29.175269965Z,10,2,38,T,B,0,233.95,108,130,167272,12493187,233.84,233.95,200,108,1,1,233.79,234.04,29,76,1,2,233.7,234.07,1200,200,1,2,233.66,234.1,1,200,1,1,233.58,234.13,505,400,2,1,233.53,234.17,10,31,1,2,233.5,234.41,100,600,1,2,233.45,234.43,15,105,1,2,233.4,234.5,110,63,2,4,233.39,234.75,10,1,1,1,JPM
2024-10-21T12:15:29.175437237Z,2024-10-21T12:15:29.175269965Z,10,2,38,C,A,0,233.95,108,130,167272,12493187,233.84,234.04,200,76,1,2,233.79,234.07,29,200,1,2,233.7,234.1,1200,200,1,1,233.66,234.13,1,400,1,1,233.58,234.17,505,31,2,2,233.53,234.41,10,600,1,2,233.5,234.43,100,105,1,2,233.45,234.5,15,63,1,4,233.4,234.75,110,1,2,1,233.39,234.79,10,2000,1,1,JPM
2024-10-21T12:15:29.175453602Z,2024-10-21T12:15:29.175287761Z,10,2,38,C,A,1,234.07,100,130,165841,12493188,233.84,234.04,200,76,1,2,233.79,234.07,29,100,1,1,233.7,234.1,1200,200,1,1,233.66,234.13,1,400,1,1,233.58,234.17,505,31,2,2,233.53,234.41,10,600,1,2,233.5,234.43,100,105,1,2,233.45,234.5,15,63,1,4,233.4,234.75,110,1,2,1,233.39,234.79,10,2000,1,1,JPM
2024-10-21T12:15:29.175459603Z,2024-10-21T12:15:29.175293157Z,10,2,38,C,A,0,234.04,38,130,166446,12493190,233.84,234.04,200,38,1,1,233.79,234.07,29,100,1,1,233.7,234.1,1200,200,1,1,233.66,234.13,1,400,1,1,233.58,234.17,505,31,2,2,233.53,234.41,10,600,1,2,233.5,234.43,100,105,1,2,233.45,234.5,15,63,1,4,233.4,234.75,110,1,2,1,233.39,234.79,10,2000,1,1,JPM
2024-10-21T12:15:29.175464536Z,2024-10-21T12:15:29.175298862Z,10,2,38,C,A,1,234.07,100,130,165674,12493191,233.84,234.04,200,38,1,1,233.79,234.1,29,200,1,1,233.7,234.13,1200,400,1,1,233.66,234.17,1,31,1,2,233.58,234.41,505,600,2,2,233.53,234.43,10,105,1,2,233.5,234.5,100,63,1,4,233.45,234.75,15,1,1,1,233.4,234.79,110,2000,2,1,233.39,234.89,10,2,1,2,JPM
2024-10-21T12:15:29.175475521Z,2024-10-21T12:15:29.175307953Z,10,2,38,A,A,1,234.08,38,130,167568,12493192,233.84,234.04,200,38,1,1,233.79,234.08,29,38,1,1,233.7,234.1,1200,200,1,1,233.66,234.13,1,400,1,1,233.58,234.17,505,31,2,2,233.53,234.41,10,600,1,2,233.5,234.43,100,105,1,2,233.45,234.5,15,63,1,4,233.4,234.75,110,1,2,1,233.39,234.79,10,2000,1,1,JPM
2024-10-21T12:15:29.175484200Z,2024-10-21T12:15:29.175318339Z,10,2,38,C,A,2,234.1,200,130,165861,12493193,233.84,234.04,200,38,1,1,233.79,234.08,29,38,1,1,233.7,234.13,1200,400,1,1,233.66,234.17,1,31,1,2,233.58,234.41,505,600,2,2,233.53,234.43,10,105,1,2,233.5,234.5,100,63,1,4,233.45,234.75,15,1,1,1,233.4,234.79,110,2000,2,1,233.39,234.89,10,2,1,2,JPM
2024-10-21T12:15:29.175542211Z,2024-10-21T12:15:29.175376083Z,10,2,38,A,B,0,233.89,38,130,166128,12493194,233.89,234.04,38,38,1,1,233.84,234.08,200,38,1,1,233.79,234.13,29,400,1,1,233.7,234.17,1200,31,1,2,233.66,234.41,1,600,1,2,233.58,234.43,505,105,2,2,233.53,234.5,10,63,1,4,233.5,234.75,100,1,1,1,233.45,234.79,15,2000,1,1,233.4,234.89,110,2,2,2,JPM
2024-10-21T12:15:29.175555082Z,2024-10-21T12:15:29.175388906Z,10,2,38,A,B,1,233.86,38,130,166176,12493195,233.89,234.04,38,38,1,1,233.86,234.08,38,38,1,1,233.84,234.13,200,400,1,1,233.79,234.17,29,31,1,2,233.7,234.41,1200,600,1,2,233.66,234.43,1,105,1,2,233.58,234.5,505,63,2,4,233.53,234.75,10,1,1,1,233.5,234.79,100,2000,1,1,233.45,234.89,15,2,1,2,JPM
2024-10-21T12:15:29.246556838Z,2024-10-21T12:15:29.246390784Z,10,2,38,C,B,2,233.84,200,130,166054,12493277,233.89,234.04,38,38,1,1,233.86,234.08,38,38,1,1,233.79,234.13,29,400,1,1,233.7,234.17,1200,31,1,2,233.66,234.41,1,600,1,2,233.58,234.43,505,105,2,2,233.53,234.5,10,63,1,4,233.5,234.75,100,1,1,1,233.45,234.79,15,2000,1,1,233.4,234.89,110,2,2,2,JPM
2024-10-21T12:15:29.246589766Z,2024-10-21T12:15:29.246423576Z,10,2,38,A,B,3,233.76,400,130,166190,12493278,233.89,234.04,38,38,1,1,233.86,234.08,38,38,1,1,233.79,234.13,29,400,1,1,233.76,234.17,400,31,1,2,233.7,234.41,1200,600,1,2,233.66,234.43,1,105,1,2,233.58,234.5,505,63,2,4,233.53,234.75,10,1,1,1,233.5,234.79,100,2000,1,1,233.45,234.89,15,2,1,2,JPM
2024-10-21T12:15:29.246983004Z,2024-10-21T12:15:29.246816914Z,10,2,38,C,B,2,233.79,29,130,166090,12493279,233.89,234.04,38,38,1,1,233.86,234.08,38,38,1,1,233.76,234.13,400,400,1,1,233.7,234.17,1200,31,1,2,233.66,234.41,1,600,1,2,233.58,234.43,505,105,2,2,233.53,234.5,10,63,1,4,233.5,234.75,100,1,1,1,233.45,234.79,15,2000,1,1,233.4,234.89,110,2,2,2,JPM
2024-10-21T12:15:29.247077109Z,2024-10-21T12:15:29.246910849Z,10,2,38,A,B,3,233.74,28,130,166260,12493280,233.89,234.04,38,38,1,1,233.86,234.08,38,38,1,1,233.76,234.13,400,400,1,1,233.74,234.17,28,31,1,2,233.7,234.41,1200,600,1,2,233.66,234.43,1,105,1,2,233.58,234.5,505,63,2,4,233.53,234.75,10,1,1,1,233.5,234.79,100,2000,1,1,233.45,234.89,15,2,1,2,JPM
2024-10-21T12:15:29.283930892Z,2024-10-21T12:15:29.283764753Z,10,2,38,C,A,1,234.08,38,130,166139,12493295,233.89,234.04,38,38,1,1,233.86,234.13,38,400,1,1,233.76,234.17,400,31,1,2,233.74,234.41,28,600,1,2,233.7,234.43,1200,105,1,2,233.66,234.5,1,63,1,4,233.58,234.75,505,1,2,1,233.53,234.79,10,2000,1,1,233.5,234.89,100,2,1,2,233.45,235.0,15,213,1,6,JPM
2024-10-21T12:15:29.283941482Z,2024-10-21T12:15:29.283775550Z,10,2,38,C,B,1,233.86,38,130,165932,12493296,233.89,234.04,38,38,1,1,233.76,234.13,400,400,1,1,233.74,234.17,28,31,1,2,233.7,234.41,1200,600,1,2,233.66,234.43,1,105,1,2,233.58,234.5,505,63,2,4,233.53,234.75,10,1,1,1,233.5,234.79,100,2000,1,1,233.45,234.89,15,2,1,2,233.4,235.0,110,213,2,6,JPM
2024-10-21T12:15:29.283989568Z,2024-10-21T12:15:29.283823523Z,10,2,38,A,A,1,234.1,400,130,166045,12493297,233.89,234.04,38,38,1,1,233.76,234.1,400,400,1,1,233.74,234.13,28,400,1,1,233.7,234.17,1200,31,1,2,233.66,234.41,1,600,1,2,233.58,234.43,505,105,2,2,233.53,234.5,10,63,1,4,233.5,234.75,100,1,1,1,233.45,234.79,15,2000,1,1,233.4,234.89,110,2,2,2,JPM
2024-10-21T12:15:29.425498174Z,2024-10-21T12:15:29.425332139Z,10,2,38,C,A,0,234.04,38,130,166035,12493515,233.89,234.1,38,400,1,1,233.76,234.13,400,400,1,1,233.74,234.17,28,31,1,2,233.7,234.41,1200,600,1,2,233.66,234.43,1,105,1,2,233.58,234.5,505,63,2,4,233.53,234.75,10,1,1,1,233.5,234.79,100,2000,1,1,233.45,234.89,15,2,1,2,233.4,235.0,110,213,2,6,JPM
2024-10-21T12:15:29.425509152Z,2024-10-21T12:15:29.425342648Z,10,2,38,C,B,0,233.89,38,130,166504,12493516,233.76,234.1,400,400,1,1,233.74,234.13,28,400,1,1,233.7,234.17,1200,31,1,2,233.66,234.41,1,600,1,2,233.58,234.43,505,105,2,2,233.53,234.5,10,63,1,4,233.5,234.75,100,1,1,1,233.45,234.79,15,2000,1,1,233.4,234.89,110,2,2,2,233.39,235.0,10,213,1,6,JPM
2024-10-21T12:15:29.496660616Z,2024-10-21T12:15:29.496494580Z,10,2,38,C,B,0,233.76,200,130,166036,12493549,233.76,234.1,200,400,1,1,233.74,234.13,28,400,1,1,233.7,234.17,1200,31,1,2,233.66,234.41,1,600,1,2,233.58,234.43,505,105,2,2,233.53,234.5,10,63,1,4,233.5,234.75,100,1,1,1,233.45,234.79,15,2000,1,1,233.4,234.89,110,2,2,2,233.39,235.0,10,213,1,6,JPM
2024-10-21T12:15:38.712982908Z,2024-10-21T12:15:38.712816410Z,10,2,38,C,A,0,234.1,200,130,166498,12503722,233.76,234.1,200,200,1,1,233.74,234.13,28,400,1,1,233.7,234.17,1200,31,1,2,233.66,234.41,1,600,1,2,233.58,234.43,505,105,2,2,233.53,234.5,10,63,1,4,233.5,234.75,100,1,1,1,233.45,234.79,15,2000,1,1,233.4,234.89,110,2,2,2,233.39,235.0,10,213,1,6,JPM
2024-10-21T12:15:38.816780965Z,2024-10-21T12:15:38.816614723Z,10,2,38,A,A,0,234.1,200,130,166242,12504039,233.76,234.1,200,400,1,2,233.74,234.13,28,400,1,1,233.7,234.17,1200,31,1,2,233.66,234.41,1,600,1,2,233.58,234.43,505,105,2,2,233.53,234.5,10,63,1,4,233.5,234.75,100,1,1,1,233.45,234.79,15,2000,1,1,233.4,234.89,110,2,2,2,233.39,235.0,10,213,1,6,JPM
2024-10-21T12:15:39.207247997Z,2024-10-21T12:15:39.207080252Z,10,2,38,A,A,0,234.0,22,130,167745,12504453,233.76,234.0,200,22,1,1,233.74,234.1,28,400,1,2,233.7,234.13,1200,400,1,1,233.66,234.17,1,31,1,2,233.58,234.41,505,600,2,2,233.53,234.43,10,105,1,2,233.5,234.5,100,63,1,4,233.45,234.75,15,1,1,1,233.4,234.79,110,2000,2,1,233.39,234.89,10,2,1,2,JPM
2024-10-21T12:15:39.207269463Z,2024-10-21T12:15:39.207103673Z,10,2,38,C,B,0,233.76,200,130,165790,12504456,233.74,234.0,28,22,1,1,233.7,234.1,1200,400,1,2,233.66,234.13,1,400,1,1,233.58,234.17,505,31,2,2,233.53,234.41,10,600,1,2,233.5,234.43,100,105,1,2,233.45,234.5,15,63,1,4,233.4,234.75,110,1,2,1,233.39,234.79,10,2000,1,1,233.31,234.89,110,2,2,2,JPM
2024-10-21T12:15:39.207333984Z,2024-10-21T12:15:39.207167970Z,10,2,38,C,A,1,234.1,200,130,166014,12504459,233.74,234.0,28,22,1,1,233.7,234.1,1200,200,1,1,233.66,234.13,1,400,1,1,233.58,234.17,505,31,2,2,233.53,234.41,10,600,1,2,233.5,234.43,100,105,1,2,233.45,234.5,15,63,1,4,233.4,234.75,110,1,2,1,233.39,234.79,10,2000,1,1,233.31,234.89,110,2,2,2,JPM
2024-10-21T12:15:39.207408030Z,2024-10-21T12:15:39.207241805Z,10,2,38,C,A,1,234.1,200,130,166225,12504461,233.74,234.0,28,22,1,1,233.7,234.13,1200,400,1,1,233.66,234.17,1,31,1,2,233.58,234.41,505,600,2,2,233.53,234.43,10,105,1,2,233.5,234.5,100,63,1,4,233.45,234.75,15,1,1,1,233.4,234.79,110,2000,2,1,233.39,234.89,10,2,1,2,233.31,235.0,110,213,2,6,JPM
2024-10-21T12:15:39.207701481Z,2024-10-21T12:15:39.207535631Z,10,2,38,C,A,0,234.0,22,130,165850,12504467,233.74,234.13,28,400,1,1,233.7,234.17,1200,31,1,2,233.66,234.41,1,600,1,2,233.58,234.43,505,105,2,2,233.53,234.5,10,63,1,4,233.5,234.75,100,1,1,1,233.45,234.79,15,2000,1,1,233.4,234.89,110,2,2,2,233.39,235.0,10,213,1,6,233.31,235.03,110,2,2,1,JPM
2024-10-21T12:15:39.274873761Z,2024-10-21T12:15:39.274707573Z,10,2,38,C,B,0,233.74,28,130,166188,12504518,233.7,234.13,1200,400,1,1,233.66,234.17,1,31,1,2,233.58,234.41,505,600,2,2,233.53,234.43,10,105,1,2,233.5,234.5,100,63,1,4,233.45,234.75,15,1,1,1,233.4,234.79,110,2000,2,1,233.39,234.89,10,2,1,2,233.31,235.0,110,213,2,6,233.3,235.03,100,2,1,1,JPM
2024-10-21T12:15:39.274960881Z,2024-10-21T12:15:39.274794258Z,10,2,38,A,B,1,233.69,28,130,166623,12504519,233.7,234.13,1200,400,1,1,233.69,234.17,28,31,1,2,233.66,234.41,1,600,1,2,233.58,234.43,505,105,2,2,233.53,234.5,10,63,1,4,233.5,234.75,100,1,1,1,233.45,234.79,15,2000,1,1,233.4,234.89,110,2,2,2,233.39,235.0,10,213,1,6,233.31,235.03,110,2,2,1,JPM
2024-10-21T12:15:39.314289508Z,2024-10-21T12:15:39.314122970Z,10,2,38,A,B,0,233.76,200,130,166538,12504563,233.76,234.13,200,400,1,1,233.7,234.17,1200,31,1,2,233.69,234.41,28,600,1,2,233.66,234.43,1,105,1,2,233.58,234.5,505,63,2,4,233.53,234.75,10,1,1,1,233.5,234.79,100,2000,1,1,233.45,234.89,15,2,1,2,233.4,235.0,110,213,2,6,233.39,235.03,10,2,1,1,JPM
2024-10-21T12:15:39.314303543Z,2024-10-21T12:15:39.314137186Z,10,2,38,A,A,0,234.1,400,130,166357,12504564,233.76,234.1,200,400,1,1,233.7,234.13,1200,400,1,1,233.69,234.17,28,31,1,2,233.66,234.41,1,600,1,2,233.58,234.43,505,105,2,2,233.53,234.5,10,63,1,4,233.5,234.75,100,1,1,1,233.45,234.79,15,2000,1,1,233.4,234.89,110,2,2,2,233.39,235.0,10,213,1,6,JPM
2024-10-21T12:15:40.360705214Z,2024-10-21T12:15:40.360537773Z,10,2,38,C,A,0,234.1,400,130,167441,12505301,233.76,234.13,200,400,1,1,233.7,234.17,1200,31,1,2,233.69,234.41,28,600,1,2,233.66,234.43,1,105,1,2,233.58,234.5,505,63,2,4,233.53,234.75,10,1,1,1,233.5,234.79,100,2000,1,1,233.45,234.89,15,2,1,2,233.4,235.0,110,213,2,6,233.39,235.03,10,2,1,1,JPM
2024-10-21T12:15:40.360715053Z,2024-10-21T12:15:40.360548894Z,10,2,38,A,A,1,234.15,400,130,166159,12505302,233.76,234.13,200,400,1,1,233.7,234.15,1200,400,1,1,233.69,234.17,28,31,1,2,233.66,234.41,1,600,1,2,233.58,234.43,505,105,2,2,233.53,234.5,10,63,1,4,233.5,234.75,100,1,1,1,233.45,234.79,15,2000,1,1,233.4,234.89,110,2,2,2,233.39,235.0,10,213,1,6,JPM
2024-10-21T12:15:40.361263637Z,2024-10-21T12:15:40.361097351Z,10,2,38,C,A,2,234.17,30,130,166286,12505308,233.76,234.13,200,400,1,1,233.7,234.15,1200,400,1,1,233.69,234.17,28,1,1,1,233.66,234.41,1,600,1,2,233.58,234.43,505,105,2,2,233.53,234.5,10,63,1,4,233.5,234.75,100,1,1,1,233.45,234.79,15,2000,1,1,233.4,234.89,110,2,2,2,233.39,235.0,10,213,1,6,JPM
2024-10-21T12:15:40.361312977Z,2024-10-21T12:15:40.361146693Z,10,2,38,A,A,3,234.22,27,130,166284,12505309,233.76,234.13,200,400,1,1,233.7,234.15,1200,400,1,1,233.69,234.17,28,1,1,1,233.66,234.22,1,27,1,1,233.58,234.41,505,600,2,2,233.53,234.43,10,105,1,2,233.5,234.5,100,63,1,4,233.45,234.75,15,1,1,1,233.4,234.79,110,2000,2,1,233.39,234.89,10,2,1,2,JPM
2024-10-21T12:15:43.401012118Z,2024-10-21T12:15:43.400846263Z,10,2,38,C,B,0,233.76,200,130,165855,12511389,233.7,234.13,1200,400,1,1,233.69,234.15,28,400,1,1,233.66,234.17,1,1,1,1,233.58,234.22,505,27,2,1,233.53,234.41,10,600,1,2,233.5,234.43,100,105,1,2,233.45,234.5,15,63,1,4,233.4,234.75,110,1,2,1,233.39,234.79,10,2000,1,1,233.31,234.89,110,2,2,2,JPM
2024-10-21T12:15:43.401025404Z,2024-10-21T12:15:43.400859035Z,10,2,38,A,B,0,233.74,200,130,166369,12511390,233.74,234.13,200,400,1,1,233.7,234.15,1200,400,1,1,233.69,234.17,28,1,1,1,233.66,234.22,1,27,1,1,233.58,234.41,505,600,2,2,233.53,234.43,10,105,1,2,233.5,234.5,100,63,1,4,233.45,234.75,15,1,1,1,233.4,234.79,110,2000,2,1,233.39,234.89,10,2,1,2,JPM
2024-10-21T12:15:43.425571225Z,2024-10-21T12:15:43.425405296Z,10,2,38,C,A,3,234.22,27,130,165929,12511697,233.74,234.13,200,400,1,1,233.7,234.15,1200,400,1,1,233.69,234.17,28,1,1,1,233.66,234.41,1,600,1,2,233.58,234.43,505,105,2,2,233.53,234.5,10,63,1,4,233.5,234.75,100,1,1,1,233.45,234.79,15,2000,1,1,233.4,234.89,110,2,2,2,233.39,235.0,10,213,1,6,JPM
2024-10-21T12:15:43.425623021Z,2024-10-21T12:15:43.425456541Z,10,2,38,A,A,3,234.21,26,130,166480,12511698,233.74,234.13,200,400,1,1,233.7,234.15,1200,400,1,1,233.69,234.17,28,1,1,1,233.66,234.21,1,26,1,1,233.58,234.41,505,600,2,2,233.53,234.43,10,105,1,2,233.5,234.5,100,63,1,4,233.45,234.75,15,1,1,1,233.4,234.79,110,2000,2,1,233.39,234.89,10,2,1,2,JPM
2024-10-21T12:15:43.454501811Z,2024-10-21T12:15:43.454335483Z,10,2,38,A,A,1,234.14,400,130,166328,12511807,233.74,234.13,200,400,1,1,233.7,234.14,1200,400,1,1,233.69,234.17,28,1,1,1,233.66,234.21,1,26,1,1,233.58,234.41,505,600,2,2,233.53,234.43,10,105,1,2,233.5,234.5,100,63,1,4,233.45,234.75,15,1,1,1,233.4,234.79,110,2000,2,1,233.39,234.89,10,2,1,2,JPM
2024-10-21T12:15:43.462491808Z,2024-10-21T12:15:43.462325554Z,10,2,38,A,A,0,234.13,400,130,166254,12511952,233.74,234.13,200,800,1,2,233.7,234.17,1200,1,1,1,233.69,234.21,28,26,1,1,233.66,234.41,1,600,1,2,233.58,234.43,505,105,2,2,233.53,234.5,10,63,1,4,233.5,234.75,100,1,1,1,233.45,234.79,15,2000,1,1,233.4,234.89,110,2,2,2,233.39,235.0,10,213,1,6,JPM
2024-10-21T12:15:43.490633387Z,2024-10-21T12:15:43.490467184Z,10,2,38,A,B,3,233.66,30,130,166203,12512344,233.74,234.13,200,800,1,2,233.7,234.17,1200,1,1,1,233.69,234.21,28,26,1,1,233.66,234.41,31,600,2,2,233.58,234.43,505,105,2,2,233.53,234.5,10,63,1,4,233.5,234.75,100,1,1,1,233.45,234.79,15,2000,1,1,233.4,234.89,110,2,2,2,233.39,235.0,10,213,1,6,JPM
2024-10-21T12:15:43.546265076Z,2024-10-21T12:15:43.546099003Z,10,2,38,C,B,2,233.69,28,130,166073,12512634,233.74,234.13,200,800,1,2,233.7,234.17,1200,1,1,1,233.66,234.21,31,26,2,1,233.58,234.41,505,600,2,2,233.53,234.43,10,105,1,2,233.5,234.5,100,63,1,4,233.45,234.75,15,1,1,1,233.4,234.79,110,2000,2,1,233.39,234.89,10,2,1,2,233.31,235.0,110,213,2,6,JPM
2024-10-21T12:15:43.594979866Z,2024-10-21T12:15:43.594813115Z,10,2,38,A,A,0,234.12,200,130,166751,12512827,233.74,234.12,200,200,1,1,233.7,234.13,1200,400,1,1,233.66,234.17,31,1,2,1,233.58,234.21,505,26,2,1,233.53,234.41,10,600,1,2,233.5,234.43,100,105,1,2,233.45,234.5,15,63,1,4,233.4,234.75,110,1,2,1,233.39,234.79,10,2000,1,1,233.31,234.89,110,2,2,2,JPM
2024-10-21T12:15:43.981450269Z,2024-10-21T12:15:43.981284269Z,10,2,38,A,A,3,234.19,28,130,166000,12513411,233.74,234.12,200,200,1,1,233.7,234.13,1200,400,1,1,233.66,234.17,31,1,2,1,233.58,234.19,505,28,2,1,233.53,234.21,10,26,1,1,233.5,234.41,100,600,1,2,233.45,234.43,15,105,1,2,233.4,234.5,110,63,2,4,233.39,234.75,10,1,1,1,233.31,234.79,110,2000,2,1,JPM
2024-10-21T12:15:43.981745796Z,2024-10-21T12:15:43.981579878Z,10,2,38,C,A,4,234.21,26,130,165918,12513419,233.74,234.12,200,200,1,1,233.7,234.13,1200,400,1,1,233.66,234.17,31,1,2,1,233.58,234.19,505,28,2,1,233.53,234.41,10,600,1,2,233.5,234.43,100,105,1,2,233.45,234.5,15,63,1,4,233.4,234.75,110,1,2,1,233.39,234.79,10,2000,1,1,233.31,234.89,110,2,2,2,JPM
2024-10-21T12:15:46.504609799Z,2024-10-21T12:15:46.504444030Z,10,2,38,C,B,0,233.74,200,130,165769,12517721,233.7,234.12,1200,200,1,1,233.66,234.13,31,400,2,1,233.58,234.17,505,1,2,1,233.53,234.19,10,28,1,1,233.5,234.41,100,600,1,2,233.45,234.43,15,105,1,2,233.4,234.5,110,63,2,4,233.39,234.75,10,1,1,1,233.31,234.79,110,2000,2,1,233.3,234.89,100,2,1,2,JPM
2024-10-21T12:15:46.504623049Z,2024-10-21T12:15:46.504456348Z,10,2,38,A,B,0,233.73,200,130,166701,12517722,233.73,234.12,200,200,1,1,233.7,234.13,1200,400,1,1,233.66,234.17,31,1,2,1,233.58,234.19,505,28,2,1,233.53,234.41,10,600,1,2,233.5,234.43,100,105,1,2,233.45,234.5,15,63,1,4,233.4,234.75,110,1,2,1,233.39,234.79,10,2000,1,1,233.31,234.89,110,2,2,2,JPM
2024-10-21T12:15:46.504635795Z,2024-10-21T12:15:46.504469490Z,10,2,38,A,A,0,234.12,200,130,166305,12517724,233.73,234.12,200,400,1,2,233.7,234.13,1200,400,1,1,233.66,234.17,31,1,2,1,233.58,234.19,505,28,2,1,233.53,234.41,10,600,1,2,233.5,234.43,100,105,1,2,233.45,234.5,15,63,1,4,233.4,234.75,110,1,2,1,233.39,234.79,10,2000,1,1,233.31,234.89,110,2,2,2,JPM
2024-10-21T12:15:46.593857210Z,2024-10-21T12:15:46.593690522Z,10,2,38,A,A,3,234.18,30,130,166688,12518020,233.73,234.12,200,400,1,2,233.7,234.13,1200,400,1,1,233.66,234.17,31,1,2,1,233.58,234.18,505,30,2,1,233.53,234.19,10,28,1,1,233.5,234.41,100,600,1,2,233.45,234.43,15,105,1,2,233.4,234.5,110,63,2,4,233.39,234.75,10,1,1,1,233.31,234.79,110,2000,2,1,JPM
2024-10-21T12:15:46.594225497Z,2024-10-21T12:15:46.594059334Z,10,2,38,C,A,4,234.19,28,130,166163,12518032,233.73,234.12,200,400,1,2,233.7,234.13,1200,400,1,1,233.66,234.17,31,1,2,1,233.58,234.18,505,30,2,1,233.53,234.41,10,600,1,2,233.5,234.43,100,105,1,2,233.45,234.5,15,63,1,4,233.4,234.75,110,1,2,1,233.39,234.79,10,2000,1,1,233.31,234.89,110,2,2,2,JPM
2024-10-21T12:15:50.469902981Z,2024-10-21T12:15:50.469736889Z,10,2,38,C,A,0,234.12,200,130,166092,12522085,233.73,234.12,200,200,1,1,233.7,234.13,1200,400,1,1,233.66,234.17,31,1,2,1,233.58,234.18,505,30,2,1,233.53,234.41,10,600,1,2,233.5,234.43,100,105,1,2,233.45,234.5,15,63,1,4,233.4,234.75,110,1,2,1,233.39,234.79,10,2000,1,1,233.31,234.89,110,2,2,2,JPM
2024-10-21T12:15:55.593624526Z,2024-10-21T12:15:55.593458354Z,10,2,38,C,B,2,233.66,30,130,166172,12526601,233.73,234.12,200,200,1,1,233.7,234.13,1200,400,1,1,233.66,234.17,1,1,1,1,233.58,234.18,505,30,2,1,233.53,234.41,10,600,1,2,233.5,234.43,100,105,1,2,233.45,234.5,15,63,1,4,233.4,234.75,110,1,2,1,233.39,234.79,10,2000,1,1,233.31,234.89,110,2,2,2,JPM
2024-10-21T12:15:55.594134274Z,2024-10-21T12:15:55.593967834Z,10,2,38,A,B,1,233.71,29,130,166440,12526613,233.73,234.12,200,200,1,1,233.71,234.13,29,400,1,1,233.7,234.17,1200,1,1,1,233.66,234.18,1,30,1,1,233.58,234.41,505,600,2,2,233.53,234.43,10,105,1,2,233.5,234.5,100,63,1,4,233.45,234.75,15,1,1,1,233.4,234.79,110,2000,2,1,233.39,234.89,10,2,1,2,JPM
2024-10-21T12:15:55.643690186Z,2024-10-21T12:15:55.643523614Z,10,2,38,A,B,0,233.77,200,130,166572,12526664,233.77,234.12,200,200,1,1,233.71,234.13,29,400,1,1,233.7,234.17,1200,1,1,1,233.66,234.18,1,30,1,1,233.58,234.41,505,600,2,2,233.53,234.43,10,105,1,2,233.5,234.5,100,63,1,4,233.45,234.75,15,1,1,1,233.4,234.79,110,2000,2,1,233.39,234.89,10,2,1,2,JPM
2024-10-21T12:16:00.253510382Z,2024-10-21T12:16:00.253343668Z,10,2,38,A,A,0,234.11,200,130,166714,12533252,233.77,234.11,200,200,1,1,233.71,234.13,29,400,1,1,233.7,234.17,1200,1,1,1,233.66,234.18,1,30,1,1,233.58,234.41,505,600,2,2,233.53,234.43,10,105,1,2,233.5,234.5,100,63,1,4,233.45,234.75,15,1,1,1,233.4,234.79,110,2000,2,1,233.39,234.89,10,2,1,2,JPM
2024-10-21T12:16:02.523286908Z,2024-10-21T12:16:02.523121028Z,10,2,38,C,B,0,233.77,200,130,165880,12536233,233.71,234.11,29,200,1,1,233.7,234.13,1200,400,1,1,233.66,234.17,1,1,1,1,233.58,234.18,505,30,2,1,233.53,234.41,10,600,1,2,233.5,234.43,100,105,1,2,233.45,234.5,15,63,1,4,233.4,234.75,110,1,2,1,233.39,234.79,10,2000,1,1,233.31,234.89,110,2,2,2,JPM
2024-10-21T12:16:02.523299016Z,2024-10-21T12:16:02.523132984Z,10,2,38,A,B,0,233.76,200,130,166032,12536234,233.76,234.11,200,200,1,1,233.71,234.13,29,400,1,1,233.7,234.17,1200,1,1,1,233.66,234.18,1,30,1,1,233.58,234.41,505,600,2,2,233.53,234.43,10,105,1,2,233.5,234.5,100,63,1,4,233.45,234.75,15,1,1,1,233.4,234.79,110,2000,2,1,233.39,234.89,10,2,1,2,JPM
2024-10-21T12:16:02.593082475Z,2024-10-21T12:16:02.592915859Z,10,2,38,A,A,2,234.17,27,130,166616,12536503,233.76,234.11,200,200,1,1,233.71,234.13,29,400,1,1,233.7,234.17,1200,28,1,2,233.66,234.18,1,30,1,1,233.58,234.41,505,600,2,2,233.53,234.43,10,105,1,2,233.5,234.5,100,63,1,4,233.45,234.75,15,1,1,1,233.4,234.79,110,2000,2,1,233.39,234.89,10,2,1,2,JPM
2024-10-21T12:16:02.697524299Z,2024-10-21T12:16:02.697358278Z,10,2,38,C,A,3,234.18,30,130,166021,12536650,233.76,234.11,200,200,1,1,233.71,234.13,29,400,1,1,233.7,234.17,1200,28,1,2,233.66,234.41,1,600,1,2,233.58,234.43,505,105,2,2,233.53,234.5,10,63,1,4,233.5,234.75,100,1,1,1,233.45,234.79,15,2000,1,1,233.4,234.89,110,2,2,2,233.39,235.0,10,213,1,6,JPM
2024-10-21T12:16:04.305857113Z,2024-10-21T12:16:04.305690771Z,10,2,38,A,B,0,233.77,200,130,166342,12539302,233.77,234.11,200,200,1,1,233.71,234.13,29,400,1,1,233.7,234.17,1200,28,1,2,233.66,234.41,1,600,1,2,233.58,234.43,505,105,2,2,233.53,234.5,10,63,1,4,233.5,234.75,100,1,1,1,233.45,234.79,15,2000,1,1,233.4,234.89,110,2,2,2,233.39,235.0,10,213,1,6,JPM
2024-10-21T12:16:08.452361078Z,2024-10-21T12:16:08.452195034Z,10,2,38,C,B,0,233.77,200,130,166044,12544790,233.71,234.11,29,200,1,1,233.7,234.13,1200,400,1,1,233.66,234.17,1,28,1,2,233.58,234.41,505,600,2,2,233.53,234.43,10,105,1,2,233.5,234.5,100,63,1,4,233.45,234.75,15,1,1,1,233.4,234.79,110,2000,2,1,233.39,234.89,10,2,1,2,233.31,235.0,110,213,2,6,JPM
2024-10-21T12:16:08.452373943Z,2024-10-21T12:16:08.452206841Z,10,2,38,A,B,0,233.76,200,130,167102,12544791,233.76,234.11,200,200,1,1,233.71,234.13,29,400,1,1,233.7,234.17,1200,28,1,2,233.66,234.41,1,600,1,2,233.58,234.43,505,105,2,2,233.53,234.5,10,63,1,4,233.5,234.75,100,1,1,1,233.45,234.79,15,2000,1,1,233.4,234.89,110,2,2,2,233.39,235.0,10,213,1,6,JPM
2024-10-21T12:16:09.449971056Z,2024-10-21T12:16:09.449805017Z,10,2,38,C,B,1,233.71,29,130,166039,12545654,233.76,234.11,200,200,1,1,233.7,234.13,1200,400,1,1,233.66,234.17,1,28,1,2,233.58,234.41,505,600,2,2,233.53,234.43,10,105,1,2,233.5,234.5,100,63,1,4,233.45,234.75,15,1,1,1,233.4,234.79,110,2000,2,1,233.39,234.89,10,2,1,2,233.31,235.0,110,213,2,6,JPM
2024-10-21T12:16:09.450027355Z,2024-10-21T12:16:09.449860480Z,10,2,38,A,B,2,233.69,30,130,166875,12545655,233.76,234.11,200,200,1,1,233.7,234.13,1200,400,1,1,233.69,234.17,30,28,1,2,233.66,234.41,1,600,1,2,233.58,234.43,505,105,2,2,233.53,234.5,10,63,1,4,233.5,234.75,100,1,1,1,233.45,234.79,15,2000,1,1,233.4,234.89,110,2,2,2,233.39,235.0,10,213,1,6,JPM
2024-10-21T12:16:09.753978514Z,2024-10-21T12:16:09.753811454Z,10,2,38,C,B,0,233.76,200,130,167060,12546012,233.7,234.11,1200,200,1,1,233.69,234.13,30,400,1,1,233.66,234.17,1,28,1,2,233.58,234.41,505,600,2,2,233.53,234.43,10,105,1,2,233.5,234.5,100,63,1,4,233.45,234.75,15,1,1,1,233.4,234.79,110,2000,2,1,233.39,234.89,10,2,1,2,233.31,235.0,110,213,2,6,JPM
2024-10-21T12:16:09.753989713Z,2024-10-21T12:16:09.753823460Z,10,2,38,A,B,0,233.74,200,130,166253,12546013,233.74,234.11,200,200,1,1,233.7,234.13,1200,400,1,1,233.69,234.17,30,28,1,2,233.66,234.41,1,600,1,2,233.58,234.43,505,105,2,2,233.53,234.5,10,63,1,4,233.5,234.75,100,1,1,1,233.45,234.79,15,2000,1,1,233.4,234.89,110,2,2,2,233.39,235.0,10,213,1,6,JPM
2024-10-21T12:16:09.794247866Z,2024-10-21T12:16:09.794081348Z,10,2,38,A,A,0,234.1,200,130,166518,12546087,233.74,234.1,200,200,1,1,233.7,234.13,1200,400,1,1,233.69,234.17,30,28,1,2,233.66,234.41,1,600,1,2,233.58,234.43,505,105,2,2,233.53,234.5,10,63,1,4,233.5,234.75,100,1,1,1,233.45,234.79,15,2000,1,1,233.4,234.89,110,2,2,2,233.39,235.0,10,213,1,6,JPM
2024-10-21T12:16:09.813187546Z,2024-10-21T12:16:09.813020869Z,10,2,38,A,B,0,233.75,200,130,166677,12546174,233.75,234.1,200,200,1,1,233.7,234.13,1200,400,1,1,233.69,234.17,30,28,1,2,233.66,234.41,1,600,1,2,233.58,234.43,505,105,2,2,233.53,234.5,10,63,1,4,233.5,234.75,100,1,1,1,233.45,234.79,15,2000,1,1,233.4,234.89,110,2,2,2,233.39,235.0,10,213,1,6,JPM
2024-10-21T12:16:10.366670967Z,2024-10-21T12:16:10.366504475Z,10,2,38,A,A,0,234.09,200,130,166492,12546733,233.75,234.09,200,200,1,1,233.7,234.13,1200,400,1,1,233.69,234.17,30,28,1,2,233.66,234.41,1,600,1,2,233.58,234.43,505,105,2,2,233.53,234.5,10,63,1,4,233.5,234.75,100,1,1,1,233.45,234.79,15,2000,1,1,233.4,234.89,110,2,2,2,233.39,235.0,10,213,1,6,JPM
2024-10-21T12:16:10.387245860Z,2024-10-21T12:16:10.387079865Z,10,2,38,C,A,2,234.17,27,130,165995,12546807,233.75,234.09,200,200,1,1,233.7,234.13,1200,400,1,1,233.69,234.17,30,1,1,1,233.66,234.41,1,600,1,2,233.58,234.43,505,105,2,2,233.53,234.5,10,63,1,4,233.5,234.75,100,1,1,1,233.45,234.79,15,2000,1,1,233.4,234.89,110,2,2,2,233.39,235.0,10,213,1,6,JPM
2024-10-21T12:16:10.387302448Z,2024-10-21T12:16:10.387136109Z,10,2,38,A,A,2,234.16,29,130,166339,12546808,233.75,234.09,200,200,1,1,233.7,234.13,1200,400,1,1,233.69,234.16,30,29,1,1,233.66,234.17,1,1,1,1,233.58,234.41,505,600,2,2,233.53,234.43,10,105,1,2,233.5,234.5,100,63,1,4,233.45,234.75,15,1,1,1,233.4,234.79,110,2000,2,1,233.39,234.89,10,2,1,2,JPM
2024-10-21T12:16:12.011187719Z,2024-10-21T12:16:12.011021598Z,10,2,38,C,A,0,234.09,200,130,166121,12547958,233.75,234.13,200,400,1,1,233.7,234.16,1200,29,1,1,233.69,234.17,30,1,1,1,233.66,234.41,1,600,1,2,233.58,234.43,505,105,2,2,233.53,234.5,10,63,1,4,233.5,234.75,100,1,1,1,233.45,234.79,15,2000,1,1,233.4,234.89,110,2,2,2,233.39,235.0,10,213,1,6,JPM
2024-10-21T12:16:12.011200956Z,2024-10-21T12:16:12.011034600Z,10,2,38,A,A,0,234.11,200,130,166356,12547959,233.75,234.11,200,200,1,1,233.7,234.13,1200,400,1,1,233.69,234.16,30,29,1,1,233.66,234.17,1,1,1,1,233.58,234.41,505,600,2,2,233.53,234.43,10,105,1,2,233.5,234.5,100,63,1,4,233.45,234.75,15,1,1,1,233.4,234.79,110,2000,2,1,233.39,234.89,10,2,1,2,JPM
2024-10-21T12:16:12.100747677Z,2024-10-21T12:16:12.100581387Z,10,2,38,A,A,0,234.1,200,130,166290,12548144,233.75,234.1,200,200,1,1,233.7,234.13,1200,400,1,1,233.69,234.16,30,29,1,1,233.66,234.17,1,1,1,1,233.58,234.41,505,600,2,2,233.53,234.43,10,105,1,2,233.5,234.5,100,63,1,4,233.45,234.75,15,1,1,1,233.4,234.79,110,2000,2,1,233.39,234.89,10,2,1,2,JPM
2024-10-21T12:16:13.573877503Z,2024-10-21T12:16:13.573710917Z,10,2,38,A,A,0,234.09,200,130,166586,12549200,233.75,234.09,200,200,1,1,233.7,234.13,1200,400,1,1,233.69,234.16,30,29,1,1,233.66,234.17,1,1,1,1,233.58,234.41,505,600,2,2,233.53,234.43,10,105,1,2,233.5,234.5,100,63,1,4,233.45,234.75,15,1,1,1,233.4,234.79,110,2000,2,1,233.39,234.89,10,2,1,2,JPM
2024-10-21T12:16:14.439317152Z,2024-10-21T12:16:14.439151195Z,10,2,38,C,A,0,234.09,200,130,165957,12549789,233.75,234.13,200,400,1,1,233.7,234.16,1200,29,1,1,233.69,234.17,30,1,1,1,233.66,234.41,1,600,1,2,233.58,234.43,505,105,2,2,233.53,234.5,10,63,1,4,233.5,234.75,100,1,1,1,233.45,234.79,15,2000,1,1,233.4,234.89,110,2,2,2,233.39,235.0,10,213,1,6,JPM
2024-10-21T12:16:14.439329197Z,2024-10-21T12:16:14.439163159Z,10,2,38,A,A,0,234.1,200,130,166038,12549790,233.75,234.1,200,200,1,1,233.7,234.13,1200,400,1,1,233.69,234.16,30,29,1,1,233.66,234.17,1,1,1,1,233.58,234.41,505,600,2,2,233.53,234.43,10,105,1,2,233.5,234.5,100,63,1,4,233.45,234.75,15,1,1,1,233.4,234.79,110,2000,2,1,233.39,234.89,10,2,1,2,JPM
2024-10-21T12:16:14.647379555Z,2024-10-21T12:16:14.647213365Z,10,2,38,A,A,0,234.09,200,130,166190,12550175,233.75,234.09,200,200,1,1,233.7,234.13,1200,400,1,1,233.69,234.16,30,29,1,1,233.66,234.17,1,1,1,1,233.58,234.41,505,600,2,2,233.53,234.43,10,105,1,2,233.5,234.5,100,63,1,4,233.45,234.75,15,1,1,1,233.4,234.79,110,2000,2,1,233.39,234.89,10,2,1,2,JPM
2024-10-21T12:16:20.281941255Z,2024-10-21T12:16:20.281774908Z,10,2,38,C,B,0,233.75,200,130,166347,12556695,233.7,234.09,1200,200,1,1,233.69,234.13,30,400,1,1,233.66,234.16,1,29,1,1,233.58,234.17,505,1,2,1,233.53,234.41,10,600,1,2,233.5,234.43,100,105,1,2,233.45,234.5,15,63,1,4,233.4,234.75,110,1,2,1,233.39,234.79,10,2000,1,1,233.31,234.89,110,2,2,2,JPM
2024-10-21T12:16:20.281953090Z,2024-10-21T12:16:20.281786576Z,10,2,38,A,B,0,233.73,200,130,166514,12556696,233.73,234.09,200,200,1,1,233.7,234.13,1200,400,1,1,233.69,234.16,30,29,1,1,233.66,234.17,1,1,1,1,233.58,234.41,505,600,2,2,233.53,234.43,10,105,1,2,233.5,234.5,100,63,1,4,233.45,234.75,15,1,1,1,233.4,234.79,110,2000,2,1,233.39,234.89,10,2,1,2,JPM
2024-10-21T12:16:20.339335090Z,2024-10-21T12:16:20.339168043Z,10,2,38,A,B,0,233.74,200,130,167047,12556816,233.74,234.09,200,200,1,1,233.7,234.13,1200,400,1,1,233.69,234.16,30,29,1,1,233.66,234.17,1,1,1,1,233.58,234.41,505,600,2,2,233.53,234.43,10,105,1,2,233.5,234.5,100,63,1,4,233.45,234.75,15,1,1,1,233.4,234.79,110,2000,2,1,233.39,234.89,10,2,1,2,JPM
2024-10-21T12:16:20.352255989Z,2024-10-21T12:16:20.352089791Z,10,2,38,A,B,0,233.74,200,130,166198,12556912,233.74,234.09,400,200,2,1,233.7,234.13,1200,400,1,1,233.69,234.16,30,29,1,1,233.66,234.17,1,1,1,1,233.58,234.41,505,600,2,2,233.53,234.43,10,105,1,2,233.5,234.5,100,63,1,4,233.45,234.75,15,1,1,1,233.4,234.79,110,2000,2,1,233.39,234.89,10,2,1,2,JPM
2024-10-21T12:16:20.353221672Z,2024-10-21T12:16:20.353055730Z,10,2,38,C,B,0,233.74,200,130,165942,12556917,233.74,234.09,200,200,1,1,233.7,234.13,1200,400,1,1,233.69,234.16,30,29,1,1,233.66,234.17,1,1,1,1,233.58,234.41,505,600,2,2,233.53,234.43,10,105,1,2,233.5,234.5,100,63,1,4,233.45,234.75,15,1,1,1,233.4,234.79,110,2000,2,1,233.39,234.89,10,2,1,2,JPM
2024-10-21T12:16:20.448635525Z,2024-10-21T12:16:20.448469192Z,10,2,38,A,A,0,234.08,200,130,166333,12557144,233.74,234.08,200,200,1,1,233.7,234.13,1200,400,1,1,233.69,234.16,30,29,1,1,233.66,234.17,1,1,1,1,233.58,234.41,505,600,2,2,233.53,234.43,10,105,1,2,233.5,234.5,100,63,1,4,233.45,234.75,15,1,1,1,233.4,234.79,110,2000,2,1,233.39,234.89,10,2,1,2,JPM
2024-10-21T12:16:34.456477234Z,2024-10-21T12:16:34.456311187Z,10,2,38,C,A,2,234.16,29,130,166047,12569933,233.74,234.08,200,200,1,1,233.7,234.13,1200,400,1,1,233.69,234.17,30,1,1,1,233.66,234.41,1,600,1,2,233.58,234.43,505,105,2,2,233.53,234.5,10,63,1,4,233.5,234.75,100,1,1,1,233.45,234.79,15,2000,1,1,233.4,234.89,110,2,2,2,233.39,235.0,10,213,1,6,JPM
2024-10-21T12:16:34.456534808Z,2024-10-21T12:16:34.456367935Z,10,2,38,A,A,2,234.15,30,130,166873,12569937,233.74,234.08,200,200,1,1,233.7,234.13,1200,400,1,1,233.69,234.15,30,30,1,1,233.66,234.17,1,1,1,1,233.58,234.41,505,600,2,2,233.53,234.43,10,105,1,2,233.5,234.5,100,63,1,4,233.45,234.75,15,1,1,1,233.4,234.79,110,2000,2,1,233.39,234.89,10,2,1,2,JPM
2024-10-21T12:16:35.928291181Z,2024-10-21T12:16:35.928124957Z,10,2,38,C,B,2,233.69,30,130,166224,12572168,233.74,234.08,200,200,1,1,233.7,234.13,1200,400,1,1,233.66,234.15,1,30,1,1,233.58,234.17,505,1,2,1,233.53,234.41,10,600,1,2,233.5,234.43,100,105,1,2,233.45,234.5,15,63,1,4,233.4,234.75,110,1,2,1,233.39,234.79,10,2000,1,1,233.31,234.89,110,2,2,2,JPM
2024-10-21T12:16:35.928342407Z,2024-10-21T12:16:35.928176126Z,10,2,38,A,B,2,233.67,28,130,166281,12572169,233.74,234.08,200,200,1,1,233.7,234.13,1200,400,1,1,233.67,234.15,28,30,1,1,233.66,234.17,1,1,1,1,233.58,234.41,505,600,2,2,233.53,234.43,10,105,1,2,233.5,234.5,100,63,1,4,233.45,234.75,15,1,1,1,233.4,234.79,110,2000,2,1,233.39,234.89,10,2,1,2,JPM
2024-10-21T12:16:36.290257872Z,2024-10-21T12:16:36.290091431Z,10,2,38,A,A,1,234.1,100,130,166441,12572429,233.74,234.08,200,200,1,1,233.7,234.1,1200,100,1,1,233.67,234.13,28,400,1,1,233.66,234.15,1,30,1,1,233.58,234.17,505,1,2,1,233.53,234.41,10,600,1,2,233.5,234.43,100,105,1,2,233.45,234.5,15,63,1,4,233.4,234.75,110,1,2,1,233.39,234.79,10,2000,1,1,JPM
2024-10-21T12:16:37.672891891Z,2024-10-21T12:16:37.672726079Z,10,2,38,C,B,2,233.67,28,130,165812,12574327,233.74,234.08,200,200,1,1,233.7,234.1,1200,100,1,1,233.66,234.13,1,400,1,1,233.58,234.15,505,30,2,1,233.53,234.17,10,1,1,1,233.5,234.41,100,600,1,2,233.45,234.43,15,105,1,2,233.4,234.5,110,63,2,4,233.39,234.75,10,1,1,1,233.31,234.79,110,2000,2,1,JPM
2024-10-21T12:16:37.673069955Z,2024-10-21T12:16:37.672903531Z,10,2,38,A,B,2,233.68,27,130,166424,12574328,233.74,234.08,200,200,1,1,233.7,234.1,1200,100,1,1,233.68,234.13,27,400,1,1,233.66,234.15,1,30,1,1,233.58,234.17,505,1,2,1,233.53,234.41,10,600,1,2,233.5,234.43,100,105,1,2,233.45,234.5,15,63,1,4,233.4,234.75,110,1,2,1,233.39,234.79,10,2000,1,1,JPM
2024-10-21T12:16:41.311074051Z,2024-10-21T12:16:41.310907658Z,10,2,38,C,B,0,233.74,200,130,166393,12577924,233.7,234.08,1200,200,1,1,233.68,234.1,27,100,1,1,233.66,234.13,1,400,1,1,233.58,234.15,505,30,2,1,233.53,234.17,10,1,1,1,233.5,234.41,100,600,1,2,233.45,234.43,15,105,1,2,233.4,234.5,110,63,2,4,233.39,234.75,10,1,1,1,233.31,234.79,110,2000,2,1,JPM
2024-10-21T12:16:41.311087986Z,2024-10-21T12:16:41.310921026Z,10,2,38,A,B,1,233.69,200,130,166960,12577925,233.7,234.08,1200,200,1,1,233.69,234.1,200,100,1,1,233.68,234.13,27,400,1,1,233.66,234.15,1,30,1,1,233.58,234.17,505,1,2,1,233.53,234.41,10,600,1,2,233.5,234.43,100,105,1,2,233.45,234.5,15,63,1,4,233.4,234.75,110,1,2,1,233.39,234.79,10,2000,1,1,JPM
2024-10-21T12:16:42.498174235Z,2024-10-21T12:16:42.498007357Z,10,2,38,A,A,5,234.25,100,130,166878,12578938,233.7,234.08,1200,200,1,1,233.69,234.1,200,100,1,1,233.68,234.13,27,400,1,1,233.66,234.15,1,30,1,1,233.58,234.17,505,1,2,1,233.53,234.25,10,100,1,1,233.5,234.41,100,600,1,2,233.45,234.43,15,105,1,2,233.4,234.5,110,63,2,4,233.39,234.75,10,1,1,1,JPM
2024-10-21T12:16:44.366676689Z,2024-10-21T12:16:44.366509790Z,10,2,38,A,B,0,233.74,200,130,166899,12580824,233.74,234.08,200,200,1,1,233.7,234.1,1200,100,1,1,233.68,234.13,27,400,1,1,233.66,234.15,1,30,1,1,233.58,234.17,505,1,2,1,233.53,234.25,10,100,1,1,233.5,234.41,100,600,1,2,233.45,234.43,15,105,1,2,233.4,234.5,110,63,2,4,233.39,234.75,10,1,1,1,JPM
2024-10-21T12:16:44.533960641Z,2024-10-21T12:16:44.533794596Z,10,2,38,A,A,0,233.9,18,130,166045,12580968,233.74,233.9,200,18,1,1,233.7,234.08,1200,200,1,1,233.68,234.1,27,100,1,1,233.66,234.13,1,400,1,1,233.58,234.15,505,30,2,1,233.53,234.17,10,1,1,1,233.5,234.25,100,100,1,1,233.45,234.41,15,600,1,2,233.4,234.43,110,105,2,2,233.39,234.5,10,63,1,4,JPM
2024-10-21T12:16:44.802698042Z,2024-10-21T12:16:44.802532155Z,10,2,38,C,A,4,234.15,30,130,165887,12581165,233.74,233.9,200,18,1,1,233.7,234.08,1200,200,1,1,233.68,234.1,27,100,1,1,233.66,234.13,1,400,1,1,233.58,234.17,505,1,2,1,233.53,234.25,10,100,1,1,233.5,234.41,100,600,1,2,233.45,234.43,15,105,1,2,233.4,234.5,110,63,2,4,233.39,234.75,10,1,1,1,JPM
2024-10-21T12:16:44.802744697Z,2024-10-21T12:16:44.802578420Z,10,2,38,A,A,3,234.11,27,130,166277,12581166,233.74,233.9,200,18,1,1,233.7,234.08,1200,200,1,1,233.68,234.1,27,100,1,1,233.66,234.11,1,27,1,1,233.58,234.13,505,400,2,1,233.53,234.17,10,1,1,1,233.5,234.25,100,100,1,1,233.45,234.41,15,600,1,2,233.4,234.43,110,105,2,2,233.39,234.5,10,63,1,4,JPM
2024-10-21T12:16:47.612405002Z,2024-10-21T12:16:47.612239006Z,10,2,38,A,A,1,234.08,200,130,165996,12583335,233.74,233.9,200,18,1,1,233.7,234.08,1200,400,1,2,233.68,234.1,27,100,1,1,233.66,234.11,1,27,1,1,233.58,234.13,505,400,2,1,233.53,234.17,10,1,1,1,233.5,234.25,100,100,1,1,233.45,234.41,15,600,1,2,233.4,234.43,110,105,2,2,233.39,234.5,10,63,1,4,JPM
2024-10-21T12:16:47.667042872Z,2024-10-21T12:16:47.666876898Z,10,2,38,C,A,1,234.08,200,130,165974,12583345,233.74,233.9,200,18,1,1,233.7,234.08,1200,200,1,1,233.68,234.1,27,100,1,1,233.66,234.11,1,27,1,1,233.58,234.13,505,400,2,1,233.53,234.17,10,1,1,1,233.5,234.25,100,100,1,1,233.45,234.41,15,600,1,2,233.4,234.43,110,105,2,2,233.39,234.5,10,63,1,4,JPM
2024-10-21T12:16:47.667056416Z,2024-10-21T12:16:47.666890051Z,10,2,38,A,A,1,234.04,200,130,166365,12583346,233.74,233.9,200,18,1,1,233.7,234.04,1200,200,1,1,233.68,234.1,27,100,1,1,233.66,234.11,1,27,1,1,233.58,234.13,505,400,2,1,233.53,234.17,10,1,1,1,233.5,234.25,100,100,1,1,233.45,234.41,15,600,1,2,233.4,234.43,110,105,2,2,233.39,234.5,10,63,1,4,JPM
2024-10-21T12:16:47.926963883Z,2024-10-21T12:16:47.926797838Z,10,2,38,C,B,0,233.74,200,130,166045,12583828,233.7,233.9,1200,18,1,1,233.68,234.04,27,200,1,1,233.66,234.1,1,100,1,1,233.58,234.11,505,27,2,1,233.53,234.13,10,400,1,1,233.5,234.17,100,1,1,1,233.45,234.25,15,100,1,1,233.4,234.41,110,600,2,2,233.39,234.43,10,105,1,2,233.31,234.5,110,63,2,4,JPM
2024-10-21T12:16:47.926976599Z,2024-10-21T12:16:47.926810269Z,10,2,38,A,B,1,233.68,200,130,166330,12583829,233.7,233.9,1200,18,1,1,233.68,234.04,227,200,2,1,233.66,234.1,1,100,1,1,233.58,234.11,505,27,2,1,233.53,234.13,10,400,1,1,233.5,234.17,100,1,1,1,233.45,234.25,15,100,1,1,233.4,234.41,110,600,2,2,233.39,234.43,10,105,1,2,233.31,234.5,110,63,2,4,JPM
2024-10-21T12:16:48.065770361Z,2024-10-21T12:16:48.065603630Z,10,2,38,C,A,3,234.11,27,130,166731,12584067,233.7,233.9,1200,18,1,1,233.68,234.04,227,200,2,1,233.66,234.1,1,100,1,1,233.58,234.13,505,400,2,1,233.53,234.17,10,1,1,1,233.5,234.25,100,100,1,1,233.45,234.41,15,600,1,2,233.4,234.43,110,105,2,2,233.39,234.5,10,63,1,4,233.31,234.75,110,1,2,1,JPM
2024-10-21T12:16:48.065827712Z,2024-10-21T12:16:48.065661214Z,10,2,38,A,A,2,234.06,29,130,166498,12584068,233.7,233.9,1200,18,1,1,233.68,234.04,227,200,2,1,233.66,234.06,1,29,1,1,233.58,234.1,505,100,2,1,233.53,234.13,10,400,1,1,233.5,234.17,100,1,1,1,233.45,234.25,15,100,1,1,233.4,234.41,110,600,2,2,233.39,234.43,10,105,1,2,233.31,234.5,110,63,2,4,JPM
2024-10-21T12:16:48.123133937Z,2024-10-21T12:16:48.122967378Z,10,2,38,A,A,1,234.01,200,130,166559,12584094,233.7,233.9,1200,18,1,1,233.68,234.01,227,200,2,1,233.66,234.06,1,29,1,1,233.58,234.1,505,100,2,1,233.53,234.13,10,400,1,1,233.5,234.17,100,1,1,1,233.45,234.25,15,100,1,1,233.4,234.41,110,600,2,2,233.39,234.43,10,105,1,2,233.31,234.5,110,63,2,4,JPM
2024-10-21T12:16:48.228533367Z,2024-10-21T12:16:48.228366485Z,10,2,38,A,A,1,234.01,200,130,166882,12584254,233.7,233.9,1200,18,1,1,233.68,234.01,227,400,2,2,233.66,234.06,1,29,1,1,233.58,234.1,505,100,2,1,233.53,234.13,10,400,1,1,233.5,234.17,100,1,1,1,233.45,234.25,15,100,1,1,233.4,234.41,110,600,2,2,233.39,234.43,10,105,1,2,233.31,234.5,110,63,2,4,JPM
2024-10-21T12:16:48.283326363Z,2024-10-21T12:16:48.283159712Z,10,2,38,C,A,1,234.01,200,130,166651,12584287,233.7,233.9,1200,18,1,1,233.68,234.01,227,200,2,1,233.66,234.06,1,29,1,1,233.58,234.1,505,100,2,1,233.53,234.13,10,400,1,1,233.5,234.17,100,1,1,1,233.45,234.25,15,100,1,1,233.4,234.41,110,600,2,2,233.39,234.43,10,105,1,2,233.31,234.5,110,63,2,4,JPM
2024-10-21T12:16:48.283339638Z,2024-10-21T12:16:48.283173265Z,10,2,38,A,A,1,233.98,200,130,166373,12584288,233.7,233.9,1200,18,1,1,233.68,233.98,227,200,2,1,233.66,234.06,1,29,1,1,233.58,234.1,505,100,2,1,233.53,234.13,10,400,1,1,233.5,234.17,100,1,1,1,233.45,234.25,15,100,1,1,233.4,234.41,110,600,2,2,233.39,234.43,10,105,1,2,233.31,234.5,110,63,2,4,JPM
2024-10-21T12:16:49.563943091Z,2024-10-21T12:16:49.563776410Z,10,2,38,C,A,0,233.9,18,130,166681,12585847,233.7,233.98,1200,200,1,1,233.68,234.06,227,29,2,1,233.66,234.1,1,100,1,1,233.58,234.13,505,400,2,1,233.53,234.17,10,1,1,1,233.5,234.25,100,100,1,1,233.45,234.41,15,600,1,2,233.4,234.43,110,105,2,2,233.39,234.5,10,63,1,4,233.31,234.75,110,1,2,1,JPM
2024-10-21T12:16:49.564921505Z,2024-10-21T12:16:49.564755651Z,10,2,38,C,B,1,233.68,200,130,165854,12585849,233.7,233.98,1200,200,1,1,233.68,234.06,27,29,1,1,233.66,234.1,1,100,1,1,233.58,234.13,505,400,2,1,233.53,234.17,10,1,1,1,233.5,234.25,100,100,1,1,233.45,234.41,15,600,1,2,233.4,234.43,110,105,2,2,233.39,234.5,10,63,1,4,233.31,234.75,110,1,2,1,JPM
2024-10-21T12:16:49.635290441Z,2024-10-21T12:16:49.635124163Z,10,2,38,C,A,0,233.98,200,130,166278,12585962,233.7,234.06,1200,29,1,1,233.68,234.1,27,100,1,1,233.66,234.13,1,400,1,1,233.58,234.17,505,1,2,1,233.53,234.25,10,100,1,1,233.5,234.41,100,600,1,2,233.45,234.43,15,105,1,2,233.4,234.5,110,63,2,4,233.39,234.75,10,1,1,1,233.31,234.79,110,2000,2,1,JPM
2024-10-21T12:16:49.635302899Z,2024-10-21T12:16:49.635136826Z,10,2,38,A,A,0,234.04,400,130,166073,12585963,233.7,234.04,1200,400,1,1,233.68,234.06,27,29,1,1,233.66,234.1,1,100,1,1,233.58,234.13,505,400,2,1,233.53,234.17,10,1,1,1,233.5,234.25,100,100,1,1,233.45,234.41,15,600,1,2,233.4,234.43,110,105,2,2,233.39,234.5,10,63,1,4,233.31,234.75,110,1,2,1,JPM
2024-10-21T12:16:49.635707853Z,2024-10-21T12:16:49.635541646Z,10,2,38,C,A,1,234.06,29,130,166207,12585964,233.7,234.04,1200,400,1,1,233.68,234.1,27,100,1,1,233.66,234.13,1,400,1,1,233.58,234.17,505,1,2,1,233.53,234.25,10,100,1,1,233.5,234.41,100,600,1,2,233.45,234.43,15,105,1,2,233.4,234.5,110,63,2,4,233.39,234.75,10,1,1,1,233.31,234.79,110,2000,2,1,JPM
2024-10-21T12:16:49.635803361Z,2024-10-21T12:16:49.635636984Z,10,2,38,A,A,2,234.11,29,130,166377,12585965,233.7,234.04,1200,400,1,1,233.68,234.1,27,100,1,1,233.66,234.11,1,29,1,1,233.58,234.13,505,400,2,1,233.53,234.17,10,1,1,1,233.5,234.25,100,100,1,1,233.45,234.41,15,600,1,2,233.4,234.43,110,105,2,2,233.39,234.5,10,63,1,4,233.31,234.75,110,1,2,1,JPM
2024-10-21T12:16:49.669662206Z,2024-10-21T12:16:49.669495875Z,10,2,38,A,B,1,233.68,200,130,166331,12585982,233.7,234.04,1200,400,1,1,233.68,234.1,227,100,2,1,233.66,234.11,1,29,1,1,233.58,234.13,505,400,2,1,233.53,234.17,10,1,1,1,233.5,234.25,100,100,1,1,233.45,234.41,15,600,1,2,233.4,234.43,110,105,2,2,233.39,234.5,10,63,1,4,233.31,234.75,110,1,2,1,JPM
2024-10-21T12:16:49.706410056Z,2024-10-21T12:16:49.706243840Z,10,2,38,C,A,0,234.04,200,130,166216,12585991,233.7,234.04,1200,200,1,1,233.68,234.1,227,100,2,1,233.66,234.11,1,29,1,1,233.58,234.13,505,400,2,1,233.53,234.17,10,1,1,1,233.5,234.25,100,100,1,1,233.45,234.41,15,600,1,2,233.4,234.43,110,105,2,2,233.39,234.5,10,63,1,4,233.31,234.75,110,1,2,1,JPM
2024-10-21T12:16:49.706607779Z,2024-10-21T12:16:49.706441749Z,10,2,38,C,A,0,234.04,200,130,166030,12585992,233.7,234.1,1200,100,1,1,233.68,234.11,227,29,2,1,233.66,234.13,1,400,1,1,233.58,234.17,505,1,2,1,233.53,234.25,10,100,1,1,233.5,234.41,100,600,1,2,233.45,234.43,15,105,1,2,233.4,234.5,110,63,2,4,233.39,234.75,10,1,1,1,233.31,234.79,110,2000,2,1,JPM
2024-10-21T12:16:49.706619859Z,2024-10-21T12:16:49.706453582Z,10,2,38,A,A,0,234.09,200,130,166277,12585993,233.7,234.09,1200,200,1,1,233.68,234.1,227,100,2,1,233.66,234.11,1,29,1,1,233.58,234.13,505,400,2,1,233.53,234.17,10,1,1,1,233.5,234.25,100,100,1,1,233.45,234.41,15,600,1,2,233.4,234.43,110,105,2,2,233.39,234.5,10,63,1,4,233.31,234.75,110,1,2,1,JPM
2024-10-21T12:16:49.707217404Z,2024-10-21T12:16:49.707051448Z,10,2,38,C,A,2,234.11,29,130,165956,12585994,233.7,234.09,1200,200,1,1,233.68,234.1,227,100,2,1,233.66,234.13,1,400,1,1,233.58,234.17,505,1,2,1,233.53,234.25,10,100,1,1,233.5,234.41,100,600,1,2,233.45,234.43,15,105,1,2,233.4,234.5,110,63,2,4,233.39,234.75,10,1,1,1,233.31,234.79,110,2000,2,1,JPM
2024-10-21T12:16:49.709612912Z,2024-10-21T12:16:49.709446277Z,10,2,38,A,A,0,234.09,200,130,166635,12585999,233.7,234.09,1200,400,1,2,233.68,234.1,227,100,2,1,233.66,234.13,1,400,1,1,233.58,234.17,505,1,2,1,233.53,234.25,10,100,1,1,233.5,234.41,100,600,1,2,233.45,234.43,15,105,1,2,233.4,234.5,110,63,2,4,233.39,234.75,10,1,1,1,233.31,234.79,110,2000,2,1,JPM
2024-10-21T12:16:50.277429428Z,2024-10-21T12:16:50.277262708Z,10,2,38,C,B,1,233.68,27,130,166720,12586408,233.7,234.09,1200,400,1,2,233.68,234.1,200,100,1,1,233.66,234.13,1,400,1,1,233.58,234.17,505,1,2,1,233.53,234.25,10,100,1,1,233.5,234.41,100,600,1,2,233.45,234.43,15,105,1,2,233.4,234.5,110,63,2,4,233.39,234.75,10,1,1,1,233.31,234.79,110,2000,2,1,JPM
2024-10-21T12:16:50.277516325Z,2024-10-21T12:16:50.277350058Z,10,2,38,A,A,3,234.17,27,130,166267,12586409,233.7,234.09,1200,400,1,2,233.68,234.1,200,100,1,1,233.66,234.13,1,400,1,1,233.58,234.17,505,28,2,2,233.53,234.25,10,100,1,1,233.5,234.41,100,600,1,2,233.45,234.43,15,105,1,2,233.4,234.5,110,63,2,4,233.39,234.75,10,1,1,1,233.31,234.79,110,2000,2,1,JPM
2024-10-21T12:16:50.277547866Z,2024-10-21T12:16:50.277381197Z,10,2,38,A,B,1,233.69,27,130,166669,12586410,233.7,234.09,1200,400,1,2,233.69,234.1,27,100,1,1,233.68,234.13,200,400,1,1,233.66,234.17,1,28,1,2,233.58,234.25,505,100,2,1,233.53,234.41,10,600,1,2,233.5,234.43,100,105,1,2,233.45,234.5,15,63,1,4,233.4,234.75,110,1,2,1,233.39,234.79,10,2000,1,1,JPM
2024-10-21T12:16:50.981625530Z,2024-10-21T12:16:50.981459165Z,10,2,38,A,B,0,233.7,200,130,166365,12587468,233.7,234.09,1400,400,2,2,233.69,234.1,27,100,1,1,233.66,234.13,1,400,1,1,233.58,234.17,505,28,2,2,233.53,234.25,10,100,1,1,233.5,234.41,100,600,1,2,233.45,234.43,15,105,1,2,233.4,234.5,110,63,2,4,233.39,234.75,10,1,1,1,233.31,234.79,110,2000,2,1,JPM
2024-10-21T12:16:51.768939105Z,2024-10-21T12:16:51.768772781Z,10,2,38,A,B,0,233.85,141,130,166324,12588253,233.85,234.09,141,400,1,2,233.7,234.1,1400,100,2,1,233.69,234.13,27,400,1,1,233.66,234.17,1,28,1,2,233.58,234.25,505,100,2,1,233.53,234.41,10,600,1,2,233.5,234.43,100,105,1,2,233.45,234.5,15,63,1,4,233.4,234.75,110,1,2,1,233.39,234.79,10,2000,1,1,JPM
2024-10-21T12:16:54.799926585Z,2024-10-21T12:16:54.799759269Z,10,2,38,T,N,0,233.86,13,130,167316,12591024,233.85,234.09,141,400,1,2,233.7,234.1,1400,100,2,1,233.69,234.13,27,400,1,1,233.66,234.17,1,28,1,2,233.58,234.25,505,100,2,1,233.53,234.41,10,600,1,2,233.5,234.43,100,105,1,2,233.45,234.5,15,63,1,4,233.4,234.75,110,1,2,1,233.39,234.79,10,2000,1,1,JPM
2024-10-21T12:16:54.862694065Z,2024-10-21T12:16:54.862528040Z,10,2,38,C,A,3,234.17,27,130,166025,12591058,233.85,234.09,141,400,1,2,233.7,234.1,1400,100,2,1,233.69,234.13,27,400,1,1,233.66,234.17,1,1,1,1,233.58,234.25,505,100,2,1,233.53,234.41,10,600,1,2,233.5,234.43,100,105,1,2,233.45,234.5,15,63,1,4,233.4,234.75,110,1,2,1,233.39,234.79,10,2000,1,1,JPM
2024-10-21T12:16:54.862819345Z,2024-10-21T12:16:54.862652964Z,10,2,38,A,A,3,234.16,30,130,166381,12591059,233.85,234.09,141,400,1,2,233.7,234.1,1400,100,2,1,233.69,234.13,27,400,1,1,233.66,234.16,1,30,1,1,233.58,234.17,505,1,2,1,233.53,234.25,10,100,1,1,233.5,234.41,100,600,1,2,233.45,234.43,15,105,1,2,233.4,234.5,110,63,2,4,233.39,234.75,10,1,1,1,JPM
2024-10-21T12:17:02.456671669Z,2024-10-21T12:17:02.456505763Z,10,2,38,C,A,0,234.09,200,130,165906,12600010,233.85,234.09,141,200,1,1,233.7,234.1,1400,100,2,1,233.69,234.13,27,400,1,1,233.66,234.16,1,30,1,1,233.58,234.17,505,1,2,1,233.53,234.25,10,100,1,1,233.5,234.41,100,600,1,2,233.45,234.43,15,105,1,2,233.4,234.5,110,63,2,4,233.39,234.75,10,1,1,1,JPM
2024-10-21T12:17:02.456684400Z,2024-10-21T12:17:02.456518211Z,10,2,38,A,A,0,234.08,400,130,166189,12600011,233.85,234.08,141,400,1,1,233.7,234.1,1400,100,2,1,233.69,234.13,27,400,1,1,233.66,234.16,1,30,1,1,233.58,234.17,505,1,2,1,233.53,234.25,10,100,1,1,233.5,234.41,100,600,1,2,233.45,234.43,15,105,1,2,233.4,234.5,110,63,2,4,233.39,234.75,10,1,1,1,JPM
2024-10-21T12:17:02.692870111Z,2024-10-21T12:17:02.692703742Z,10,2,38,A,B,1,233.7,200,130,166369,12600199,233.85,234.08,141,400,1,1,233.7,234.1,1600,100,3,1,233.69,234.13,27,400,1,1,233.66,234.16,1,30,1,1,233.58,234.17,505,1,2,1,233.53,234.25,10,100,1,1,233.5,234.41,100,600,1,2,233.45,234.43,15,105,1,2,233.4,234.5,110,63,2,4,233.39,234.75,10,1,1,1,JPM
2024-10-21T12:17:02.695901737Z,2024-10-21T12:17:02.695735412Z,10,2,38,A,B,1,233.73,27,130,166325,12600202,233.85,234.08,141,400,1,1,233.73,234.1,27,100,1,1,233.7,234.13,1600,400,3,1,233.69,234.16,27,30,1,1,233.66,234.17,1,1,1,1,233.58,234.25,505,100,2,1,233.53,234.41,10,600,1,2,233.5,234.43,100,105,1,2,233.45,234.5,15,63,1,4,233.4,234.75,110,1,2,1,JPM
2024-10-21T12:17:02.695928779Z,2024-10-21T12:17:02.695762734Z,10,2,38,C,B,3,233.69,27,130,166045,12600203,233.85,234.08,141,400,1,1,233.73,234.1,27,100,1,1,233.7,234.13,1600,400,3,1,233.66,234.16,1,30,1,1,233.58,234.17,505,1,2,1,233.53,234.25,10,100,1,1,233.5,234.41,100,600,1,2,233.45,234.43,15,105,1,2,233.4,234.5,110,63,2,4,233.39,234.75,10,1,1,1,JPM
2024-10-21T12:17:02.744107650Z,2024-10-21T12:17:02.743941560Z,10,2,38,C,B,2,233.7,200,130,166090,12600243,233.85,234.08,141,400,1,1,233.73,234.1,27,100,1,1,233.7,234.13,1400,400,2,1,233.66,234.16,1,30,1,1,233.58,234.17,505,1,2,1,233.53,234.25,10,100,1,1,233.5,234.41,100,600,1,2,233.45,234.43,15,105,1,2,233.4,234.5,110,63,2,4,233.39,234.75,10,1,1,1,JPM
2024-10-21T12:17:02.744120623Z,2024-10-21T12:17:02.743954174Z,10,2,38,A,B,1,233.77,200,130,166449,12600244,233.85,234.08,141,400,1,1,233.77,234.1,200,100,1,1,233.73,234.13,27,400,1,1,233.7,234.16,1200,30,1,1,233.66,234.17,1,1,1,1,233.58,234.25,505,100,2,1,233.53,234.41,10,600,1,2,233.5,234.43,100,105,1,2,233.45,234.5,15,63,1,4,233.4,234.75,110,1,2,1,JPM
2024-10-21T12:17:04.308892470Z,2024-10-21T12:17:04.308725875Z,10,2,38,C,A,3,234.16,30,130,166595,12602099,233.85,234.08,141,400,1,1,233.77,234.1,200,100,1,1,233.73,234.13,27,400,1,1,233.7,234.17,1200,1,1,1,233.66,234.25,1,100,1,1,233.58,234.41,505,600,2,2,233.53,234.43,10,105,1,2,233.5,234.5,100,63,1,4,233.45,234.75,15,1,1,1,233.4,234.79,110,2000,2,1,JPM
2024-10-21T12:17:04.308942951Z,2024-10-21T12:17:04.308776780Z,10,2,38,A,A,3,234.15,26,130,166171,12602100,233.85,234.08,141,400,1,1,233.77,234.1,200,100,1,1,233.73,234.13,27,400,1,1,233.7,234.15,1200,26,1,1,233.66,234.17,1,1,1,1,233.58,234.25,505,100,2,1,233.53,234.41,10,600,1,2,233.5,234.43,100,105,1,2,233.45,234.5,15,63,1,4,233.4,234.75,110,1,2,1,JPM
2024-10-21T12:17:06.048460890Z,2024-10-21T12:17:06.048294911Z,10,2,38,C,B,1,233.77,200,130,165979,12604816,233.85,234.08,141,400,1,1,233.73,234.1,27,100,1,1,233.7,234.13,1200,400,1,1,233.66,234.15,1,26,1,1,233.58,234.17,505,1,2,1,233.53,234.25,10,100,1,1,233.5,234.41,100,600,1,2,233.45,234.43,15,105,1,2,233.4,234.5,110,63,2,4,233.39,234.75,10,1,1,1,JPM
2024-10-21T12:17:06.048474822Z,2024-10-21T12:17:06.048308319Z,10,2,38,A,B,1,233.74,200,130,166503,12604817,233.85,234.08,141,400,1,1,233.74,234.1,200,100,1,1,233.73,234.13,27,400,1,1,233.7,234.15,1200,26,1,1,233.66,234.17,1,1,1,1,233.58,234.25,505,100,2,1,233.53,234.41,10,600,1,2,233.5,234.43,100,105,1,2,233.45,234.5,15,63,1,4,233.4,234.75,110,1,2,1,JPM
2024-10-21T12:17:07.404034239Z,2024-10-21T12:17:07.403868087Z,10,2,38,A,B,1,233.74,200,130,166152,12606471,233.85,234.08,141,400,1,1,233.74,234.1,400,100,2,1,233.73,234.13,27,400,1,1,233.7,234.15,1200,26,1,1,233.66,234.17,1,1,1,1,233.58,234.25,505,100,2,1,233.53,234.41,10,600,1,2,233.5,234.43,100,105,1,2,233.45,234.5,15,63,1,4,233.4,234.75,110,1,2,1,JPM
2024-10-21T12:17:07.458838488Z,2024-10-21T12:17:07.458672320Z,10,2,38,C,B,1,233.74,200,130,166168,12606559,233.85,234.08,141,400,1,1,233.74,234.1,200,100,1,1,233.73,234.13,27,400,1,1,233.7,234.15,1200,26,1,1,233.66,234.17,1,1,1,1,233.58,234.25,505,100,2,1,233.53,234.41,10,600,1,2,233.5,234.43,100,105,1,2,233.45,234.5,15,63,1,4,233.4,234.75,110,1,2,1,JPM
2024-10-21T12:17:07.458851802Z,2024-10-21T12:17:07.458684918Z,10,2,38,A,B,1,233.77,200,130,166884,12606560,233.85,234.08,141,400,1,1,233.77,234.1,200,100,1,1,233.73,234.13,27,400,1,1,233.7,234.15,1200,26,1,1,233.66,234.17,1,1,1,1,233.58,234.25,505,100,2,1,233.53,234.41,10,600,1,2,233.5,234.43,100,105,1,2,233.45,234.5,15,63,1,4,233.4,234.75,110,1,2,1,JPM
2024-10-21T12:17:10.980236242Z,2024-10-21T12:17:10.980069944Z,10,2,38,C,B,1,233.77,200,130,166298,12610019,233.85,234.08,141,400,1,1,233.73,234.1,27,100,1,1,233.7,234.13,1200,400,1,1,233.66,234.15,1,26,1,1,233.58,234.17,505,1,2,1,233.53,234.25,10,100,1,1,233.5,234.41,100,600,1,2,233.45,234.43,15,105,1,2,233.4,234.5,110,63,2,4,233.39,234.75,10,1,1,1,JPM
2024-10-21T12:17:10.980249439Z,2024-10-21T12:17:10.980083268Z,10,2,38,A,B,1,233.74,200,130,166171,12610020,233.85,234.08,141,400,1,1,233.74,234.1,200,100,1,1,233.73,234.13,27,400,1,1,233.7,234.15,1200,26,1,1,233.66,234.17,1,1,1,1,233.58,234.25,505,100,2,1,233.53,234.41,10,600,1,2,233.5,234.43,100,105,1,2,233.45,234.5,15,63,1,4,233.4,234.75,110,1,2,1,JPM
2024-10-21T12:17:16.047057825Z,2024-10-21T12:17:16.046891679Z,10,2,38,A,B,1,233.74,200,130,166146,12615898,233.85,234.08,141,400,1,1,233.74,234.1,400,100,2,1,233.73,234.13,27,400,1,1,233.7,234.15,1200,26,1,1,233.66,234.17,1,1,1,1,233.58,234.25,505,100,2,1,233.53,234.41,10,600,1,2,233.5,234.43,100,105,1,2,233.45,234.5,15,63,1,4,233.4,234.75,110,1,2,1,JPM
2024-10-21T12:17:16.101486118Z,2024-10-21T12:17:16.101320234Z,10,2,38,C,B,1,233.74,200,130,165884,12616034,233.85,234.08,141,400,1,1,233.74,234.1,200,100,1,1,233.73,234.13,27,400,1,1,233.7,234.15,1200,26,1,1,233.66,234.17,1,1,1,1,233.58,234.25,505,100,2,1,233.53,234.41,10,600,1,2,233.5,234.43,100,105,1,2,233.45,234.5,15,63,1,4,233.4,234.75,110,1,2,1,JPM
2024-10-21T12:17:16.101498861Z,2024-10-21T12:17:16.101332500Z,10,2,38,A,B,1,233.77,200,130,166361,12616035,233.85,234.08,141,400,1,1,233.77,234.1,200,100,1,1,233.73,234.13,27,400,1,1,233.7,234.15,1200,26,1,1,233.66,234.17,1,1,1,1,233.58,234.25,505,100,2,1,233.53,234.41,10,600,1,2,233.5,234.43,100,105,1,2,233.45,234.5,15,63,1,4,233.4,234.75,110,1,2,1,JPM
2024-10-21T12:17:18.814393783Z,2024-10-21T12:17:18.814227520Z,10,2,38,A,B,0,233.9,10,130,166263,12619312,233.9,234.08,10,400,1,1,233.85,234.1,141,100,1,1,233.77,234.13,200,400,1,1,233.73,234.15,27,26,1,1,233.7,234.17,1200,1,1,1,233.66,234.25,1,100,1,1,233.58,234.41,505,600,2,2,233.53,234.43,10,105,1,2,233.5,234.5,100,63,1,4,233.45,234.75,15,1,1,1,JPM
2024-10-21T12:17:20.656989311Z,2024-10-21T12:17:20.656823195Z,10,2,38,C,B,2,233.77,200,130,166116,12621045,233.9,234.08,10,400,1,1,233.85,234.1,141,100,1,1,233.73,234.13,27,400,1,1,233.7,234.15,1200,26,1,1,233.66,234.17,1,1,1,1,233.58,234.25,505,100,2,1,233.53,234.41,10,600,1,2,233.5,234.43,100,105,1,2,233.45,234.5,15,63,1,4,233.4,234.75,110,1,2,1,JPM
2024-10-21T12:17:20.662449680Z,2024-10-21T12:17:20.662283454Z,10,2,38,A,A,0,234.05,100,130,166226,12621054,233.9,234.05,10,100,1,1,233.85,234.08,141,400,1,1,233.73,234.1,27,100,1,1,233.7,234.13,1200,400,1,1,233.66,234.15,1,26,1,1,233.58,234.17,505,1,2,1,233.53,234.25,10,100,1,1,233.5,234.41,100,600,1,2,233.45,234.43,15,105,1,2,233.4,234.5,110,63,2,4,JPM
2024-10-21T12:17:20.662910009Z,2024-10-21T12:17:20.662744252Z,10,2,38,C,A,0,234.05,100,130,165757,12621055,233.9,234.08,10,400,1,1,233.85,234.1,141,100,1,1,233.73,234.13,27,400,1,1,233.7,234.15,1200,26,1,1,233.66,234.17,1,1,1,1,233.58,234.25,505,100,2,1,233.53,234.41,10,600,1,2,233.5,234.43,100,105,1,2,233.45,234.5,15,63,1,4,233.4,234.75,110,1,2,1,JPM
2024-10-21T12:17:20.719927826Z,2024-10-21T12:17:20.719761250Z,10,2,38,C,A,0,234.08,200,130,166576,12621104,233.9,234.08,10,200,1,1,233.85,234.1,141,100,1,1,233.73,234.13,27,400,1,1,233.7,234.15,1200,26,1,1,233.66,234.17,1,1,1,1,233.58,234.25,505,100,2,1,233.53,234.41,10,600,1,2,233.5,234.43,100,105,1,2,233.45,234.5,15,63,1,4,233.4,234.75,110,1,2,1,JPM
2024-10-21T12:17:20.762706336Z,2024-10-21T12:17:20.762539880Z,10,2,38,A,B,2,233.77,200,130,166456,12621151,233.9,234.08,10,200,1,1,233.85,234.1,141,100,1,1,233.77,234.13,200,400,1,1,233.73,234.15,27,26,1,1,233.7,234.17,1200,1,1,1,233.66,234.25,1,100,1,1,233.58,234.41,505,600,2,2,233.53,234.43,10,105,1,2,233.5,234.5,100,63,1,4,233.45,234.75,15,1,1,1,JPM
2024-10-21T12:17:21.079070269Z,2024-10-21T12:17:21.078904005Z,10,2,38,A,B,2,233.77,200,130,166264,12621965,233.9,234.08,10,200,1,1,233.85,234.1,141,100,1,1,233.77,234.13,400,400,2,1,233.73,234.15,27,26,1,1,233.7,234.17,1200,1,1,1,233.66,234.25,1,100,1,1,233.58,234.41,505,600,2,2,233.53,234.43,10,105,1,2,233.5,234.5,100,63,1,4,233.45,234.75,15,1,1,1,JPM
2024-10-21T12:17:21.133776008Z,2024-10-21T12:17:21.133609901Z,10,2,38,C,B,2,233.77,200,130,166107,12622031,233.9,234.08,10,200,1,1,233.85,234.1,141,100,1,1,233.77,234.13,200,400,1,1,233.73,234.15,27,26,1,1,233.7,234.17,1200,1,1,1,233.66,234.25,1,100,1,1,233.58,234.41,505,600,2,2,233.53,234.43,10,105,1,2,233.5,234.5,100,63,1,4,233.45,234.75,15,1,1,1,JPM
2024-10-21T12:17:21.133789577Z,2024-10-21T12:17:21.133623109Z,10,2,38,A,B,2,233.8,400,130,166468,12622032,233.9,234.08,10,200,1,1,233.85,234.1,141,100,1,1,233.8,234.13,400,400,1,1,233.73,234.15,27,26,1,1,233.7,234.17,1200,1,1,1,233.66,234.25,1,100,1,1,233.58,234.41,505,600,2,2,233.53,234.43,10,105,1,2,233.5,234.5,100,63,1,4,233.45,234.75,15,1,1,1,JPM
2024-10-21T12:17:21.840377137Z,2024-10-21T12:17:21.840211165Z,10,2,38,C,A,0,234.08,200,130,165972,12622599,233.9,234.1,10,100,1,1,233.85,234.13,141,400,1,1,233.8,234.15,400,26,1,1,233.73,234.17,27,1,1,1,233.7,234.25,1200,100,1,1,233.66,234.41,1,600,1,2,233.58,234.43,505,105,2,2,233.53,234.5,10,63,1,4,233.5,234.75,100,1,1,1,233.45,234.79,15,2000,1,1,JPM
2024-10-21T12:17:21.840390874Z,2024-10-21T12:17:21.840224418Z,10,2,38,A,A,2,234.14,200,130,166456,12622600,233.9,234.1,10,100,1,1,233.85,234.13,141,400,1,1,233.8,234.14,400,200,1,1,233.73,234.15,27,26,1,1,233.7,234.17,1200,1,1,1,233.66,234.25,1,100,1,1,233.58,234.41,505,600,2,2,233.53,234.43,10,105,1,2,233.5,234.5,100,63,1,4,233.45,234.75,15,1,1,1,JPM
2024-10-21T12:17:22.072471402Z,2024-10-21T12:17:22.072304747Z,10,2,38,A,A,1,234.13,200,130,166655,12622909,233.9,234.1,10,100,1,1,233.85,234.13,141,600,1,2,233.8,234.15,400,26,1,1,233.73,234.17,27,1,1,1,233.7,234.25,1200,100,1,1,233.66,234.41,1,600,1,2,233.58,234.43,505,105,2,2,233.53,234.5,10,63,1,4,233.5,234.75,100,1,1,1,233.45,234.79,15,2000,1,1,JPM
2024-10-21T12:17:22.085874150Z,2024-10-21T12:17:22.085707892Z,10,2,38,A,A,0,234.0,50,130,166258,12622918,233.9,234.0,10,50,1,1,233.85,234.1,141,100,1,1,233.8,234.13,400,600,1,2,233.73,234.15,27,26,1,1,233.7,234.17,1200,1,1,1,233.66,234.25,1,100,1,1,233.58,234.41,505,600,2,2,233.53,234.43,10,105,1,2,233.5,234.5,100,63,1,4,233.45,234.75,15,1,1,1,JPM
2024-10-21T12:17:24.840534781Z,2024-10-21T12:17:24.840366131Z,10,2,38,A,A,2,234.13,200,130,168650,12624574,233.9,234.0,10,50,1,1,233.85,234.1,141,100,1,1,233.8,234.13,400,800,1,3,233.73,234.15,27,26,1,1,233.7,234.17,1200,1,1,1,233.66,234.25,1,100,1,1,233.58,234.41,505,600,2,2,233.53,234.43,10,105,1,2,233.5,234.5,100,63,1,4,233.45,234.75,15,1,1,1,JPM
2024-10-21T12:17:24.840961517Z,2024-10-21T12:17:24.840795392Z,10,2,38,A,A,1,234.1,28,130,166125,12624575,233.9,234.0,10,50,1,1,233.85,234.1,141,128,1,2,233.8,234.13,400,800,1,3,233.73,234.15,27,26,1,1,233.7,234.17,1200,1,1,1,233.66,234.25,1,100,1,1,233.58,234.41,505,600,2,2,233.53,234.43,10,105,1,2,233.5,234.5,100,63,1,4,233.45,234.75,15,1,1,1,JPM
2024-10-21T12:17:24.840987330Z,2024-10-21T12:17:24.840821231Z,10,2,38,C,A,3,234.15,26,130,166099,12624576,233.9,234.0,10,50,1,1,233.85,234.1,141,128,1,2,233.8,234.13,400,800,1,3,233.73,234.17,27,1,1,1,233.7,234.25,1200,100,1,1,233.66,234.41,1,600,1,2,233.58,234.43,505,105,2,2,233.53,234.5,10,63,1,4,233.5,234.75,100,1,1,1,233.45,234.79,15,2000,1,1,JPM
2024-10-21T12:17:24.896181576Z,2024-10-21T12:17:24.896015668Z,10,2,38,C,A,2,234.13,200,130,165908,12624585,233.9,234.0,10,50,1,1,233.85,234.1,141,128,1,2,233.8,234.13,400,600,1,2,233.73,234.17,27,1,1,1,233.7,234.25,1200,100,1,1,233.66,234.41,1,600,1,2,233.58,234.43,505,105,2,2,233.53,234.5,10,63,1,4,233.5,234.75,100,1,1,1,233.45,234.79,15,2000,1,1,JPM
2024-10-21T12:17:24.896197156Z,2024-10-21T12:17:24.896030774Z,10,2,38,A,A,1,234.04,200,130,166382,12624586,233.9,234.0,10,50,1,1,233.85,234.04,141,200,1,1,233.8,234.1,400,128,1,2,233.73,234.13,27,400,1,1,233.7,234.17,1200,1,1,1,233.66,234.25,1,100,1,1,233.58,234.41,505,600,2,2,233.53,234.43,10,105,1,2,233.5,234.5,100,63,1,4,233.45,234.75,15,1,1,1,JPM
2024-10-21T12:17:26.219893772Z,2024-10-21T12:17:26.219727754Z,10,2,38,C,A,2,234.1,28,130,166018,12625936,233.9,234.0,10,50,1,1,233.85,234.04,141,200,1,1,233.8,234.1,400,100,1,1,233.73,234.13,27,400,1,1,233.7,234.17,1200,1,1,1,233.66,234.25,1,100,1,1,233.58,234.41,505,600,2,2,233.53,234.43,10,105,1,2,233.5,234.5,100,63,1,4,233.45,234.75,15,1,1,1,JPM
2024-10-21T12:17:26.219990353Z,2024-10-21T12:17:26.219824269Z,10,2,38,A,A,2,234.09,27,130,166084,12625937,233.9,234.0,10,50,1,1,233.85,234.04,141,200,1,1,233.8,234.09,400,27,1,1,233.73,234.1,27,100,1,1,233.7,234.13,1200,400,1,1,233.66,234.17,1,1,1,1,233.58,234.25,505,100,2,1,233.53,234.41,10,600,1,2,233.5,234.43,100,105,1,2,233.45,234.5,15,63,1,4,JPM
2024-10-21T12:17:26.287111991Z,2024-10-21T12:17:26.286945437Z,10,2,38,A,A,1,234.03,200,130,166554,12626109,233.9,234.0,10,50,1,1,233.85,234.03,141,200,1,1,233.8,234.09,400,27,1,1,233.73,234.1,27,100,1,1,233.7,234.13,1200,400,1,1,233.66,234.17,1,1,1,1,233.58,234.25,505,100,2,1,233.53,234.41,10,600,1,2,233.5,234.43,100,105,1,2,233.45,234.5,15,63,1,4,JPM
2024-10-21T12:17:30.761811610Z,2024-10-21T12:17:30.761645371Z,10,2,38,C,A,1,234.03,200,130,166239,12633053,233.9,234.0,10,50,1,1,233.85,234.09,141,27,1,1,233.8,234.1,400,100,1,1,233.73,234.13,27,400,1,1,233.7,234.17,1200,1,1,1,233.66,234.25,1,100,1,1,233.58,234.41,505,600,2,2,233.53,234.43,10,105,1,2,233.5,234.5,100,63,1,4,233.45,234.75,15,1,1,1,JPM
2024-10-21T12:17:30.761824012Z,2024-10-21T12:17:30.761657680Z,10,2,38,A,A,1,234.08,200,130,166332,12633054,233.9,234.0,10,50,1,1,233.85,234.08,141,200,1,1,233.8,234.09,400,27,1,1,233.73,234.1,27,100,1,1,233.7,234.13,1200,400,1,1,233.66,234.17,1,1,1,1,233.58,234.25,505,100,2,1,233.53,234.41,10,600,1,2,233.5,234.43,100,105,1,2,233.45,234.5,15,63,1,4,JPM
2024-10-21T12:17:30.763106554Z,2024-10-21T12:17:30.762940179Z,10,2,38,A,A,1,234.08,200,130,166375,12633055,233.9,234.0,10,50,1,1,233.85,234.08,141,400,1,2,233.8,234.09,400,27,1,1,233.73,234.1,27,100,1,1,233.7,234.13,1200,400,1,1,233.66,234.17,1,1,1,1,233.58,234.25,505,100,2,1,233.53,234.41,10,600,1,2,233.5,234.43,100,105,1,2,233.45,234.5,15,63,1,4,JPM
2024-10-21T12:17:30.764758511Z,2024-10-21T12:17:30.764592400Z,10,2,38,C,A,2,234.09,27,130,166111,12633057,233.9,234.0,10,50,1,1,233.85,234.08,141,400,1,2,233.8,234.1,400,100,1,1,233.73,234.13,27,400,1,1,233.7,234.17,1200,1,1,1,233.66,234.25,1,100,1,1,233.58,234.41,505,600,2,2,233.53,234.43,10,105,1,2,233.5,234.5,100,63,1,4,233.45,234.75,15,1,1,1,JPM
2024-10-21T12:17:30.764858610Z,2024-10-21T12:17:30.764692359Z,10,2,38,A,A,4,234.15,29,130,166251,12633058,233.9,234.0,10,50,1,1,233.85,234.08,141,400,1,2,233.8,234.1,400,100,1,1,233.73,234.13,27,400,1,1,233.7,234.15,1200,29,1,1,233.66,234.17,1,1,1,1,233.58,234.25,505,100,2,1,233.53,234.41,10,600,1,2,233.5,234.43,100,105,1,2,233.45,234.5,15,63,1,4,JPM
2024-10-21T12:17:33.378449675Z,2024-10-21T12:17:33.378283593Z,10,2,38,C,B,2,233.8,400,130,166082,12636437,233.9,234.0,10,50,1,1,233.85,234.08,141,400,1,2,233.73,234.1,27,100,1,1,233.7,234.13,1200,400,1,1,233.66,234.15,1,29,1,1,233.58,234.17,505,1,2,1,233.53,234.25,10,100,1,1,233.5,234.41,100,600,1,2,233.45,234.43,15,105,1,2,233.4,234.5,110,63,2,4,JPM
2024-10-21T12:17:33.378463077Z,2024-10-21T12:17:33.378297030Z,10,2,38,A,B,2,233.77,200,130,166047,12636438,233.9,234.0,10,50,1,1,233.85,234.08,141,400,1,2,233.77,234.1,200,100,1,1,233.73,234.13,27,400,1,1,233.7,234.15,1200,29,1,1,233.66,234.17,1,1,1,1,233.58,234.25,505,100,2,1,233.53,234.41,10,600,1,2,233.5,234.43,100,105,1,2,233.45,234.5,15,63,1,4,JPM
2024-10-21T12:17:33.764976450Z,2024-10-21T12:17:33.764809990Z,10,2,38,A,A,2,234.09,29,130,166460,12637750,233.9,234.0,10,50,1,1,233.85,234.08,141,400,1,2,233.77,234.09,200,29,1,1,233.73,234.1,27,100,1,1,233.7,234.13,1200,400,1,1,233.66,234.15,1,29,1,1,233.58,234.17,505,1,2,1,233.53,234.25,10,100,1,1,233.5,234.41,100,600,1,2,233.45,234.43,15,105,1,2,JPM
2024-10-21T12:17:33.765000603Z,2024-10-21T12:17:33.764834502Z,10,2,38,C,A,5,234.15,29,130,166101,12637751,233.9,234.0,10,50,1,1,233.85,234.08,141,400,1,2,233.77,234.09,200,29,1,1,233.73,234.1,27,100,1,1,233.7,234.13,1200,400,1,1,233.66,234.17,1,1,1,1,233.58,234.25,505,100,2,1,233.53,234.41,10,600,1,2,233.5,234.43,100,105,1,2,233.45,234.5,15,63,1,4,JPM
2024-10-21T12:17:33.822988558Z,2024-10-21T12:17:33.822822391Z,10,2,38,C,A,1,234.08,200,130,166167,12637806,233.9,234.0,10,50,1,1,233.85,234.08,141,200,1,1,233.77,234.09,200,29,1,1,233.73,234.1,27,100,1,1,233.7,234.13,1200,400,1,1,233.66,234.17,1,1,1,1,233.58,234.25,505,100,2,1,233.53,234.41,10,600,1,2,233.5,234.43,100,105,1,2,233.45,234.5,15,63,1,4,JPM
2024-10-21T12:17:33.823002310Z,2024-10-21T12:17:33.822835795Z,10,2,38,A,A,1,234.03,200,130,166515,12637807,233.9,234.0,10,50,1,1,233.85,234.03,141,200,1,1,233.77,234.09,200,29,1,1,233.73,234.1,27,100,1,1,233.7,234.13,1200,400,1,1,233.66,234.17,1,1,1,1,233.58,234.25,505,100,2,1,233.53,234.41,10,600,1,2,233.5,234.43,100,105,1,2,233.45,234.5,15,63,1,4,JPM
2024-10-21T12:17:35.461566586Z,2024-10-21T12:17:35.461400679Z,10,2,38,C,A,1,234.03,200,130,165907,12639539,233.9,234.0,10,50,1,1,233.85,234.09,141,29,1,1,233.77,234.1,200,100,1,1,233.73,234.13,27,400,1,1,233.7,234.17,1200,1,1,1,233.66,234.25,1,100,1,1,233.58,234.41,505,600,2,2,233.53,234.43,10,105,1,2,233.5,234.5,100,63,1,4,233.45,234.75,15,1,1,1,JPM
2024-10-21T12:17:35.461578939Z,2024-10-21T12:17:35.461412055Z,10,2,38,A,A,1,234.08,400,130,166884,12639540,233.9,234.0,10,50,1,1,233.85,234.08,141,400,1,1,233.77,234.09,200,29,1,1,233.73,234.1,27,100,1,1,233.7,234.13,1200,400,1,1,233.66,234.17,1,1,1,1,233.58,234.25,505,100,2,1,233.53,234.41,10,600,1,2,233.5,234.43,100,105,1,2,233.45,234.5,15,63,1,4,JPM
2024-10-21T12:17:35.470157228Z,2024-10-21T12:17:35.469991264Z,10,2,38,C,A,2,234.09,29,130,165964,12639580,233.9,234.0,10,50,1,1,233.85,234.08,141,400,1,1,233.77,234.1,200,100,1,1,233.73,234.13,27,400,1,1,233.7,234.17,1200,1,1,1,233.66,234.25,1,100,1,1,233.58,234.41,505,600,2,2,233.53,234.43,10,105,1,2,233.5,234.5,100,63,1,4,233.45,234.75,15,1,1,1,JPM
2024-10-21T12:17:35.470212130Z,2024-10-21T12:17:35.470045707Z,10,2,38,A,A,4,234.15,28,130,166423,12639581,233.9,234.0,10,50,1,1,233.85,234.08,141,400,1,1,233.77,234.1,200,100,1,1,233.73,234.13,27,400,1,1,233.7,234.15,1200,28,1,1,233.66,234.17,1,1,1,1,233.58,234.25,505,100,2,1,233.53,234.41,10,600,1,2,233.5,234.43,100,105,1,2,233.45,234.5,15,63,1,4,JPM
2024-10-21T12:17:37.663795596Z,2024-10-21T12:17:37.663629357Z,10,2,38,A,B,2,233.77,200,130,166239,12641761,233.9,234.0,10,50,1,1,233.85,234.08,141,400,1,1,233.77,234.1,400,100,2,1,233.73,234.13,27,400,1,1,233.7,234.15,1200,28,1,1,233.66,234.17,1,1,1,1,233.58,234.25,505,100,2,1,233.53,234.41,10,600,1,2,233.5,234.43,100,105,1,2,233.45,234.5,15,63,1,4,JPM
2024-10-21T12:17:37.718760543Z,2024-10-21T12:17:37.718594298Z,10,2,38,C,B,2,233.77,200,130,166245,12641892,233.9,234.0,10,50,1,1,233.85,234.08,141,400,1,1,233.77,234.1,200,100,1,1,233.73,234.13,27,400,1,1,233.7,234.15,1200,28,1,1,233.66,234.17,1,1,1,1,233.58,234.25,505,100,2,1,233.53,234.41,10,600,1,2,233.5,234.43,100,105,1,2,233.45,234.5,15,63,1,4,JPM
2024-10-21T12:17:37.718772651Z,2024-10-21T12:17:37.718605853Z,10,2,38,A,B,2,233.8,400,130,166798,12641893,233.9,234.0,10,50,1,1,233.85,234.08,141,400,1,1,233.8,234.1,400,100,1,1,233.73,234.13,27,400,1,1,233.7,234.15,1200,28,1,1,233.66,234.17,1,1,1,1,233.58,234.25,505,100,2,1,233.53,234.41,10,600,1,2,233.5,234.43,100,105,1,2,233.45,234.5,15,63,1,4,JPM
2024-10-21T12:17:38.521294530Z,2024-10-21T12:17:38.521127910Z,10,2,38,A,A,1,234.04,200,130,166620,12642639,233.9,234.0,10,50,1,1,233.85,234.04,141,200,1,1,233.8,234.1,400,100,1,1,233.73,234.13,27,400,1,1,233.7,234.15,1200,28,1,1,233.66,234.17,1,1,1,1,233.58,234.25,505,100,2,1,233.53,234.41,10,600,1,2,233.5,234.43,100,105,1,2,233.45,234.5,15,63,1,4,JPM
2024-10-21T12:17:39.973713394Z,2024-10-21T12:17:39.973547435Z,10,2,38,C,A,4,234.15,28,130,165959,12644151,233.9,234.0,10,50,1,1,233.85,234.04,141,200,1,1,233.8,234.1,400,100,1,1,233.73,234.13,27,400,1,1,233.7,234.17,1200,1,1,1,233.66,234.25,1,100,1,1,233.58,234.41,505,600,2,2,233.53,234.43,10,105,1,2,233.5,234.5,100,63,1,4,233.45,234.75,15,1,1,1,JPM
2024-10-21T12:17:39.973752037Z,2024-10-21T12:17:39.973585910Z,10,2,38,A,A,2,234.1,27,130,166127,12644152,233.9,234.0,10,50,1,1,233.85,234.04,141,200,1,1,233.8,234.1,400,127,1,2,233.73,234.13,27,400,1,1,233.7,234.17,1200,1,1,1,233.66,234.25,1,100,1,1,233.58,234.41,505,600,2,2,233.53,234.43,10,105,1,2,233.5,234.5,100,63,1,4,233.45,234.75,15,1,1,1,JPM
2024-10-21T12:17:47.136044765Z,2024-10-21T12:17:47.135873221Z,10,2,38,T,A,0,233.9,10,0,171544,12650095,233.9,234.0,10,50,1,1,233.85,234.04,141,200,1,1,233.8,234.1,400,127,1,2,233.73,234.13,27,400,1,1,233.7,234.17,1200,1,1,1,233.66,234.25,1,100,1,1,233.58,234.41,505,600,2,2,233.53,234.43,10,105,1,2,233.5,234.5,100,63,1,4,233.45,234.75,15,1,1,1,JPM
2024-10-21T12:17:47.136044765Z,2024-10-21T12:17:47.135873221Z,10,2,38,T,A,0,233.85,141,0,171544,12650096,233.85,234.0,141,50,1,1,233.8,234.04,400,200,1,1,233.73,234.1,27,127,1,2,233.7,234.13,1200,400,1,1,233.66,234.17,1,1,1,1,233.58,234.25,505,100,2,1,233.53,234.41,10,600,1,2,233.5,234.43,100,105,1,2,233.45,234.5,15,63,1,4,233.4,234.75,110,1,2,1,JPM
2024-10-21T12:17:47.136044765Z,2024-10-21T12:17:47.135873221Z,10,2,38,T,N,0,233.85,50,130,171544,12650097,233.8,234.0,400,50,1,1,233.73,234.04,27,200,1,1,233.7,234.1,1200,127,1,2,233.66,234.13,1,400,1,1,233.58,234.17,505,1,2,1,233.53,234.25,10,100,1,1,233.5,234.41,100,600,1,2,233.45,234.43,15,105,1,2,233.4,234.5,110,63,2,4,233.39,234.75,10,1,1,1,JPM
2024-10-21T12:17:47.136066911Z,2024-10-21T12:17:47.135900626Z,10,2,38,A,A,0,233.98,100,130,166285,12650098,233.8,233.98,400,100,1,1,233.73,234.0,27,50,1,1,233.7,234.04,1200,200,1,1,233.66,234.1,1,127,1,2,233.58,234.13,505,400,2,1,233.53,234.17,10,1,1,1,233.5,234.25,100,100,1,1,233.45,234.41,15,600,1,2,233.4,234.43,110,105,2,2,233.39,234.5,10,63,1,4,JPM
2024-10-21T12:17:47.136072149Z,2024-10-21T12:17:47.135905168Z,10,2,38,A,A,0,233.97,100,130,166981,12650099,233.8,233.97,400,100,1,1,233.73,233.98,27,100,1,1,233.7,234.0,1200,50,1,1,233.66,234.04,1,200,1,1,233.58,234.1,505,127,2,2,233.53,234.13,10,400,1,1,233.5,234.17,100,1,1,1,233.45,234.25,15,100,1,1,233.4,234.41,110,600,2,2,233.39,234.43,10,105,1,2,JPM
2024-10-21T12:17:47.136074817Z,2024-10-21T12:17:47.135906292Z,10,2,38,A,A,0,233.95,162,130,168525,12650101,233.8,233.95,400,162,1,1,233.73,233.97,27,200,1,2,233.7,233.98,1200,100,1,1,233.66,234.0,1,50,1,1,233.58,234.04,505,200,2,1,233.53,234.1,10,127,1,2,233.5,234.13,100,400,1,1,233.45,234.17,15,1,1,1,233.4,234.25,110,100,2,1,233.39,234.41,10,600,1,2,JPM
2024-10-21T12:17:47.136079816Z,2024-10-21T12:17:47.135913885Z,10,2,38,A,A,0,233.92,100,130,165931,12650102,233.8,233.92,400,100,1,1,233.73,233.95,27,162,1,1,233.7,233.97,1200,200,1,2,233.66,233.98,1,100,1,1,233.58,234.0,505,50,2,1,233.53,234.04,10,200,1,1,233.5,234.1,100,127,1,2,233.45,234.13,15,400,1,1,233.4,234.17,110,1,2,1,233.39,234.25,10,100,1,1,JPM
2024-10-21T12:17:47.136082565Z,2024-10-21T12:17:47.135916592Z,10,2,38,A,A,3,233.98,100,130,165973,12650103,233.8,233.92,400,100,1,1,233.73,233.95,27,162,1,1,233.7,233.97,1200,200,1,2,233.66,233.98,1,200,1,2,233.58,234.0,505,50,2,1,233.53,234.04,10,200,1,1,233.5,234.1,100,127,1,2,233.45,234.13,15,400,1,1,233.4,234.17,110,1,2,1,233.39,234.25,10,100,1,1,JPM
2024-10-21T12:17:47.136093537Z,2024-10-21T12:17:47.135925594Z,10,2,38,A,A,2,233.97,100,130,167943,12650104,233.8,233.92,400,100,1,1,233.73,233.95,27,162,1,1,233.7,233.97,1200,300,1,3,233.66,233.98,1,200,1,2,233.58,234.0,505,50,2,1,233.53,234.04,10,200,1,1,233.5,234.1,100,127,1,2,233.45,234.13,15,400,1,1,233.4,234.17,110,1,2,1,233.39,234.25,10,100,1,1,JPM
2024-10-21T12:17:47.136099687Z,2024-10-21T12:17:47.135933669Z,10,2,38,A,A,1,233.93,35,130,166018,12650105,233.8,233.92,400,100,1,1,233.73,233.93,27,35,1,1,233.7,233.95,1200,162,1,1,233.66,233.97,1,300,1,3,233.58,233.98,505,200,2,2,233.53,234.0,10,50,1,1,233.5,234.04,100,200,1,1,233.45,234.1,15,127,1,2,233.4,234.13,110,400,2,1,233.39,234.17,10,1,1,1,JPM
2024-10-21T12:17:47.136103482Z,2024-10-21T12:17:47.135937314Z,10,2,38,C,A,4,233.98,100,130,166168,12650106,233.8,233.92,400,100,1,1,233.73,233.93,27,35,1,1,233.7,233.95,1200,162,1,1,233.66,233.97,1,300,1,3,233.58,233.98,505,100,2,1,233.53,234.0,10,50,1,1,233.5,234.04,100,200,1,1,233.45,234.1,15,127,1,2,233.4,234.13,110,400,2,1,233.39,234.17,10,1,1,1,JPM
2024-10-21T12:17:47.136107460Z,2024-10-21T12:17:47.135940686Z,10,2,38,A,A,3,233.97,100,130,166774,12650107,233.8,233.92,400,100,1,1,233.73,233.93,27,35,1,1,233.7,233.95,1200,162,1,1,233.66,233.97,1,400,1,4,233.58,233.98,505,100,2,1,233.53,234.0,10,50,1,1,233.5,234.04,100,200,1,1,233.45,234.1,15,127,1,2,233.4,234.13,110,400,2,1,233.39,234.17,10,1,1,1,JPM
2024-10-21T12:17:47.136114326Z,2024-10-21T12:17:47.135946914Z,10,2,38,A,A,0,233.97,35,130,167412,12650109,233.8,233.93,400,35,1,1,233.73,233.95,27,162,1,1,233.7,233.97,1200,435,1,5,233.66,233.98,1,100,1,1,233.58,234.0,505,50,2,1,233.53,234.04,10,200,1,1,233.5,234.1,100,127,1,2,233.45,234.13,15,400,1,1,233.4,234.17,110,1,2,1,233.39,234.25,10,100,1,1,JPM
2024-10-21T12:17:47.136118512Z,2024-10-21T12:17:47.135952535Z,10,2,38,C,A,3,233.98,100,130,165977,12650110,233.8,233.93,400,35,1,1,233.73,233.95,27,162,1,1,233.7,233.97,1200,435,1,5,233.66,234.0,1,50,1,1,233.58,234.04,505,200,2,1,233.53,234.1,10,127,1,2,233.5,234.13,100,400,1,1,233.45,234.17,15,1,1,1,233.4,234.25,110,100,2,1,233.39,234.41,10,600,1,2,JPM
2024-10-21T12:17:47.136124318Z,2024-10-21T12:17:47.135958456Z,10,2,38,C,B,0,233.8,400,130,165862,12650111,233.73,233.93,27,35,1,1,233.7,233.95,1200,162,1,1,233.66,233.97,1,435,1,5,233.58,234.0,505,50,2,1,233.53,234.04,10,200,1,1,233.5,234.1,100,127,1,2,233.45,234.13,15,400,1,1,233.4,234.17,110,1,2,1,233.39,234.25,10,100,1,1,233.31,234.41,110,600,2,2,JPM
2024-10-21T12:17:47.136134998Z,2024-10-21T12:17:47.135968023Z,10,2,38,C,A,1,233.95,162,128,166975,12650112,233.73,233.93,27,35,1,1,233.7,233.97,1200,435,1,5,233.66,234.0,1,50,1,1,233.58,234.04,505,200,2,1,233.53,234.1,10,127,1,2,233.5,234.13,100,400,1,1,233.45,234.17,15,1,1,1,233.4,234.25,110,100,2,1,233.39,234.41,10,600,1,2,233.31,234.43,110,105,2,2,JPM
2024-10-21T12:17:47.136176630Z,2024-10-21T12:17:47.136008874Z,10,2,38,C,A,1,233.97,100,130,167756,12650118,233.73,233.93,27,35,1,1,233.7,233.97,1200,335,1,4,233.66,234.0,1,50,1,1,233.58,234.04,505,200,2,1,233.53,234.1,10,127,1,2,233.5,234.13,100,400,1,1,233.45,234.17,15,1,1,1,233.4,234.25,110,100,2,1,233.39,234.41,10,600,1,2,233.31,234.43,110,105,2,2,JPM
2024-10-21T12:17:47.136220660Z,2024-10-21T12:17:47.136054541Z,10,2,38,C,A,1,233.97,100,130,166119,12650119,233.73,233.93,27,35,1,1,233.7,233.97,1200,235,1,3,233.66,234.0,1,50,1,1,233.58,234.04,505,200,2,1,233.53,234.1,10,127,1,2,233.5,234.13,100,400,1,1,233.45,234.17,15,1,1,1,233.4,234.25,110,100,2,1,233.39,234.41,10,600,1,2,233.31,234.43,110,105,2,2,JPM
2024-10-21T12:17:47.136384565Z,2024-10-21T12:17:47.136218636Z,10,2,38,C,A,1,233.97,100,130,165929,12650120,233.73,233.93,27,35,1,1,233.7,233.97,1200,135,1,2,233.66,234.0,1,50,1,1,233.58,234.04,505,200,2,1,233.53,234.1,10,127,1,2,233.5,234.13,100,400,1,1,233.45,234.17,15,1,1,1,233.4,234.25,110,100,2,1,233.39,234.41,10,600,1,2,233.31,234.43,110,105,2,2,JPM
2024-10-21T12:17:47.136391264Z,2024-10-21T12:17:47.136225295Z,10,2,38,C,A,1,233.97,100,130,165969,12650121,233.73,233.93,27,35,1,1,233.7,233.97,1200,35,1,1,233.66,234.0,1,50,1,1,233.58,234.04,505,200,2,1,233.53,234.1,10,127,1,2,233.5,234.13,100,400,1,1,233.45,234.17,15,1,1,1,233.4,234.25,110,100,2,1,233.39,234.41,10,600,1,2,233.31,234.43,110,105,2,2,JPM
2024-10-21T12:17:47.136731997Z,2024-10-21T12:17:47.136565013Z,10,2,38,A,A,0,233.92,100,130,166984,12650123,233.73,233.92,27,100,1,1,233.7,233.93,1200,35,1,1,233.66,233.97,1,35,1,1,233.58,234.0,505,50,2,1,233.53,234.04,10,200,1,1,233.5,234.1,100,127,1,2,233.45,234.13,15,400,1,1,233.4,234.17,110,1,2,1,233.39,234.25,10,100,1,1,233.31,234.41,110,600,2,2,JPM
2024-10-21T12:17:47.137204585Z,2024-10-21T12:17:47.137037920Z,10,2,38,C,A,0,233.92,100,130,166665,12650124,233.73,233.93,27,35,1,1,233.7,233.97,1200,35,1,1,233.66,234.0,1,50,1,1,233.58,234.04,505,200,2,1,233.53,234.1,10,127,1,2,233.5,234.13,100,400,1,1,233.45,234.17,15,1,1,1,233.4,234.25,110,100,2,1,233.39,234.41,10,600,1,2,233.31,234.43,110,105,2,2,JPM
